Initialising...
Starting CloudSim version 3.0
GlobalBroker is starting...
Datacenter is starting...
Entities started.
Adding: broker_0
broker_0 is starting...
60.3: broker_0: Cloud Resource List received with 1 resource(s)
60.3: broker_0: Trying to Create VM #0 in Datacenter
60.30: VM #0 has been allocated to the host #0
60.4: broker_0: VM #0 has been created in Datacenter #3, Host #0
60.4: broker_0: Sending cloudlet 0 to VM #0


--------------------------------------------------------------


New resource usage for the time frame starting at 120.40:
Adding: broker_1
broker_1 is starting...
120.6: broker_1: Cloud Resource List received with 1 resource(s)
120.6: broker_1: Trying to Create VM #1 in Datacenter
120.6: broker_1: Trying to Create VM #2 in Datacenter
120.6: broker_1: Trying to Create VM #3 in Datacenter
120.6: broker_1: Trying to Create VM #4 in Datacenter
120.6: broker_1: Trying to Create VM #5 in Datacenter
120.6: broker_1: Trying to Create VM #6 in Datacenter
120.6: broker_1: Trying to Create VM #7 in Datacenter
120.6: broker_1: Trying to Create VM #8 in Datacenter
120.6: broker_1: Trying to Create VM #9 in Datacenter
120.6: broker_1: Trying to Create VM #10 in Datacenter
120.6: broker_1: Trying to Create VM #11 in Datacenter
120.6: broker_1: Trying to Create VM #12 in Datacenter
120.6: broker_1: Trying to Create VM #13 in Datacenter
120.6: broker_1: Trying to Create VM #14 in Datacenter
120.6: broker_1: Trying to Create VM #15 in Datacenter
120.6: broker_1: Trying to Create VM #16 in Datacenter
120.60: VM #1 has been allocated to the host #1
120.60: VM #2 has been allocated to the host #2
120.60: VM #3 has been allocated to the host #3
120.60: VM #4 has been allocated to the host #4
120.60: VM #5 has been allocated to the host #5
120.60: VM #6 has been allocated to the host #6
120.60: VM #7 has been allocated to the host #7
120.60: VM #8 has been allocated to the host #8
120.60: VM #9 has been allocated to the host #9
120.60: VM #10 has been allocated to the host #10
120.60: VM #11 has been allocated to the host #11
120.60: VM #12 has been allocated to the host #12
120.60: VM #13 has been allocated to the host #13
120.60: VM #14 has been allocated to the host #14
120.60: VM #15 has been allocated to the host #15
120.60: VM #16 has been allocated to the host #16
120.69999999999999: broker_1: VM #1 has been created in Datacenter #3, Host #1
120.69999999999999: broker_1: VM #2 has been created in Datacenter #3, Host #2
120.69999999999999: broker_1: VM #3 has been created in Datacenter #3, Host #3
120.69999999999999: broker_1: VM #4 has been created in Datacenter #3, Host #4
120.69999999999999: broker_1: VM #5 has been created in Datacenter #3, Host #5
120.69999999999999: broker_1: VM #6 has been created in Datacenter #3, Host #6
120.69999999999999: broker_1: VM #7 has been created in Datacenter #3, Host #7
120.69999999999999: broker_1: VM #8 has been created in Datacenter #3, Host #8
120.69999999999999: broker_1: VM #9 has been created in Datacenter #3, Host #9
120.69999999999999: broker_1: VM #10 has been created in Datacenter #3, Host #10
120.69999999999999: broker_1: VM #11 has been created in Datacenter #3, Host #11
120.69999999999999: broker_1: VM #12 has been created in Datacenter #3, Host #12
120.69999999999999: broker_1: VM #13 has been created in Datacenter #3, Host #13
120.69999999999999: broker_1: VM #14 has been created in Datacenter #3, Host #14
120.69999999999999: broker_1: VM #15 has been created in Datacenter #3, Host #15
120.69999999999999: broker_1: VM #16 has been created in Datacenter #3, Host #16
120.69999999999999: broker_1: Sending cloudlet 1 to VM #1
120.69999999999999: broker_1: Sending cloudlet 2 to VM #2
120.69999999999999: broker_1: Sending cloudlet 3 to VM #3
120.69999999999999: broker_1: Sending cloudlet 4 to VM #4
120.69999999999999: broker_1: Sending cloudlet 5 to VM #5
120.69999999999999: broker_1: Sending cloudlet 6 to VM #6
120.69999999999999: broker_1: Sending cloudlet 7 to VM #7
120.69999999999999: broker_1: Sending cloudlet 8 to VM #8
120.69999999999999: broker_1: Sending cloudlet 9 to VM #9
120.69999999999999: broker_1: Sending cloudlet 10 to VM #10
120.69999999999999: broker_1: Sending cloudlet 11 to VM #11
120.69999999999999: broker_1: Sending cloudlet 12 to VM #12
120.69999999999999: broker_1: Sending cloudlet 13 to VM #13
120.69999999999999: broker_1: Sending cloudlet 14 to VM #14
120.69999999999999: broker_1: Sending cloudlet 15 to VM #15
120.69999999999999: broker_1: Sending cloudlet 16 to VM #16


--------------------------------------------------------------


New resource usage for the time frame starting at 180.70:
Adding: broker_2
broker_2 is starting...
180.89999999999998: broker_2: Cloud Resource List received with 1 resource(s)
180.89999999999998: broker_2: Trying to Create VM #17 in Datacenter
180.89999999999998: broker_2: Trying to Create VM #18 in Datacenter
180.89999999999998: broker_2: Trying to Create VM #19 in Datacenter
180.89999999999998: broker_2: Trying to Create VM #20 in Datacenter
180.89999999999998: broker_2: Trying to Create VM #21 in Datacenter
180.89999999999998: broker_2: Trying to Create VM #22 in Datacenter
180.89999999999998: broker_2: Trying to Create VM #23 in Datacenter
180.89999999999998: broker_2: Trying to Create VM #24 in Datacenter
180.89999999999998: broker_2: Trying to Create VM #25 in Datacenter
180.89999999999998: broker_2: Trying to Create VM #26 in Datacenter
180.89999999999998: broker_2: Trying to Create VM #27 in Datacenter
180.89999999999998: broker_2: Trying to Create VM #28 in Datacenter
180.90: VM #17 has been allocated to the host #17
180.90: VM #18 has been allocated to the host #18
180.90: VM #19 has been allocated to the host #19
180.90: VM #20 has been allocated to the host #20
180.90: VM #21 has been allocated to the host #21
180.90: VM #22 has been allocated to the host #22
180.90: VM #23 has been allocated to the host #23
180.90: VM #24 has been allocated to the host #24
180.90: VM #25 has been allocated to the host #25
180.90: VM #26 has been allocated to the host #26
180.90: VM #27 has been allocated to the host #27
180.90: VM #28 has been allocated to the host #28
180.99999999999997: broker_2: VM #17 has been created in Datacenter #3, Host #17
180.99999999999997: broker_2: VM #18 has been created in Datacenter #3, Host #18
180.99999999999997: broker_2: VM #19 has been created in Datacenter #3, Host #19
180.99999999999997: broker_2: VM #20 has been created in Datacenter #3, Host #20
180.99999999999997: broker_2: VM #21 has been created in Datacenter #3, Host #21
180.99999999999997: broker_2: VM #22 has been created in Datacenter #3, Host #22
180.99999999999997: broker_2: VM #23 has been created in Datacenter #3, Host #23
180.99999999999997: broker_2: VM #24 has been created in Datacenter #3, Host #24
180.99999999999997: broker_2: VM #25 has been created in Datacenter #3, Host #25
180.99999999999997: broker_2: VM #26 has been created in Datacenter #3, Host #26
180.99999999999997: broker_2: VM #27 has been created in Datacenter #3, Host #27
180.99999999999997: broker_2: VM #28 has been created in Datacenter #3, Host #28
180.99999999999997: broker_2: Sending cloudlet 17 to VM #17
180.99999999999997: broker_2: Sending cloudlet 18 to VM #18
180.99999999999997: broker_2: Sending cloudlet 19 to VM #19
180.99999999999997: broker_2: Sending cloudlet 20 to VM #20
180.99999999999997: broker_2: Sending cloudlet 21 to VM #21
180.99999999999997: broker_2: Sending cloudlet 22 to VM #22
180.99999999999997: broker_2: Sending cloudlet 23 to VM #23
180.99999999999997: broker_2: Sending cloudlet 24 to VM #24
180.99999999999997: broker_2: Sending cloudlet 25 to VM #25
180.99999999999997: broker_2: Sending cloudlet 26 to VM #26
180.99999999999997: broker_2: Sending cloudlet 27 to VM #27
180.99999999999997: broker_2: Sending cloudlet 28 to VM #28


--------------------------------------------------------------


New resource usage for the time frame starting at 241.00:
Adding: broker_3
broker_3 is starting...
241.2: broker_3: Cloud Resource List received with 1 resource(s)
241.2: broker_3: Trying to Create VM #29 in Datacenter
241.2: broker_3: Trying to Create VM #30 in Datacenter
241.2: broker_3: Trying to Create VM #31 in Datacenter
241.2: broker_3: Trying to Create VM #32 in Datacenter
241.2: broker_3: Trying to Create VM #33 in Datacenter
241.2: broker_3: Trying to Create VM #34 in Datacenter
241.2: broker_3: Trying to Create VM #35 in Datacenter
241.2: broker_3: Trying to Create VM #36 in Datacenter
241.2: broker_3: Trying to Create VM #37 in Datacenter
241.20: VM #29 has been allocated to the host #29
241.20: VM #30 has been allocated to the host #30
241.20: VM #31 has been allocated to the host #31
241.20: VM #32 has been allocated to the host #32
241.20: VM #33 has been allocated to the host #33
241.20: VM #34 has been allocated to the host #34
241.20: VM #35 has been allocated to the host #35
241.20: VM #36 has been allocated to the host #36
241.20: VM #37 has been allocated to the host #37
241.29999999999998: broker_3: VM #29 has been created in Datacenter #3, Host #29
241.29999999999998: broker_3: VM #30 has been created in Datacenter #3, Host #30
241.29999999999998: broker_3: VM #31 has been created in Datacenter #3, Host #31
241.29999999999998: broker_3: VM #32 has been created in Datacenter #3, Host #32
241.29999999999998: broker_3: VM #33 has been created in Datacenter #3, Host #33
241.29999999999998: broker_3: VM #34 has been created in Datacenter #3, Host #34
241.29999999999998: broker_3: VM #35 has been created in Datacenter #3, Host #35
241.29999999999998: broker_3: VM #36 has been created in Datacenter #3, Host #36
241.29999999999998: broker_3: VM #37 has been created in Datacenter #3, Host #37
241.29999999999998: broker_3: Sending cloudlet 29 to VM #29
241.29999999999998: broker_3: Sending cloudlet 30 to VM #30
241.29999999999998: broker_3: Sending cloudlet 31 to VM #31
241.29999999999998: broker_3: Sending cloudlet 32 to VM #32
241.29999999999998: broker_3: Sending cloudlet 33 to VM #33
241.29999999999998: broker_3: Sending cloudlet 34 to VM #34
241.29999999999998: broker_3: Sending cloudlet 35 to VM #35
241.29999999999998: broker_3: Sending cloudlet 36 to VM #36
241.29999999999998: broker_3: Sending cloudlet 37 to VM #37


--------------------------------------------------------------


New resource usage for the time frame starting at 301.30:
Adding: broker_4
broker_4 is starting...
301.5: broker_4: Cloud Resource List received with 1 resource(s)
301.5: broker_4: Trying to Create VM #38 in Datacenter
301.5: broker_4: Trying to Create VM #39 in Datacenter
301.5: broker_4: Trying to Create VM #40 in Datacenter
301.5: broker_4: Trying to Create VM #41 in Datacenter
301.5: broker_4: Trying to Create VM #42 in Datacenter
301.5: broker_4: Trying to Create VM #43 in Datacenter
301.50: VM #38 has been allocated to the host #38
301.50: VM #39 has been allocated to the host #39
301.50: VM #40 has been allocated to the host #40
301.50: VM #41 has been allocated to the host #41
301.50: VM #42 has been allocated to the host #42
301.50: VM #43 has been allocated to the host #43
301.6: broker_4: VM #38 has been created in Datacenter #3, Host #38
301.6: broker_4: VM #39 has been created in Datacenter #3, Host #39
301.6: broker_4: VM #40 has been created in Datacenter #3, Host #40
301.6: broker_4: VM #41 has been created in Datacenter #3, Host #41
301.6: broker_4: VM #42 has been created in Datacenter #3, Host #42
301.6: broker_4: VM #43 has been created in Datacenter #3, Host #43
301.6: broker_4: Sending cloudlet 38 to VM #38
301.6: broker_4: Sending cloudlet 39 to VM #39
301.6: broker_4: Sending cloudlet 40 to VM #40
301.6: broker_4: Sending cloudlet 41 to VM #41
301.6: broker_4: Sending cloudlet 42 to VM #42
301.6: broker_4: Sending cloudlet 43 to VM #43


--------------------------------------------------------------


New resource usage for the time frame starting at 361.60:
Adding: broker_5
broker_5 is starting...
361.8: broker_5: Cloud Resource List received with 1 resource(s)
361.8: broker_5: Trying to Create VM #44 in Datacenter
361.8: broker_5: Trying to Create VM #45 in Datacenter
361.8: broker_5: Trying to Create VM #46 in Datacenter
361.8: broker_5: Trying to Create VM #47 in Datacenter
361.8: broker_5: Trying to Create VM #48 in Datacenter
361.8: broker_5: Trying to Create VM #49 in Datacenter
361.8: broker_5: Trying to Create VM #50 in Datacenter
361.80: VM #44 has been allocated to the host #44
361.80: VM #45 has been allocated to the host #45
361.80: VM #46 has been allocated to the host #46
361.80: VM #47 has been allocated to the host #47
361.80: VM #48 has been allocated to the host #48
361.80: VM #49 has been allocated to the host #49
361.80: VM #50 has been allocated to the host #50
361.90000000000003: broker_5: VM #44 has been created in Datacenter #3, Host #44
361.90000000000003: broker_5: VM #45 has been created in Datacenter #3, Host #45
361.90000000000003: broker_5: VM #46 has been created in Datacenter #3, Host #46
361.90000000000003: broker_5: VM #47 has been created in Datacenter #3, Host #47
361.90000000000003: broker_5: VM #48 has been created in Datacenter #3, Host #48
361.90000000000003: broker_5: VM #49 has been created in Datacenter #3, Host #49
361.90000000000003: broker_5: VM #50 has been created in Datacenter #3, Host #50
361.90000000000003: broker_5: Sending cloudlet 44 to VM #44
361.90000000000003: broker_5: Sending cloudlet 45 to VM #45
361.90000000000003: broker_5: Sending cloudlet 46 to VM #46
361.90000000000003: broker_5: Sending cloudlet 47 to VM #47
361.90000000000003: broker_5: Sending cloudlet 48 to VM #48
361.90000000000003: broker_5: Sending cloudlet 49 to VM #49
361.90000000000003: broker_5: Sending cloudlet 50 to VM #50


--------------------------------------------------------------


New resource usage for the time frame starting at 421.90:
Adding: broker_6
broker_6 is starting...
422.1: broker_6: Cloud Resource List received with 1 resource(s)
422.1: broker_6: Trying to Create VM #51 in Datacenter
422.1: broker_6: Trying to Create VM #52 in Datacenter
422.1: broker_6: Trying to Create VM #53 in Datacenter
422.1: broker_6: Trying to Create VM #54 in Datacenter
422.1: broker_6: Trying to Create VM #55 in Datacenter
422.1: broker_6: Trying to Create VM #56 in Datacenter
422.1: broker_6: Trying to Create VM #57 in Datacenter
422.1: broker_6: Trying to Create VM #58 in Datacenter
422.1: broker_6: Trying to Create VM #59 in Datacenter
422.10: VM #51 has been allocated to the host #51
422.10: VM #52 has been allocated to the host #52
422.10: VM #53 has been allocated to the host #53
422.10: VM #54 has been allocated to the host #54
422.10: VM #55 has been allocated to the host #55
422.10: VM #56 has been allocated to the host #56
422.10: VM #57 has been allocated to the host #57
422.10: VM #58 has been allocated to the host #58
422.10: VM #59 has been allocated to the host #59
422.20000000000005: broker_6: VM #51 has been created in Datacenter #3, Host #51
422.20000000000005: broker_6: VM #52 has been created in Datacenter #3, Host #52
422.20000000000005: broker_6: VM #53 has been created in Datacenter #3, Host #53
422.20000000000005: broker_6: VM #54 has been created in Datacenter #3, Host #54
422.20000000000005: broker_6: VM #55 has been created in Datacenter #3, Host #55
422.20000000000005: broker_6: VM #56 has been created in Datacenter #3, Host #56
422.20000000000005: broker_6: VM #57 has been created in Datacenter #3, Host #57
422.20000000000005: broker_6: VM #58 has been created in Datacenter #3, Host #58
422.20000000000005: broker_6: VM #59 has been created in Datacenter #3, Host #59
422.20000000000005: broker_6: Sending cloudlet 51 to VM #51
422.20000000000005: broker_6: Sending cloudlet 52 to VM #52
422.20000000000005: broker_6: Sending cloudlet 53 to VM #53
422.20000000000005: broker_6: Sending cloudlet 54 to VM #54
422.20000000000005: broker_6: Sending cloudlet 55 to VM #55
422.20000000000005: broker_6: Sending cloudlet 56 to VM #56
422.20000000000005: broker_6: Sending cloudlet 57 to VM #57
422.20000000000005: broker_6: Sending cloudlet 58 to VM #58
422.20000000000005: broker_6: Sending cloudlet 59 to VM #59


--------------------------------------------------------------


New resource usage for the time frame starting at 482.20:
Adding: broker_7
broker_7 is starting...
482.40000000000003: broker_7: Cloud Resource List received with 1 resource(s)
482.40000000000003: broker_7: Trying to Create VM #60 in Datacenter
482.40000000000003: broker_7: Trying to Create VM #61 in Datacenter
482.40000000000003: broker_7: Trying to Create VM #62 in Datacenter
482.40000000000003: broker_7: Trying to Create VM #63 in Datacenter
482.40000000000003: broker_7: Trying to Create VM #64 in Datacenter
482.40000000000003: broker_7: Trying to Create VM #65 in Datacenter
482.40000000000003: broker_7: Trying to Create VM #66 in Datacenter
482.40000000000003: broker_7: Trying to Create VM #67 in Datacenter
482.40000000000003: broker_7: Trying to Create VM #68 in Datacenter
482.40000000000003: broker_7: Trying to Create VM #69 in Datacenter
482.40: VM #60 has been allocated to the host #60
482.40: VM #61 has been allocated to the host #61
482.40: VM #62 has been allocated to the host #62
482.40: VM #63 has been allocated to the host #63
482.40: VM #64 has been allocated to the host #64
482.40: VM #65 has been allocated to the host #65
482.40: VM #66 has been allocated to the host #66
482.40: VM #67 has been allocated to the host #67
482.40: VM #68 has been allocated to the host #68
482.40: VM #69 has been allocated to the host #69
482.50000000000006: broker_7: VM #60 has been created in Datacenter #3, Host #60
482.50000000000006: broker_7: VM #61 has been created in Datacenter #3, Host #61
482.50000000000006: broker_7: VM #62 has been created in Datacenter #3, Host #62
482.50000000000006: broker_7: VM #63 has been created in Datacenter #3, Host #63
482.50000000000006: broker_7: VM #64 has been created in Datacenter #3, Host #64
482.50000000000006: broker_7: VM #65 has been created in Datacenter #3, Host #65
482.50000000000006: broker_7: VM #66 has been created in Datacenter #3, Host #66
482.50000000000006: broker_7: VM #67 has been created in Datacenter #3, Host #67
482.50000000000006: broker_7: VM #68 has been created in Datacenter #3, Host #68
482.50000000000006: broker_7: VM #69 has been created in Datacenter #3, Host #69
482.50000000000006: broker_7: Sending cloudlet 60 to VM #60
482.50000000000006: broker_7: Sending cloudlet 61 to VM #61
482.50000000000006: broker_7: Sending cloudlet 62 to VM #62
482.50000000000006: broker_7: Sending cloudlet 63 to VM #63
482.50000000000006: broker_7: Sending cloudlet 64 to VM #64
482.50000000000006: broker_7: Sending cloudlet 65 to VM #65
482.50000000000006: broker_7: Sending cloudlet 66 to VM #66
482.50000000000006: broker_7: Sending cloudlet 67 to VM #67
482.50000000000006: broker_7: Sending cloudlet 68 to VM #68
482.50000000000006: broker_7: Sending cloudlet 69 to VM #69


--------------------------------------------------------------


New resource usage for the time frame starting at 542.50:
Adding: broker_8
broker_8 is starting...
542.7: broker_8: Cloud Resource List received with 1 resource(s)
542.7: broker_8: Trying to Create VM #70 in Datacenter
542.7: broker_8: Trying to Create VM #71 in Datacenter
542.7: broker_8: Trying to Create VM #72 in Datacenter
542.7: broker_8: Trying to Create VM #73 in Datacenter
542.7: broker_8: Trying to Create VM #74 in Datacenter
542.7: broker_8: Trying to Create VM #75 in Datacenter
542.7: broker_8: Trying to Create VM #76 in Datacenter
542.7: broker_8: Trying to Create VM #77 in Datacenter
542.7: broker_8: Trying to Create VM #78 in Datacenter
542.7: broker_8: Trying to Create VM #79 in Datacenter
542.7: broker_8: Trying to Create VM #80 in Datacenter
542.7: broker_8: Trying to Create VM #81 in Datacenter
542.7: broker_8: Trying to Create VM #82 in Datacenter
542.70: VM #70 has been allocated to the host #70
542.70: VM #71 has been allocated to the host #71
542.70: VM #72 has been allocated to the host #72
542.70: VM #73 has been allocated to the host #73
542.70: VM #74 has been allocated to the host #74
542.70: VM #75 has been allocated to the host #75
542.70: VM #76 has been allocated to the host #76
542.70: VM #77 has been allocated to the host #77
542.70: VM #78 has been allocated to the host #78
542.70: VM #79 has been allocated to the host #79
542.70: VM #80 has been allocated to the host #80
542.70: VM #81 has been allocated to the host #81
542.70: VM #82 has been allocated to the host #82
542.8000000000001: broker_8: VM #70 has been created in Datacenter #3, Host #70
542.8000000000001: broker_8: VM #71 has been created in Datacenter #3, Host #71
542.8000000000001: broker_8: VM #72 has been created in Datacenter #3, Host #72
542.8000000000001: broker_8: VM #73 has been created in Datacenter #3, Host #73
542.8000000000001: broker_8: VM #74 has been created in Datacenter #3, Host #74
542.8000000000001: broker_8: VM #75 has been created in Datacenter #3, Host #75
542.8000000000001: broker_8: VM #76 has been created in Datacenter #3, Host #76
542.8000000000001: broker_8: VM #77 has been created in Datacenter #3, Host #77
542.8000000000001: broker_8: VM #78 has been created in Datacenter #3, Host #78
542.8000000000001: broker_8: VM #79 has been created in Datacenter #3, Host #79
542.8000000000001: broker_8: VM #80 has been created in Datacenter #3, Host #80
542.8000000000001: broker_8: VM #81 has been created in Datacenter #3, Host #81
542.8000000000001: broker_8: VM #82 has been created in Datacenter #3, Host #82
542.8000000000001: broker_8: Sending cloudlet 70 to VM #70
542.8000000000001: broker_8: Sending cloudlet 71 to VM #71
542.8000000000001: broker_8: Sending cloudlet 72 to VM #72
542.8000000000001: broker_8: Sending cloudlet 73 to VM #73
542.8000000000001: broker_8: Sending cloudlet 74 to VM #74
542.8000000000001: broker_8: Sending cloudlet 75 to VM #75
542.8000000000001: broker_8: Sending cloudlet 76 to VM #76
542.8000000000001: broker_8: Sending cloudlet 77 to VM #77
542.8000000000001: broker_8: Sending cloudlet 78 to VM #78
542.8000000000001: broker_8: Sending cloudlet 79 to VM #79
542.8000000000001: broker_8: Sending cloudlet 80 to VM #80
542.8000000000001: broker_8: Sending cloudlet 81 to VM #81
542.8000000000001: broker_8: Sending cloudlet 82 to VM #82


--------------------------------------------------------------


New resource usage for the time frame starting at 602.80:
Adding: broker_9
broker_9 is starting...
603.0: broker_9: Cloud Resource List received with 1 resource(s)
603.0: broker_9: Trying to Create VM #83 in Datacenter
603.0: broker_9: Trying to Create VM #84 in Datacenter
603.0: broker_9: Trying to Create VM #85 in Datacenter
603.0: broker_9: Trying to Create VM #86 in Datacenter
603.0: broker_9: Trying to Create VM #87 in Datacenter
603.0: broker_9: Trying to Create VM #88 in Datacenter
603.0: broker_9: Trying to Create VM #89 in Datacenter
603.0: broker_9: Trying to Create VM #90 in Datacenter
603.0: broker_9: Trying to Create VM #91 in Datacenter
603.0: broker_9: Trying to Create VM #92 in Datacenter
603.0: broker_9: Trying to Create VM #93 in Datacenter
603.0: broker_9: Trying to Create VM #94 in Datacenter
603.0: broker_9: Trying to Create VM #95 in Datacenter
603.0: broker_9: Trying to Create VM #96 in Datacenter
603.0: broker_9: Trying to Create VM #97 in Datacenter
603.0: broker_9: Trying to Create VM #98 in Datacenter
603.0: broker_9: Trying to Create VM #99 in Datacenter
603.00: VM #83 has been allocated to the host #83
603.00: VM #84 has been allocated to the host #84
603.00: VM #85 has been allocated to the host #85
603.00: VM #86 has been allocated to the host #86
603.00: VM #87 has been allocated to the host #87
603.00: VM #88 has been allocated to the host #88
603.00: VM #89 has been allocated to the host #89
603.00: VM #90 has been allocated to the host #90
603.00: VM #91 has been allocated to the host #91
603.00: VM #92 has been allocated to the host #92
603.00: VM #93 has been allocated to the host #93
603.00: VM #94 has been allocated to the host #94
603.00: VM #95 has been allocated to the host #95
603.00: VM #96 has been allocated to the host #96
603.00: VM #97 has been allocated to the host #97
603.00: VM #98 has been allocated to the host #98
603.00: VM #99 has been allocated to the host #99
603.1: broker_9: VM #83 has been created in Datacenter #3, Host #83
603.1: broker_9: VM #84 has been created in Datacenter #3, Host #84
603.1: broker_9: VM #85 has been created in Datacenter #3, Host #85
603.1: broker_9: VM #86 has been created in Datacenter #3, Host #86
603.1: broker_9: VM #87 has been created in Datacenter #3, Host #87
603.1: broker_9: VM #88 has been created in Datacenter #3, Host #88
603.1: broker_9: VM #89 has been created in Datacenter #3, Host #89
603.1: broker_9: VM #90 has been created in Datacenter #3, Host #90
603.1: broker_9: VM #91 has been created in Datacenter #3, Host #91
603.1: broker_9: VM #92 has been created in Datacenter #3, Host #92
603.1: broker_9: VM #93 has been created in Datacenter #3, Host #93
603.1: broker_9: VM #94 has been created in Datacenter #3, Host #94
603.1: broker_9: VM #95 has been created in Datacenter #3, Host #95
603.1: broker_9: VM #96 has been created in Datacenter #3, Host #96
603.1: broker_9: VM #97 has been created in Datacenter #3, Host #97
603.1: broker_9: VM #98 has been created in Datacenter #3, Host #98
603.1: broker_9: VM #99 has been created in Datacenter #3, Host #99
603.1: broker_9: Sending cloudlet 83 to VM #83
603.1: broker_9: Sending cloudlet 84 to VM #84
603.1: broker_9: Sending cloudlet 85 to VM #85
603.1: broker_9: Sending cloudlet 86 to VM #86
603.1: broker_9: Sending cloudlet 87 to VM #87
603.1: broker_9: Sending cloudlet 88 to VM #88
603.1: broker_9: Sending cloudlet 89 to VM #89
603.1: broker_9: Sending cloudlet 90 to VM #90
603.1: broker_9: Sending cloudlet 91 to VM #91
603.1: broker_9: Sending cloudlet 92 to VM #92
603.1: broker_9: Sending cloudlet 93 to VM #93
603.1: broker_9: Sending cloudlet 94 to VM #94
603.1: broker_9: Sending cloudlet 95 to VM #95
603.1: broker_9: Sending cloudlet 96 to VM #96
603.1: broker_9: Sending cloudlet 97 to VM #97
603.1: broker_9: Sending cloudlet 98 to VM #98
603.1: broker_9: Sending cloudlet 99 to VM #99


--------------------------------------------------------------


New resource usage for the time frame starting at 663.10:
Adding: broker_10
broker_10 is starting...
663.3: broker_10: Cloud Resource List received with 1 resource(s)
663.3: broker_10: Trying to Create VM #100 in Datacenter
663.3: broker_10: Trying to Create VM #101 in Datacenter
663.3: broker_10: Trying to Create VM #102 in Datacenter
663.3: broker_10: Trying to Create VM #103 in Datacenter
663.3: broker_10: Trying to Create VM #104 in Datacenter
663.3: broker_10: Trying to Create VM #105 in Datacenter
663.3: broker_10: Trying to Create VM #106 in Datacenter
663.3: broker_10: Trying to Create VM #107 in Datacenter
663.3: broker_10: Trying to Create VM #108 in Datacenter
663.3: broker_10: Trying to Create VM #109 in Datacenter
663.30: VM #100 has been allocated to the host #100
663.30: VM #101 has been allocated to the host #101
663.30: VM #102 has been allocated to the host #102
663.30: VM #103 has been allocated to the host #103
663.30: VM #104 has been allocated to the host #104
663.30: VM #105 has been allocated to the host #105
663.30: VM #106 has been allocated to the host #106
663.30: VM #107 has been allocated to the host #107
663.30: VM #108 has been allocated to the host #108
663.30: VM #109 has been allocated to the host #109
663.4: broker_10: VM #100 has been created in Datacenter #3, Host #100
663.4: broker_10: VM #101 has been created in Datacenter #3, Host #101
663.4: broker_10: VM #102 has been created in Datacenter #3, Host #102
663.4: broker_10: VM #103 has been created in Datacenter #3, Host #103
663.4: broker_10: VM #104 has been created in Datacenter #3, Host #104
663.4: broker_10: VM #105 has been created in Datacenter #3, Host #105
663.4: broker_10: VM #106 has been created in Datacenter #3, Host #106
663.4: broker_10: VM #107 has been created in Datacenter #3, Host #107
663.4: broker_10: VM #108 has been created in Datacenter #3, Host #108
663.4: broker_10: VM #109 has been created in Datacenter #3, Host #109
663.4: broker_10: Sending cloudlet 100 to VM #100
663.4: broker_10: Sending cloudlet 101 to VM #101
663.4: broker_10: Sending cloudlet 102 to VM #102
663.4: broker_10: Sending cloudlet 103 to VM #103
663.4: broker_10: Sending cloudlet 104 to VM #104
663.4: broker_10: Sending cloudlet 105 to VM #105
663.4: broker_10: Sending cloudlet 106 to VM #106
663.4: broker_10: Sending cloudlet 107 to VM #107
663.4: broker_10: Sending cloudlet 108 to VM #108
663.4: broker_10: Sending cloudlet 109 to VM #109


--------------------------------------------------------------


New resource usage for the time frame starting at 723.40:
Adding: broker_11
broker_11 is starting...
723.5999999999999: broker_11: Cloud Resource List received with 1 resource(s)
723.5999999999999: broker_11: Trying to Create VM #110 in Datacenter
723.5999999999999: broker_11: Trying to Create VM #111 in Datacenter
723.5999999999999: broker_11: Trying to Create VM #112 in Datacenter
723.5999999999999: broker_11: Trying to Create VM #113 in Datacenter
723.5999999999999: broker_11: Trying to Create VM #114 in Datacenter
723.5999999999999: broker_11: Trying to Create VM #115 in Datacenter
723.5999999999999: broker_11: Trying to Create VM #116 in Datacenter
723.5999999999999: broker_11: Trying to Create VM #117 in Datacenter
723.5999999999999: broker_11: Trying to Create VM #118 in Datacenter
723.5999999999999: broker_11: Trying to Create VM #119 in Datacenter
723.5999999999999: broker_11: Trying to Create VM #120 in Datacenter
723.5999999999999: broker_11: Trying to Create VM #121 in Datacenter
723.5999999999999: broker_11: Trying to Create VM #122 in Datacenter
723.5999999999999: broker_11: Trying to Create VM #123 in Datacenter
723.5999999999999: broker_11: Trying to Create VM #124 in Datacenter
723.5999999999999: broker_11: Trying to Create VM #125 in Datacenter
723.5999999999999: broker_11: Trying to Create VM #126 in Datacenter
723.5999999999999: broker_11: Trying to Create VM #127 in Datacenter
723.5999999999999: broker_11: Trying to Create VM #128 in Datacenter
723.5999999999999: broker_11: Trying to Create VM #129 in Datacenter
723.60: VM #110 has been allocated to the host #110
723.60: VM #111 has been allocated to the host #111
723.60: VM #112 has been allocated to the host #112
723.60: VM #113 has been allocated to the host #113
723.60: VM #114 has been allocated to the host #114
723.60: VM #115 has been allocated to the host #115
723.60: VM #116 has been allocated to the host #116
723.60: VM #117 has been allocated to the host #117
723.60: VM #118 has been allocated to the host #118
723.60: VM #119 has been allocated to the host #119
723.60: VM #120 has been allocated to the host #120
723.60: VM #121 has been allocated to the host #121
723.60: VM #122 has been allocated to the host #122
723.60: VM #123 has been allocated to the host #123
723.60: VM #124 has been allocated to the host #124
723.60: VM #125 has been allocated to the host #125
723.60: VM #126 has been allocated to the host #126
723.60: VM #127 has been allocated to the host #127
723.60: VM #128 has been allocated to the host #128
723.60: VM #129 has been allocated to the host #129
723.6999999999999: broker_11: VM #110 has been created in Datacenter #3, Host #110
723.6999999999999: broker_11: VM #111 has been created in Datacenter #3, Host #111
723.6999999999999: broker_11: VM #112 has been created in Datacenter #3, Host #112
723.6999999999999: broker_11: VM #113 has been created in Datacenter #3, Host #113
723.6999999999999: broker_11: VM #114 has been created in Datacenter #3, Host #114
723.6999999999999: broker_11: VM #115 has been created in Datacenter #3, Host #115
723.6999999999999: broker_11: VM #116 has been created in Datacenter #3, Host #116
723.6999999999999: broker_11: VM #117 has been created in Datacenter #3, Host #117
723.6999999999999: broker_11: VM #118 has been created in Datacenter #3, Host #118
723.6999999999999: broker_11: VM #119 has been created in Datacenter #3, Host #119
723.6999999999999: broker_11: VM #120 has been created in Datacenter #3, Host #120
723.6999999999999: broker_11: VM #121 has been created in Datacenter #3, Host #121
723.6999999999999: broker_11: VM #122 has been created in Datacenter #3, Host #122
723.6999999999999: broker_11: VM #123 has been created in Datacenter #3, Host #123
723.6999999999999: broker_11: VM #124 has been created in Datacenter #3, Host #124
723.6999999999999: broker_11: VM #125 has been created in Datacenter #3, Host #125
723.6999999999999: broker_11: VM #126 has been created in Datacenter #3, Host #126
723.6999999999999: broker_11: VM #127 has been created in Datacenter #3, Host #127
723.6999999999999: broker_11: VM #128 has been created in Datacenter #3, Host #128
723.6999999999999: broker_11: VM #129 has been created in Datacenter #3, Host #129
723.6999999999999: broker_11: Sending cloudlet 110 to VM #110
723.6999999999999: broker_11: Sending cloudlet 111 to VM #111
723.6999999999999: broker_11: Sending cloudlet 112 to VM #112
723.6999999999999: broker_11: Sending cloudlet 113 to VM #113
723.6999999999999: broker_11: Sending cloudlet 114 to VM #114
723.6999999999999: broker_11: Sending cloudlet 115 to VM #115
723.6999999999999: broker_11: Sending cloudlet 116 to VM #116
723.6999999999999: broker_11: Sending cloudlet 117 to VM #117
723.6999999999999: broker_11: Sending cloudlet 118 to VM #118
723.6999999999999: broker_11: Sending cloudlet 119 to VM #119
723.6999999999999: broker_11: Sending cloudlet 120 to VM #120
723.6999999999999: broker_11: Sending cloudlet 121 to VM #121
723.6999999999999: broker_11: Sending cloudlet 122 to VM #122
723.6999999999999: broker_11: Sending cloudlet 123 to VM #123
723.6999999999999: broker_11: Sending cloudlet 124 to VM #124
723.6999999999999: broker_11: Sending cloudlet 125 to VM #125
723.6999999999999: broker_11: Sending cloudlet 126 to VM #126
723.6999999999999: broker_11: Sending cloudlet 127 to VM #127
723.6999999999999: broker_11: Sending cloudlet 128 to VM #128
723.6999999999999: broker_11: Sending cloudlet 129 to VM #129


--------------------------------------------------------------


New resource usage for the time frame starting at 783.70:
Adding: broker_12
broker_12 is starting...
783.8999999999999: broker_12: Cloud Resource List received with 1 resource(s)
783.8999999999999: broker_12: Trying to Create VM #130 in Datacenter
783.8999999999999: broker_12: Trying to Create VM #131 in Datacenter
783.8999999999999: broker_12: Trying to Create VM #132 in Datacenter
783.8999999999999: broker_12: Trying to Create VM #133 in Datacenter
783.8999999999999: broker_12: Trying to Create VM #134 in Datacenter
783.8999999999999: broker_12: Trying to Create VM #135 in Datacenter
783.8999999999999: broker_12: Trying to Create VM #136 in Datacenter
783.8999999999999: broker_12: Trying to Create VM #137 in Datacenter
783.8999999999999: broker_12: Trying to Create VM #138 in Datacenter
783.8999999999999: broker_12: Trying to Create VM #139 in Datacenter
783.8999999999999: broker_12: Trying to Create VM #140 in Datacenter
783.8999999999999: broker_12: Trying to Create VM #141 in Datacenter
783.90: VM #130 has been allocated to the host #130
783.90: VM #131 has been allocated to the host #131
783.90: VM #132 has been allocated to the host #132
783.90: VM #133 has been allocated to the host #133
783.90: VM #134 has been allocated to the host #134
783.90: VM #135 has been allocated to the host #135
783.90: VM #136 has been allocated to the host #136
783.90: VM #137 has been allocated to the host #137
783.90: VM #138 has been allocated to the host #138
783.90: VM #139 has been allocated to the host #139
783.90: VM #140 has been allocated to the host #140
783.90: VM #141 has been allocated to the host #141
783.9999999999999: broker_12: VM #130 has been created in Datacenter #3, Host #130
783.9999999999999: broker_12: VM #131 has been created in Datacenter #3, Host #131
783.9999999999999: broker_12: VM #132 has been created in Datacenter #3, Host #132
783.9999999999999: broker_12: VM #133 has been created in Datacenter #3, Host #133
783.9999999999999: broker_12: VM #134 has been created in Datacenter #3, Host #134
783.9999999999999: broker_12: VM #135 has been created in Datacenter #3, Host #135
783.9999999999999: broker_12: VM #136 has been created in Datacenter #3, Host #136
783.9999999999999: broker_12: VM #137 has been created in Datacenter #3, Host #137
783.9999999999999: broker_12: VM #138 has been created in Datacenter #3, Host #138
783.9999999999999: broker_12: VM #139 has been created in Datacenter #3, Host #139
783.9999999999999: broker_12: VM #140 has been created in Datacenter #3, Host #140
783.9999999999999: broker_12: VM #141 has been created in Datacenter #3, Host #141
783.9999999999999: broker_12: Sending cloudlet 130 to VM #130
783.9999999999999: broker_12: Sending cloudlet 131 to VM #131
783.9999999999999: broker_12: Sending cloudlet 132 to VM #132
783.9999999999999: broker_12: Sending cloudlet 133 to VM #133
783.9999999999999: broker_12: Sending cloudlet 134 to VM #134
783.9999999999999: broker_12: Sending cloudlet 135 to VM #135
783.9999999999999: broker_12: Sending cloudlet 136 to VM #136
783.9999999999999: broker_12: Sending cloudlet 137 to VM #137
783.9999999999999: broker_12: Sending cloudlet 138 to VM #138
783.9999999999999: broker_12: Sending cloudlet 139 to VM #139
783.9999999999999: broker_12: Sending cloudlet 140 to VM #140
783.9999999999999: broker_12: Sending cloudlet 141 to VM #141


--------------------------------------------------------------


New resource usage for the time frame starting at 844.00:
Adding: broker_13
broker_13 is starting...
844.1999999999998: broker_13: Cloud Resource List received with 1 resource(s)


--------------------------------------------------------------


New resource usage for the time frame starting at 904.00:
Adding: broker_14
broker_14 is starting...
904.4999999999998: broker_14: Cloud Resource List received with 1 resource(s)
904.4999999999998: broker_14: Trying to Create VM #142 in Datacenter
904.4999999999998: broker_14: Trying to Create VM #143 in Datacenter
904.4999999999998: broker_14: Trying to Create VM #144 in Datacenter
904.4999999999998: broker_14: Trying to Create VM #145 in Datacenter
904.4999999999998: broker_14: Trying to Create VM #146 in Datacenter
904.4999999999998: broker_14: Trying to Create VM #147 in Datacenter
904.4999999999998: broker_14: Trying to Create VM #148 in Datacenter
904.4999999999998: broker_14: Trying to Create VM #149 in Datacenter
904.4999999999998: broker_14: Trying to Create VM #150 in Datacenter
904.50: VM #142 has been allocated to the host #142
904.50: VM #143 has been allocated to the host #143
904.50: VM #144 has been allocated to the host #144
904.50: VM #145 has been allocated to the host #145
904.50: VM #146 has been allocated to the host #146
904.50: VM #147 has been allocated to the host #147
904.50: VM #148 has been allocated to the host #148
904.50: VM #149 has been allocated to the host #149
904.50: VM #150 has been allocated to the host #150
904.5999999999998: broker_14: VM #142 has been created in Datacenter #3, Host #142
904.5999999999998: broker_14: VM #143 has been created in Datacenter #3, Host #143
904.5999999999998: broker_14: VM #144 has been created in Datacenter #3, Host #144
904.5999999999998: broker_14: VM #145 has been created in Datacenter #3, Host #145
904.5999999999998: broker_14: VM #146 has been created in Datacenter #3, Host #146
904.5999999999998: broker_14: VM #147 has been created in Datacenter #3, Host #147
904.5999999999998: broker_14: VM #148 has been created in Datacenter #3, Host #148
904.5999999999998: broker_14: VM #149 has been created in Datacenter #3, Host #149
904.5999999999998: broker_14: VM #150 has been created in Datacenter #3, Host #150
904.5999999999998: broker_14: Sending cloudlet 142 to VM #142
904.5999999999998: broker_14: Sending cloudlet 143 to VM #143
904.5999999999998: broker_14: Sending cloudlet 144 to VM #144
904.5999999999998: broker_14: Sending cloudlet 145 to VM #145
904.5999999999998: broker_14: Sending cloudlet 146 to VM #146
904.5999999999998: broker_14: Sending cloudlet 147 to VM #147
904.5999999999998: broker_14: Sending cloudlet 148 to VM #148
904.5999999999998: broker_14: Sending cloudlet 149 to VM #149
904.5999999999998: broker_14: Sending cloudlet 150 to VM #150


--------------------------------------------------------------


New resource usage for the time frame starting at 964.60:
Adding: broker_15
broker_15 is starting...
964.7999999999997: broker_15: Cloud Resource List received with 1 resource(s)


--------------------------------------------------------------


New resource usage for the time frame starting at 1024.60:
Adding: broker_16
broker_16 is starting...
1025.0999999999997: broker_16: Cloud Resource List received with 1 resource(s)
1025.0999999999997: broker_16: Trying to Create VM #151 in Datacenter
1025.0999999999997: broker_16: Trying to Create VM #152 in Datacenter
1025.0999999999997: broker_16: Trying to Create VM #153 in Datacenter
1025.0999999999997: broker_16: Trying to Create VM #154 in Datacenter
1025.0999999999997: broker_16: Trying to Create VM #155 in Datacenter
1025.0999999999997: broker_16: Trying to Create VM #156 in Datacenter
1025.0999999999997: broker_16: Trying to Create VM #157 in Datacenter
1025.0999999999997: broker_16: Trying to Create VM #158 in Datacenter
1025.0999999999997: broker_16: Trying to Create VM #159 in Datacenter
1025.10: VM #151 has been allocated to the host #151
1025.10: VM #152 has been allocated to the host #152
1025.10: VM #153 has been allocated to the host #153
1025.10: VM #154 has been allocated to the host #154
1025.10: VM #155 has been allocated to the host #155
1025.10: VM #156 has been allocated to the host #156
1025.10: VM #157 has been allocated to the host #157
1025.10: VM #158 has been allocated to the host #158
1025.10: VM #159 has been allocated to the host #159
1025.1999999999996: broker_16: VM #151 has been created in Datacenter #3, Host #151
1025.1999999999996: broker_16: VM #152 has been created in Datacenter #3, Host #152
1025.1999999999996: broker_16: VM #153 has been created in Datacenter #3, Host #153
1025.1999999999996: broker_16: VM #154 has been created in Datacenter #3, Host #154
1025.1999999999996: broker_16: VM #155 has been created in Datacenter #3, Host #155
1025.1999999999996: broker_16: VM #156 has been created in Datacenter #3, Host #156
1025.1999999999996: broker_16: VM #157 has been created in Datacenter #3, Host #157
1025.1999999999996: broker_16: VM #158 has been created in Datacenter #3, Host #158
1025.1999999999996: broker_16: VM #159 has been created in Datacenter #3, Host #159
1025.1999999999996: broker_16: Sending cloudlet 151 to VM #151
1025.1999999999996: broker_16: Sending cloudlet 152 to VM #152
1025.1999999999996: broker_16: Sending cloudlet 153 to VM #153
1025.1999999999996: broker_16: Sending cloudlet 154 to VM #154
1025.1999999999996: broker_16: Sending cloudlet 155 to VM #155
1025.1999999999996: broker_16: Sending cloudlet 156 to VM #156
1025.1999999999996: broker_16: Sending cloudlet 157 to VM #157
1025.1999999999996: broker_16: Sending cloudlet 158 to VM #158
1025.1999999999996: broker_16: Sending cloudlet 159 to VM #159


--------------------------------------------------------------


New resource usage for the time frame starting at 1085.20:
Adding: broker_17
broker_17 is starting...
1085.3999999999996: broker_17: Cloud Resource List received with 1 resource(s)
1085.3999999999996: broker_17: Trying to Create VM #160 in Datacenter
1085.3999999999996: broker_17: Trying to Create VM #161 in Datacenter
1085.3999999999996: broker_17: Trying to Create VM #162 in Datacenter
1085.3999999999996: broker_17: Trying to Create VM #163 in Datacenter
1085.40: VM #160 has been allocated to the host #160
1085.40: VM #161 has been allocated to the host #161
1085.40: VM #162 has been allocated to the host #162
1085.40: VM #163 has been allocated to the host #163
1085.4999999999995: broker_17: VM #160 has been created in Datacenter #3, Host #160
1085.4999999999995: broker_17: VM #161 has been created in Datacenter #3, Host #161
1085.4999999999995: broker_17: VM #162 has been created in Datacenter #3, Host #162
1085.4999999999995: broker_17: VM #163 has been created in Datacenter #3, Host #163
1085.4999999999995: broker_17: Sending cloudlet 160 to VM #160
1085.4999999999995: broker_17: Sending cloudlet 161 to VM #161
1085.4999999999995: broker_17: Sending cloudlet 162 to VM #162
1085.4999999999995: broker_17: Sending cloudlet 163 to VM #163


--------------------------------------------------------------


New resource usage for the time frame starting at 1145.50:
Adding: broker_18
broker_18 is starting...
1145.6999999999996: broker_18: Cloud Resource List received with 1 resource(s)
1145.6999999999996: broker_18: Trying to Create VM #164 in Datacenter
1145.6999999999996: broker_18: Trying to Create VM #165 in Datacenter
1145.6999999999996: broker_18: Trying to Create VM #166 in Datacenter
1145.6999999999996: broker_18: Trying to Create VM #167 in Datacenter
1145.6999999999996: broker_18: Trying to Create VM #168 in Datacenter
1145.6999999999996: broker_18: Trying to Create VM #169 in Datacenter
1145.6999999999996: broker_18: Trying to Create VM #170 in Datacenter
1145.70: VM #164 has been allocated to the host #164
1145.70: VM #165 has been allocated to the host #165
1145.70: VM #166 has been allocated to the host #166
1145.70: VM #167 has been allocated to the host #167
1145.70: VM #168 has been allocated to the host #168
1145.70: VM #169 has been allocated to the host #169
1145.70: VM #170 has been allocated to the host #170
1145.7999999999995: broker_18: VM #164 has been created in Datacenter #3, Host #164
1145.7999999999995: broker_18: VM #165 has been created in Datacenter #3, Host #165
1145.7999999999995: broker_18: VM #166 has been created in Datacenter #3, Host #166
1145.7999999999995: broker_18: VM #167 has been created in Datacenter #3, Host #167
1145.7999999999995: broker_18: VM #168 has been created in Datacenter #3, Host #168
1145.7999999999995: broker_18: VM #169 has been created in Datacenter #3, Host #169
1145.7999999999995: broker_18: VM #170 has been created in Datacenter #3, Host #170
1145.7999999999995: broker_18: Sending cloudlet 164 to VM #164
1145.7999999999995: broker_18: Sending cloudlet 165 to VM #165
1145.7999999999995: broker_18: Sending cloudlet 166 to VM #166
1145.7999999999995: broker_18: Sending cloudlet 167 to VM #167
1145.7999999999995: broker_18: Sending cloudlet 168 to VM #168
1145.7999999999995: broker_18: Sending cloudlet 169 to VM #169
1145.7999999999995: broker_18: Sending cloudlet 170 to VM #170


--------------------------------------------------------------


New resource usage for the time frame starting at 1205.80:
Adding: broker_19
broker_19 is starting...
1205.9999999999995: broker_19: Cloud Resource List received with 1 resource(s)
1205.9999999999995: broker_19: Trying to Create VM #171 in Datacenter
1205.9999999999995: broker_19: Trying to Create VM #172 in Datacenter
1205.9999999999995: broker_19: Trying to Create VM #173 in Datacenter
1205.9999999999995: broker_19: Trying to Create VM #174 in Datacenter
1205.9999999999995: broker_19: Trying to Create VM #175 in Datacenter
1205.9999999999995: broker_19: Trying to Create VM #176 in Datacenter
1206.00: VM #171 has been allocated to the host #171
1206.00: VM #172 has been allocated to the host #172
1206.00: VM #173 has been allocated to the host #173
1206.00: VM #174 has been allocated to the host #174
1206.00: VM #175 has been allocated to the host #175
1206.00: VM #176 has been allocated to the host #176
1206.0999999999995: broker_19: VM #171 has been created in Datacenter #3, Host #171
1206.0999999999995: broker_19: VM #172 has been created in Datacenter #3, Host #172
1206.0999999999995: broker_19: VM #173 has been created in Datacenter #3, Host #173
1206.0999999999995: broker_19: VM #174 has been created in Datacenter #3, Host #174
1206.0999999999995: broker_19: VM #175 has been created in Datacenter #3, Host #175
1206.0999999999995: broker_19: VM #176 has been created in Datacenter #3, Host #176
1206.0999999999995: broker_19: Sending cloudlet 171 to VM #171
1206.0999999999995: broker_19: Sending cloudlet 172 to VM #172
1206.0999999999995: broker_19: Sending cloudlet 173 to VM #173
1206.0999999999995: broker_19: Sending cloudlet 174 to VM #174
1206.0999999999995: broker_19: Sending cloudlet 175 to VM #175
1206.0999999999995: broker_19: Sending cloudlet 176 to VM #176


--------------------------------------------------------------


New resource usage for the time frame starting at 1266.10:
Adding: broker_20
broker_20 is starting...
1266.2999999999995: broker_20: Cloud Resource List received with 1 resource(s)
1266.2999999999995: broker_20: Trying to Create VM #177 in Datacenter
1266.2999999999995: broker_20: Trying to Create VM #178 in Datacenter
1266.2999999999995: broker_20: Trying to Create VM #179 in Datacenter
1266.2999999999995: broker_20: Trying to Create VM #180 in Datacenter
1266.2999999999995: broker_20: Trying to Create VM #181 in Datacenter
1266.2999999999995: broker_20: Trying to Create VM #182 in Datacenter
1266.2999999999995: broker_20: Trying to Create VM #183 in Datacenter
1266.2999999999995: broker_20: Trying to Create VM #184 in Datacenter
1266.30: VM #177 has been allocated to the host #177
1266.30: VM #178 has been allocated to the host #178
1266.30: VM #179 has been allocated to the host #179
1266.30: VM #180 has been allocated to the host #180
1266.30: VM #181 has been allocated to the host #181
1266.30: VM #182 has been allocated to the host #182
1266.30: VM #183 has been allocated to the host #183
1266.30: VM #184 has been allocated to the host #184
1266.3999999999994: broker_20: VM #177 has been created in Datacenter #3, Host #177
1266.3999999999994: broker_20: VM #178 has been created in Datacenter #3, Host #178
1266.3999999999994: broker_20: VM #179 has been created in Datacenter #3, Host #179
1266.3999999999994: broker_20: VM #180 has been created in Datacenter #3, Host #180
1266.3999999999994: broker_20: VM #181 has been created in Datacenter #3, Host #181
1266.3999999999994: broker_20: VM #182 has been created in Datacenter #3, Host #182
1266.3999999999994: broker_20: VM #183 has been created in Datacenter #3, Host #183
1266.3999999999994: broker_20: VM #184 has been created in Datacenter #3, Host #184
1266.3999999999994: broker_20: Sending cloudlet 177 to VM #177
1266.3999999999994: broker_20: Sending cloudlet 178 to VM #178
1266.3999999999994: broker_20: Sending cloudlet 179 to VM #179
1266.3999999999994: broker_20: Sending cloudlet 180 to VM #180
1266.3999999999994: broker_20: Sending cloudlet 181 to VM #181
1266.3999999999994: broker_20: Sending cloudlet 182 to VM #182
1266.3999999999994: broker_20: Sending cloudlet 183 to VM #183
1266.3999999999994: broker_20: Sending cloudlet 184 to VM #184


--------------------------------------------------------------


New resource usage for the time frame starting at 1326.40:
Adding: broker_21
broker_21 is starting...
1326.5999999999995: broker_21: Cloud Resource List received with 1 resource(s)
1326.5999999999995: broker_21: Trying to Create VM #185 in Datacenter
1326.5999999999995: broker_21: Trying to Create VM #186 in Datacenter
1326.5999999999995: broker_21: Trying to Create VM #187 in Datacenter
1326.5999999999995: broker_21: Trying to Create VM #188 in Datacenter
1326.5999999999995: broker_21: Trying to Create VM #189 in Datacenter
1326.5999999999995: broker_21: Trying to Create VM #190 in Datacenter
1326.5999999999995: broker_21: Trying to Create VM #191 in Datacenter
1326.5999999999995: broker_21: Trying to Create VM #192 in Datacenter
1326.5999999999995: broker_21: Trying to Create VM #193 in Datacenter
1326.5999999999995: broker_21: Trying to Create VM #194 in Datacenter
1326.5999999999995: broker_21: Trying to Create VM #195 in Datacenter
1326.60: VM #185 has been allocated to the host #185
1326.60: VM #186 has been allocated to the host #186
1326.60: VM #187 has been allocated to the host #187
1326.60: VM #188 has been allocated to the host #188
1326.60: VM #189 has been allocated to the host #189
1326.60: VM #190 has been allocated to the host #190
1326.60: VM #191 has been allocated to the host #191
1326.60: VM #192 has been allocated to the host #192
1326.60: VM #193 has been allocated to the host #193
1326.60: VM #194 has been allocated to the host #194
1326.60: VM #195 has been allocated to the host #195
1326.6999999999994: broker_21: VM #185 has been created in Datacenter #3, Host #185
1326.6999999999994: broker_21: VM #186 has been created in Datacenter #3, Host #186
1326.6999999999994: broker_21: VM #187 has been created in Datacenter #3, Host #187
1326.6999999999994: broker_21: VM #188 has been created in Datacenter #3, Host #188
1326.6999999999994: broker_21: VM #189 has been created in Datacenter #3, Host #189
1326.6999999999994: broker_21: VM #190 has been created in Datacenter #3, Host #190
1326.6999999999994: broker_21: VM #191 has been created in Datacenter #3, Host #191
1326.6999999999994: broker_21: VM #192 has been created in Datacenter #3, Host #192
1326.6999999999994: broker_21: VM #193 has been created in Datacenter #3, Host #193
1326.6999999999994: broker_21: VM #194 has been created in Datacenter #3, Host #194
1326.6999999999994: broker_21: VM #195 has been created in Datacenter #3, Host #195
1326.6999999999994: broker_21: Sending cloudlet 185 to VM #185
1326.6999999999994: broker_21: Sending cloudlet 186 to VM #186
1326.6999999999994: broker_21: Sending cloudlet 187 to VM #187
1326.6999999999994: broker_21: Sending cloudlet 188 to VM #188
1326.6999999999994: broker_21: Sending cloudlet 189 to VM #189
1326.6999999999994: broker_21: Sending cloudlet 190 to VM #190
1326.6999999999994: broker_21: Sending cloudlet 191 to VM #191
1326.6999999999994: broker_21: Sending cloudlet 192 to VM #192
1326.6999999999994: broker_21: Sending cloudlet 193 to VM #193
1326.6999999999994: broker_21: Sending cloudlet 194 to VM #194
1326.6999999999994: broker_21: Sending cloudlet 195 to VM #195


--------------------------------------------------------------


New resource usage for the time frame starting at 1386.70:
Adding: broker_22
broker_22 is starting...
1386.8999999999994: broker_22: Cloud Resource List received with 1 resource(s)
1386.8999999999994: broker_22: Trying to Create VM #196 in Datacenter
1386.8999999999994: broker_22: Trying to Create VM #197 in Datacenter
1386.8999999999994: broker_22: Trying to Create VM #198 in Datacenter
1386.8999999999994: broker_22: Trying to Create VM #199 in Datacenter
1386.8999999999994: broker_22: Trying to Create VM #200 in Datacenter
1386.8999999999994: broker_22: Trying to Create VM #201 in Datacenter
1386.8999999999994: broker_22: Trying to Create VM #202 in Datacenter
1386.8999999999994: broker_22: Trying to Create VM #203 in Datacenter
1386.8999999999994: broker_22: Trying to Create VM #204 in Datacenter
1386.8999999999994: broker_22: Trying to Create VM #205 in Datacenter
1386.8999999999994: broker_22: Trying to Create VM #206 in Datacenter
1386.8999999999994: broker_22: Trying to Create VM #207 in Datacenter
1386.8999999999994: broker_22: Trying to Create VM #208 in Datacenter
1386.8999999999994: broker_22: Trying to Create VM #209 in Datacenter
1386.8999999999994: broker_22: Trying to Create VM #210 in Datacenter
1386.8999999999994: broker_22: Trying to Create VM #211 in Datacenter
1386.8999999999994: broker_22: Trying to Create VM #212 in Datacenter
1386.90: VM #196 has been allocated to the host #196
1386.90: VM #197 has been allocated to the host #197
1386.90: VM #198 has been allocated to the host #198
1386.90: VM #199 has been allocated to the host #199
1386.90: VM #200 has been allocated to the host #0
1386.90: VM #201 has been allocated to the host #1
1386.90: VM #202 has been allocated to the host #2
1386.90: VM #203 has been allocated to the host #3
1386.90: VM #204 has been allocated to the host #4
1386.90: VM #205 has been allocated to the host #5
1386.90: VM #206 has been allocated to the host #6
1386.90: VM #207 has been allocated to the host #7
1386.90: VM #208 has been allocated to the host #8
1386.90: VM #209 has been allocated to the host #9
1386.90: VM #210 has been allocated to the host #10
1386.90: VM #211 has been allocated to the host #11
1386.90: VM #212 has been allocated to the host #12
1386.9999999999993: broker_22: VM #196 has been created in Datacenter #3, Host #196
1386.9999999999993: broker_22: VM #197 has been created in Datacenter #3, Host #197
1386.9999999999993: broker_22: VM #198 has been created in Datacenter #3, Host #198
1386.9999999999993: broker_22: VM #199 has been created in Datacenter #3, Host #199
1386.9999999999993: broker_22: VM #200 has been created in Datacenter #3, Host #0
1386.9999999999993: broker_22: VM #201 has been created in Datacenter #3, Host #1
1386.9999999999993: broker_22: VM #202 has been created in Datacenter #3, Host #2
1386.9999999999993: broker_22: VM #203 has been created in Datacenter #3, Host #3
1386.9999999999993: broker_22: VM #204 has been created in Datacenter #3, Host #4
1386.9999999999993: broker_22: VM #205 has been created in Datacenter #3, Host #5
1386.9999999999993: broker_22: VM #206 has been created in Datacenter #3, Host #6
1386.9999999999993: broker_22: VM #207 has been created in Datacenter #3, Host #7
1386.9999999999993: broker_22: VM #208 has been created in Datacenter #3, Host #8
1386.9999999999993: broker_22: VM #209 has been created in Datacenter #3, Host #9
1386.9999999999993: broker_22: VM #210 has been created in Datacenter #3, Host #10
1386.9999999999993: broker_22: VM #211 has been created in Datacenter #3, Host #11
1386.9999999999993: broker_22: VM #212 has been created in Datacenter #3, Host #12
1386.9999999999993: broker_22: Sending cloudlet 196 to VM #196
1386.9999999999993: broker_22: Sending cloudlet 197 to VM #197
1386.9999999999993: broker_22: Sending cloudlet 198 to VM #198
1386.9999999999993: broker_22: Sending cloudlet 199 to VM #199
1386.9999999999993: broker_22: Sending cloudlet 200 to VM #200
1386.9999999999993: broker_22: Sending cloudlet 201 to VM #201
1386.9999999999993: broker_22: Sending cloudlet 202 to VM #202
1386.9999999999993: broker_22: Sending cloudlet 203 to VM #203
1386.9999999999993: broker_22: Sending cloudlet 204 to VM #204
1386.9999999999993: broker_22: Sending cloudlet 205 to VM #205
1386.9999999999993: broker_22: Sending cloudlet 206 to VM #206
1386.9999999999993: broker_22: Sending cloudlet 207 to VM #207
1386.9999999999993: broker_22: Sending cloudlet 208 to VM #208
1386.9999999999993: broker_22: Sending cloudlet 209 to VM #209
1386.9999999999993: broker_22: Sending cloudlet 210 to VM #210
1386.9999999999993: broker_22: Sending cloudlet 211 to VM #211
1386.9999999999993: broker_22: Sending cloudlet 212 to VM #212


--------------------------------------------------------------


New resource usage for the time frame starting at 1447.00:
Adding: broker_23
broker_23 is starting...
1447.1999999999994: broker_23: Cloud Resource List received with 1 resource(s)
1447.1999999999994: broker_23: Trying to Create VM #213 in Datacenter
1447.1999999999994: broker_23: Trying to Create VM #214 in Datacenter
1447.1999999999994: broker_23: Trying to Create VM #215 in Datacenter
1447.1999999999994: broker_23: Trying to Create VM #216 in Datacenter
1447.1999999999994: broker_23: Trying to Create VM #217 in Datacenter
1447.1999999999994: broker_23: Trying to Create VM #218 in Datacenter
1447.1999999999994: broker_23: Trying to Create VM #219 in Datacenter
1447.1999999999994: broker_23: Trying to Create VM #220 in Datacenter
1447.1999999999994: broker_23: Trying to Create VM #221 in Datacenter
1447.1999999999994: broker_23: Trying to Create VM #222 in Datacenter
1447.1999999999994: broker_23: Trying to Create VM #223 in Datacenter
1447.1999999999994: broker_23: Trying to Create VM #224 in Datacenter
1447.1999999999994: broker_23: Trying to Create VM #225 in Datacenter
1447.1999999999994: broker_23: Trying to Create VM #226 in Datacenter
1447.1999999999994: broker_23: Trying to Create VM #227 in Datacenter
1447.1999999999994: broker_23: Trying to Create VM #228 in Datacenter
1447.1999999999994: broker_23: Trying to Create VM #229 in Datacenter
1447.20: VM #213 has been allocated to the host #13
1447.20: VM #214 has been allocated to the host #14
1447.20: VM #215 has been allocated to the host #15
1447.20: VM #216 has been allocated to the host #16
1447.20: VM #217 has been allocated to the host #17
1447.20: VM #218 has been allocated to the host #18
1447.20: VM #219 has been allocated to the host #19
1447.20: VM #220 has been allocated to the host #20
1447.20: VM #221 has been allocated to the host #21
1447.20: VM #222 has been allocated to the host #22
1447.20: VM #223 has been allocated to the host #23
1447.20: VM #224 has been allocated to the host #24
1447.20: VM #225 has been allocated to the host #25
1447.20: VM #226 has been allocated to the host #26
1447.20: VM #227 has been allocated to the host #27
1447.20: VM #228 has been allocated to the host #28
1447.20: VM #229 has been allocated to the host #29
1447.2999999999993: broker_23: VM #213 has been created in Datacenter #3, Host #13
1447.2999999999993: broker_23: VM #214 has been created in Datacenter #3, Host #14
1447.2999999999993: broker_23: VM #215 has been created in Datacenter #3, Host #15
1447.2999999999993: broker_23: VM #216 has been created in Datacenter #3, Host #16
1447.2999999999993: broker_23: VM #217 has been created in Datacenter #3, Host #17
1447.2999999999993: broker_23: VM #218 has been created in Datacenter #3, Host #18
1447.2999999999993: broker_23: VM #219 has been created in Datacenter #3, Host #19
1447.2999999999993: broker_23: VM #220 has been created in Datacenter #3, Host #20
1447.2999999999993: broker_23: VM #221 has been created in Datacenter #3, Host #21
1447.2999999999993: broker_23: VM #222 has been created in Datacenter #3, Host #22
1447.2999999999993: broker_23: VM #223 has been created in Datacenter #3, Host #23
1447.2999999999993: broker_23: VM #224 has been created in Datacenter #3, Host #24
1447.2999999999993: broker_23: VM #225 has been created in Datacenter #3, Host #25
1447.2999999999993: broker_23: VM #226 has been created in Datacenter #3, Host #26
1447.2999999999993: broker_23: VM #227 has been created in Datacenter #3, Host #27
1447.2999999999993: broker_23: VM #228 has been created in Datacenter #3, Host #28
1447.2999999999993: broker_23: VM #229 has been created in Datacenter #3, Host #29
1447.2999999999993: broker_23: Sending cloudlet 213 to VM #213
1447.2999999999993: broker_23: Sending cloudlet 214 to VM #214
1447.2999999999993: broker_23: Sending cloudlet 215 to VM #215
1447.2999999999993: broker_23: Sending cloudlet 216 to VM #216
1447.2999999999993: broker_23: Sending cloudlet 217 to VM #217
1447.2999999999993: broker_23: Sending cloudlet 218 to VM #218
1447.2999999999993: broker_23: Sending cloudlet 219 to VM #219
1447.2999999999993: broker_23: Sending cloudlet 220 to VM #220
1447.2999999999993: broker_23: Sending cloudlet 221 to VM #221
1447.2999999999993: broker_23: Sending cloudlet 222 to VM #222
1447.2999999999993: broker_23: Sending cloudlet 223 to VM #223
1447.2999999999993: broker_23: Sending cloudlet 224 to VM #224
1447.2999999999993: broker_23: Sending cloudlet 225 to VM #225
1447.2999999999993: broker_23: Sending cloudlet 226 to VM #226
1447.2999999999993: broker_23: Sending cloudlet 227 to VM #227
1447.2999999999993: broker_23: Sending cloudlet 228 to VM #228
1447.2999999999993: broker_23: Sending cloudlet 229 to VM #229


--------------------------------------------------------------


New resource usage for the time frame starting at 1507.30:
Adding: broker_24
broker_24 is starting...
1507.4999999999993: broker_24: Cloud Resource List received with 1 resource(s)
1507.4999999999993: broker_24: Trying to Create VM #230 in Datacenter
1507.4999999999993: broker_24: Trying to Create VM #231 in Datacenter
1507.4999999999993: broker_24: Trying to Create VM #232 in Datacenter
1507.4999999999993: broker_24: Trying to Create VM #233 in Datacenter
1507.4999999999993: broker_24: Trying to Create VM #234 in Datacenter
1507.50: VM #230 has been allocated to the host #30
1507.50: VM #231 has been allocated to the host #31
1507.50: VM #232 has been allocated to the host #32
1507.50: VM #233 has been allocated to the host #33
1507.50: VM #234 has been allocated to the host #34
1507.5999999999992: broker_24: VM #230 has been created in Datacenter #3, Host #30
1507.5999999999992: broker_24: VM #231 has been created in Datacenter #3, Host #31
1507.5999999999992: broker_24: VM #232 has been created in Datacenter #3, Host #32
1507.5999999999992: broker_24: VM #233 has been created in Datacenter #3, Host #33
1507.5999999999992: broker_24: VM #234 has been created in Datacenter #3, Host #34
1507.5999999999992: broker_24: Sending cloudlet 230 to VM #230
1507.5999999999992: broker_24: Sending cloudlet 231 to VM #231
1507.5999999999992: broker_24: Sending cloudlet 232 to VM #232
1507.5999999999992: broker_24: Sending cloudlet 233 to VM #233
1507.5999999999992: broker_24: Sending cloudlet 234 to VM #234


--------------------------------------------------------------


New resource usage for the time frame starting at 1567.60:
Adding: broker_25
broker_25 is starting...
1567.7999999999993: broker_25: Cloud Resource List received with 1 resource(s)
1567.7999999999993: broker_25: Trying to Create VM #235 in Datacenter
1567.7999999999993: broker_25: Trying to Create VM #236 in Datacenter
1567.7999999999993: broker_25: Trying to Create VM #237 in Datacenter
1567.7999999999993: broker_25: Trying to Create VM #238 in Datacenter
1567.7999999999993: broker_25: Trying to Create VM #239 in Datacenter
1567.7999999999993: broker_25: Trying to Create VM #240 in Datacenter
1567.7999999999993: broker_25: Trying to Create VM #241 in Datacenter
1567.7999999999993: broker_25: Trying to Create VM #242 in Datacenter
1567.7999999999993: broker_25: Trying to Create VM #243 in Datacenter
1567.7999999999993: broker_25: Trying to Create VM #244 in Datacenter
1567.7999999999993: broker_25: Trying to Create VM #245 in Datacenter
1567.7999999999993: broker_25: Trying to Create VM #246 in Datacenter
1567.7999999999993: broker_25: Trying to Create VM #247 in Datacenter
1567.7999999999993: broker_25: Trying to Create VM #248 in Datacenter
1567.7999999999993: broker_25: Trying to Create VM #249 in Datacenter
1567.7999999999993: broker_25: Trying to Create VM #250 in Datacenter
1567.7999999999993: broker_25: Trying to Create VM #251 in Datacenter
1567.7999999999993: broker_25: Trying to Create VM #252 in Datacenter
1567.80: VM #235 has been allocated to the host #35
1567.80: VM #236 has been allocated to the host #36
1567.80: VM #237 has been allocated to the host #37
1567.80: VM #238 has been allocated to the host #38
1567.80: VM #239 has been allocated to the host #39
1567.80: VM #240 has been allocated to the host #40
1567.80: VM #241 has been allocated to the host #41
1567.80: VM #242 has been allocated to the host #42
1567.80: VM #243 has been allocated to the host #43
1567.80: VM #244 has been allocated to the host #44
1567.80: VM #245 has been allocated to the host #45
1567.80: VM #246 has been allocated to the host #46
1567.80: VM #247 has been allocated to the host #47
1567.80: VM #248 has been allocated to the host #48
1567.80: VM #249 has been allocated to the host #49
1567.80: VM #250 has been allocated to the host #50
1567.80: VM #251 has been allocated to the host #51
1567.80: VM #252 has been allocated to the host #52
1567.8999999999992: broker_25: VM #235 has been created in Datacenter #3, Host #35
1567.8999999999992: broker_25: VM #236 has been created in Datacenter #3, Host #36
1567.8999999999992: broker_25: VM #237 has been created in Datacenter #3, Host #37
1567.8999999999992: broker_25: VM #238 has been created in Datacenter #3, Host #38
1567.8999999999992: broker_25: VM #239 has been created in Datacenter #3, Host #39
1567.8999999999992: broker_25: VM #240 has been created in Datacenter #3, Host #40
1567.8999999999992: broker_25: VM #241 has been created in Datacenter #3, Host #41
1567.8999999999992: broker_25: VM #242 has been created in Datacenter #3, Host #42
1567.8999999999992: broker_25: VM #243 has been created in Datacenter #3, Host #43
1567.8999999999992: broker_25: VM #244 has been created in Datacenter #3, Host #44
1567.8999999999992: broker_25: VM #245 has been created in Datacenter #3, Host #45
1567.8999999999992: broker_25: VM #246 has been created in Datacenter #3, Host #46
1567.8999999999992: broker_25: VM #247 has been created in Datacenter #3, Host #47
1567.8999999999992: broker_25: VM #248 has been created in Datacenter #3, Host #48
1567.8999999999992: broker_25: VM #249 has been created in Datacenter #3, Host #49
1567.8999999999992: broker_25: VM #250 has been created in Datacenter #3, Host #50
1567.8999999999992: broker_25: VM #251 has been created in Datacenter #3, Host #51
1567.8999999999992: broker_25: VM #252 has been created in Datacenter #3, Host #52
1567.8999999999992: broker_25: Sending cloudlet 235 to VM #235
1567.8999999999992: broker_25: Sending cloudlet 236 to VM #236
1567.8999999999992: broker_25: Sending cloudlet 237 to VM #237
1567.8999999999992: broker_25: Sending cloudlet 238 to VM #238
1567.8999999999992: broker_25: Sending cloudlet 239 to VM #239
1567.8999999999992: broker_25: Sending cloudlet 240 to VM #240
1567.8999999999992: broker_25: Sending cloudlet 241 to VM #241
1567.8999999999992: broker_25: Sending cloudlet 242 to VM #242
1567.8999999999992: broker_25: Sending cloudlet 243 to VM #243
1567.8999999999992: broker_25: Sending cloudlet 244 to VM #244
1567.8999999999992: broker_25: Sending cloudlet 245 to VM #245
1567.8999999999992: broker_25: Sending cloudlet 246 to VM #246
1567.8999999999992: broker_25: Sending cloudlet 247 to VM #247
1567.8999999999992: broker_25: Sending cloudlet 248 to VM #248
1567.8999999999992: broker_25: Sending cloudlet 249 to VM #249
1567.8999999999992: broker_25: Sending cloudlet 250 to VM #250
1567.8999999999992: broker_25: Sending cloudlet 251 to VM #251
1567.8999999999992: broker_25: Sending cloudlet 252 to VM #252


--------------------------------------------------------------


New resource usage for the time frame starting at 1627.90:
Adding: broker_26
broker_26 is starting...
1628.0999999999992: broker_26: Cloud Resource List received with 1 resource(s)
1628.0999999999992: broker_26: Trying to Create VM #253 in Datacenter
1628.0999999999992: broker_26: Trying to Create VM #254 in Datacenter
1628.0999999999992: broker_26: Trying to Create VM #255 in Datacenter
1628.0999999999992: broker_26: Trying to Create VM #256 in Datacenter
1628.0999999999992: broker_26: Trying to Create VM #257 in Datacenter
1628.0999999999992: broker_26: Trying to Create VM #258 in Datacenter
1628.0999999999992: broker_26: Trying to Create VM #259 in Datacenter
1628.0999999999992: broker_26: Trying to Create VM #260 in Datacenter
1628.0999999999992: broker_26: Trying to Create VM #261 in Datacenter
1628.0999999999992: broker_26: Trying to Create VM #262 in Datacenter
1628.0999999999992: broker_26: Trying to Create VM #263 in Datacenter
1628.0999999999992: broker_26: Trying to Create VM #264 in Datacenter
1628.10: VM #253 has been allocated to the host #53
1628.10: VM #254 has been allocated to the host #54
1628.10: VM #255 has been allocated to the host #55
1628.10: VM #256 has been allocated to the host #56
1628.10: VM #257 has been allocated to the host #57
1628.10: VM #258 has been allocated to the host #58
1628.10: VM #259 has been allocated to the host #59
1628.10: VM #260 has been allocated to the host #60
1628.10: VM #261 has been allocated to the host #61
1628.10: VM #262 has been allocated to the host #62
1628.10: VM #263 has been allocated to the host #63
1628.10: VM #264 has been allocated to the host #64
1628.1999999999991: broker_26: VM #253 has been created in Datacenter #3, Host #53
1628.1999999999991: broker_26: VM #254 has been created in Datacenter #3, Host #54
1628.1999999999991: broker_26: VM #255 has been created in Datacenter #3, Host #55
1628.1999999999991: broker_26: VM #256 has been created in Datacenter #3, Host #56
1628.1999999999991: broker_26: VM #257 has been created in Datacenter #3, Host #57
1628.1999999999991: broker_26: VM #258 has been created in Datacenter #3, Host #58
1628.1999999999991: broker_26: VM #259 has been created in Datacenter #3, Host #59
1628.1999999999991: broker_26: VM #260 has been created in Datacenter #3, Host #60
1628.1999999999991: broker_26: VM #261 has been created in Datacenter #3, Host #61
1628.1999999999991: broker_26: VM #262 has been created in Datacenter #3, Host #62
1628.1999999999991: broker_26: VM #263 has been created in Datacenter #3, Host #63
1628.1999999999991: broker_26: VM #264 has been created in Datacenter #3, Host #64
1628.1999999999991: broker_26: Sending cloudlet 253 to VM #253
1628.1999999999991: broker_26: Sending cloudlet 254 to VM #254
1628.1999999999991: broker_26: Sending cloudlet 255 to VM #255
1628.1999999999991: broker_26: Sending cloudlet 256 to VM #256
1628.1999999999991: broker_26: Sending cloudlet 257 to VM #257
1628.1999999999991: broker_26: Sending cloudlet 258 to VM #258
1628.1999999999991: broker_26: Sending cloudlet 259 to VM #259
1628.1999999999991: broker_26: Sending cloudlet 260 to VM #260
1628.1999999999991: broker_26: Sending cloudlet 261 to VM #261
1628.1999999999991: broker_26: Sending cloudlet 262 to VM #262
1628.1999999999991: broker_26: Sending cloudlet 263 to VM #263
1628.1999999999991: broker_26: Sending cloudlet 264 to VM #264


--------------------------------------------------------------


New resource usage for the time frame starting at 1688.20:
Adding: broker_27
broker_27 is starting...
1688.3999999999992: broker_27: Cloud Resource List received with 1 resource(s)
1688.3999999999992: broker_27: Trying to Create VM #265 in Datacenter
1688.3999999999992: broker_27: Trying to Create VM #266 in Datacenter
1688.3999999999992: broker_27: Trying to Create VM #267 in Datacenter
1688.3999999999992: broker_27: Trying to Create VM #268 in Datacenter
1688.3999999999992: broker_27: Trying to Create VM #269 in Datacenter
1688.3999999999992: broker_27: Trying to Create VM #270 in Datacenter
1688.3999999999992: broker_27: Trying to Create VM #271 in Datacenter
1688.3999999999992: broker_27: Trying to Create VM #272 in Datacenter
1688.3999999999992: broker_27: Trying to Create VM #273 in Datacenter
1688.3999999999992: broker_27: Trying to Create VM #274 in Datacenter
1688.3999999999992: broker_27: Trying to Create VM #275 in Datacenter
1688.3999999999992: broker_27: Trying to Create VM #276 in Datacenter
1688.3999999999992: broker_27: Trying to Create VM #277 in Datacenter
1688.3999999999992: broker_27: Trying to Create VM #278 in Datacenter
1688.3999999999992: broker_27: Trying to Create VM #279 in Datacenter
1688.3999999999992: broker_27: Trying to Create VM #280 in Datacenter
1688.40: VM #265 has been allocated to the host #65
1688.40: VM #266 has been allocated to the host #66
1688.40: VM #267 has been allocated to the host #67
1688.40: VM #268 has been allocated to the host #68
1688.40: VM #269 has been allocated to the host #69
1688.40: VM #270 has been allocated to the host #70
1688.40: VM #271 has been allocated to the host #71
1688.40: VM #272 has been allocated to the host #72
1688.40: VM #273 has been allocated to the host #73
1688.40: VM #274 has been allocated to the host #74
1688.40: VM #275 has been allocated to the host #75
1688.40: VM #276 has been allocated to the host #76
1688.40: VM #277 has been allocated to the host #77
1688.40: VM #278 has been allocated to the host #78
1688.40: VM #279 has been allocated to the host #79
1688.40: VM #280 has been allocated to the host #80
1688.499999999999: broker_27: VM #265 has been created in Datacenter #3, Host #65
1688.499999999999: broker_27: VM #266 has been created in Datacenter #3, Host #66
1688.499999999999: broker_27: VM #267 has been created in Datacenter #3, Host #67
1688.499999999999: broker_27: VM #268 has been created in Datacenter #3, Host #68
1688.499999999999: broker_27: VM #269 has been created in Datacenter #3, Host #69
1688.499999999999: broker_27: VM #270 has been created in Datacenter #3, Host #70
1688.499999999999: broker_27: VM #271 has been created in Datacenter #3, Host #71
1688.499999999999: broker_27: VM #272 has been created in Datacenter #3, Host #72
1688.499999999999: broker_27: VM #273 has been created in Datacenter #3, Host #73
1688.499999999999: broker_27: VM #274 has been created in Datacenter #3, Host #74
1688.499999999999: broker_27: VM #275 has been created in Datacenter #3, Host #75
1688.499999999999: broker_27: VM #276 has been created in Datacenter #3, Host #76
1688.499999999999: broker_27: VM #277 has been created in Datacenter #3, Host #77
1688.499999999999: broker_27: VM #278 has been created in Datacenter #3, Host #78
1688.499999999999: broker_27: VM #279 has been created in Datacenter #3, Host #79
1688.499999999999: broker_27: VM #280 has been created in Datacenter #3, Host #80
1688.499999999999: broker_27: Sending cloudlet 265 to VM #265
1688.499999999999: broker_27: Sending cloudlet 266 to VM #266
1688.499999999999: broker_27: Sending cloudlet 267 to VM #267
1688.499999999999: broker_27: Sending cloudlet 268 to VM #268
1688.499999999999: broker_27: Sending cloudlet 269 to VM #269
1688.499999999999: broker_27: Sending cloudlet 270 to VM #270
1688.499999999999: broker_27: Sending cloudlet 271 to VM #271
1688.499999999999: broker_27: Sending cloudlet 272 to VM #272
1688.499999999999: broker_27: Sending cloudlet 273 to VM #273
1688.499999999999: broker_27: Sending cloudlet 274 to VM #274
1688.499999999999: broker_27: Sending cloudlet 275 to VM #275
1688.499999999999: broker_27: Sending cloudlet 276 to VM #276
1688.499999999999: broker_27: Sending cloudlet 277 to VM #277
1688.499999999999: broker_27: Sending cloudlet 278 to VM #278
1688.499999999999: broker_27: Sending cloudlet 279 to VM #279
1688.499999999999: broker_27: Sending cloudlet 280 to VM #280


--------------------------------------------------------------


New resource usage for the time frame starting at 1748.50:
Adding: broker_28
broker_28 is starting...
1748.6999999999991: broker_28: Cloud Resource List received with 1 resource(s)
1748.6999999999991: broker_28: Trying to Create VM #281 in Datacenter
1748.6999999999991: broker_28: Trying to Create VM #282 in Datacenter
1748.70: VM #281 has been allocated to the host #81
1748.70: VM #282 has been allocated to the host #82
1748.799999999999: broker_28: VM #281 has been created in Datacenter #3, Host #81
1748.799999999999: broker_28: VM #282 has been created in Datacenter #3, Host #82
1748.799999999999: broker_28: Sending cloudlet 281 to VM #281
1748.799999999999: broker_28: Sending cloudlet 282 to VM #282


--------------------------------------------------------------


New resource usage for the time frame starting at 1808.80:
Adding: broker_29
broker_29 is starting...
1808.999999999999: broker_29: Cloud Resource List received with 1 resource(s)
1808.999999999999: broker_29: Trying to Create VM #283 in Datacenter
1808.999999999999: broker_29: Trying to Create VM #284 in Datacenter
1808.999999999999: broker_29: Trying to Create VM #285 in Datacenter
1808.999999999999: broker_29: Trying to Create VM #286 in Datacenter
1808.999999999999: broker_29: Trying to Create VM #287 in Datacenter
1808.999999999999: broker_29: Trying to Create VM #288 in Datacenter
1808.999999999999: broker_29: Trying to Create VM #289 in Datacenter
1809.00: VM #283 has been allocated to the host #83
1809.00: VM #284 has been allocated to the host #84
1809.00: VM #285 has been allocated to the host #85
1809.00: VM #286 has been allocated to the host #86
1809.00: VM #287 has been allocated to the host #87
1809.00: VM #288 has been allocated to the host #88
1809.00: VM #289 has been allocated to the host #89
1809.099999999999: broker_29: VM #283 has been created in Datacenter #3, Host #83
1809.099999999999: broker_29: VM #284 has been created in Datacenter #3, Host #84
1809.099999999999: broker_29: VM #285 has been created in Datacenter #3, Host #85
1809.099999999999: broker_29: VM #286 has been created in Datacenter #3, Host #86
1809.099999999999: broker_29: VM #287 has been created in Datacenter #3, Host #87
1809.099999999999: broker_29: VM #288 has been created in Datacenter #3, Host #88
1809.099999999999: broker_29: VM #289 has been created in Datacenter #3, Host #89
1809.099999999999: broker_29: Sending cloudlet 283 to VM #283
1809.099999999999: broker_29: Sending cloudlet 284 to VM #284
1809.099999999999: broker_29: Sending cloudlet 285 to VM #285
1809.099999999999: broker_29: Sending cloudlet 286 to VM #286
1809.099999999999: broker_29: Sending cloudlet 287 to VM #287
1809.099999999999: broker_29: Sending cloudlet 288 to VM #288
1809.099999999999: broker_29: Sending cloudlet 289 to VM #289


--------------------------------------------------------------


New resource usage for the time frame starting at 1869.10:
Adding: broker_30
broker_30 is starting...
1869.299999999999: broker_30: Cloud Resource List received with 1 resource(s)
1869.299999999999: broker_30: Trying to Create VM #290 in Datacenter
1869.299999999999: broker_30: Trying to Create VM #291 in Datacenter
1869.299999999999: broker_30: Trying to Create VM #292 in Datacenter
1869.299999999999: broker_30: Trying to Create VM #293 in Datacenter
1869.299999999999: broker_30: Trying to Create VM #294 in Datacenter
1869.299999999999: broker_30: Trying to Create VM #295 in Datacenter
1869.299999999999: broker_30: Trying to Create VM #296 in Datacenter
1869.299999999999: broker_30: Trying to Create VM #297 in Datacenter
1869.299999999999: broker_30: Trying to Create VM #298 in Datacenter
1869.299999999999: broker_30: Trying to Create VM #299 in Datacenter
1869.299999999999: broker_30: Trying to Create VM #300 in Datacenter
1869.299999999999: broker_30: Trying to Create VM #301 in Datacenter
1869.299999999999: broker_30: Trying to Create VM #302 in Datacenter
1869.299999999999: broker_30: Trying to Create VM #303 in Datacenter
1869.299999999999: broker_30: Trying to Create VM #304 in Datacenter
1869.30: VM #290 has been allocated to the host #90
1869.30: VM #291 has been allocated to the host #91
1869.30: VM #292 has been allocated to the host #92
1869.30: VM #293 has been allocated to the host #93
1869.30: VM #294 has been allocated to the host #94
1869.30: VM #295 has been allocated to the host #95
1869.30: VM #296 has been allocated to the host #96
1869.30: VM #297 has been allocated to the host #97
1869.30: VM #298 has been allocated to the host #98
1869.30: VM #299 has been allocated to the host #99
1869.30: VM #300 has been allocated to the host #100
1869.30: VM #301 has been allocated to the host #101
1869.30: VM #302 has been allocated to the host #102
1869.30: VM #303 has been allocated to the host #103
1869.30: VM #304 has been allocated to the host #104
1869.399999999999: broker_30: VM #290 has been created in Datacenter #3, Host #90
1869.399999999999: broker_30: VM #291 has been created in Datacenter #3, Host #91
1869.399999999999: broker_30: VM #292 has been created in Datacenter #3, Host #92
1869.399999999999: broker_30: VM #293 has been created in Datacenter #3, Host #93
1869.399999999999: broker_30: VM #294 has been created in Datacenter #3, Host #94
1869.399999999999: broker_30: VM #295 has been created in Datacenter #3, Host #95
1869.399999999999: broker_30: VM #296 has been created in Datacenter #3, Host #96
1869.399999999999: broker_30: VM #297 has been created in Datacenter #3, Host #97
1869.399999999999: broker_30: VM #298 has been created in Datacenter #3, Host #98
1869.399999999999: broker_30: VM #299 has been created in Datacenter #3, Host #99
1869.399999999999: broker_30: VM #300 has been created in Datacenter #3, Host #100
1869.399999999999: broker_30: VM #301 has been created in Datacenter #3, Host #101
1869.399999999999: broker_30: VM #302 has been created in Datacenter #3, Host #102
1869.399999999999: broker_30: VM #303 has been created in Datacenter #3, Host #103
1869.399999999999: broker_30: VM #304 has been created in Datacenter #3, Host #104
1869.399999999999: broker_30: Sending cloudlet 290 to VM #290
1869.399999999999: broker_30: Sending cloudlet 291 to VM #291
1869.399999999999: broker_30: Sending cloudlet 292 to VM #292
1869.399999999999: broker_30: Sending cloudlet 293 to VM #293
1869.399999999999: broker_30: Sending cloudlet 294 to VM #294
1869.399999999999: broker_30: Sending cloudlet 295 to VM #295
1869.399999999999: broker_30: Sending cloudlet 296 to VM #296
1869.399999999999: broker_30: Sending cloudlet 297 to VM #297
1869.399999999999: broker_30: Sending cloudlet 298 to VM #298
1869.399999999999: broker_30: Sending cloudlet 299 to VM #299
1869.399999999999: broker_30: Sending cloudlet 300 to VM #300
1869.399999999999: broker_30: Sending cloudlet 301 to VM #301
1869.399999999999: broker_30: Sending cloudlet 302 to VM #302
1869.399999999999: broker_30: Sending cloudlet 303 to VM #303
1869.399999999999: broker_30: Sending cloudlet 304 to VM #304


--------------------------------------------------------------


New resource usage for the time frame starting at 1929.40:
Adding: broker_31
broker_31 is starting...
1929.599999999999: broker_31: Cloud Resource List received with 1 resource(s)
1929.599999999999: broker_31: Trying to Create VM #305 in Datacenter
1929.599999999999: broker_31: Trying to Create VM #306 in Datacenter
1929.599999999999: broker_31: Trying to Create VM #307 in Datacenter
1929.599999999999: broker_31: Trying to Create VM #308 in Datacenter
1929.599999999999: broker_31: Trying to Create VM #309 in Datacenter
1929.599999999999: broker_31: Trying to Create VM #310 in Datacenter
1929.60: VM #305 has been allocated to the host #105
1929.60: VM #306 has been allocated to the host #106
1929.60: VM #307 has been allocated to the host #107
1929.60: VM #308 has been allocated to the host #108
1929.60: VM #309 has been allocated to the host #109
1929.60: VM #310 has been allocated to the host #110
1929.699999999999: broker_31: VM #305 has been created in Datacenter #3, Host #105
1929.699999999999: broker_31: VM #306 has been created in Datacenter #3, Host #106
1929.699999999999: broker_31: VM #307 has been created in Datacenter #3, Host #107
1929.699999999999: broker_31: VM #308 has been created in Datacenter #3, Host #108
1929.699999999999: broker_31: VM #309 has been created in Datacenter #3, Host #109
1929.699999999999: broker_31: VM #310 has been created in Datacenter #3, Host #110
1929.699999999999: broker_31: Sending cloudlet 305 to VM #305
1929.699999999999: broker_31: Sending cloudlet 306 to VM #306
1929.699999999999: broker_31: Sending cloudlet 307 to VM #307
1929.699999999999: broker_31: Sending cloudlet 308 to VM #308
1929.699999999999: broker_31: Sending cloudlet 309 to VM #309
1929.699999999999: broker_31: Sending cloudlet 310 to VM #310


--------------------------------------------------------------


New resource usage for the time frame starting at 1989.70:
Adding: broker_32
broker_32 is starting...
1989.899999999999: broker_32: Cloud Resource List received with 1 resource(s)


--------------------------------------------------------------


New resource usage for the time frame starting at 2049.70:
Adding: broker_33
broker_33 is starting...
2050.199999999999: broker_33: Cloud Resource List received with 1 resource(s)
2050.199999999999: broker_33: Trying to Create VM #311 in Datacenter
2050.199999999999: broker_33: Trying to Create VM #312 in Datacenter
2050.20: VM #311 has been allocated to the host #111
2050.20: VM #312 has been allocated to the host #112
2050.299999999999: broker_33: VM #311 has been created in Datacenter #3, Host #111
2050.299999999999: broker_33: VM #312 has been created in Datacenter #3, Host #112
2050.299999999999: broker_33: Sending cloudlet 311 to VM #311
2050.299999999999: broker_33: Sending cloudlet 312 to VM #312


--------------------------------------------------------------


New resource usage for the time frame starting at 2110.30:
Adding: broker_34
broker_34 is starting...
2110.499999999999: broker_34: Cloud Resource List received with 1 resource(s)
2110.499999999999: broker_34: Trying to Create VM #313 in Datacenter
2110.499999999999: broker_34: Trying to Create VM #314 in Datacenter
2110.499999999999: broker_34: Trying to Create VM #315 in Datacenter
2110.499999999999: broker_34: Trying to Create VM #316 in Datacenter
2110.499999999999: broker_34: Trying to Create VM #317 in Datacenter
2110.499999999999: broker_34: Trying to Create VM #318 in Datacenter
2110.499999999999: broker_34: Trying to Create VM #319 in Datacenter
2110.50: VM #313 has been allocated to the host #113
2110.50: VM #314 has been allocated to the host #114
2110.50: VM #315 has been allocated to the host #115
2110.50: VM #316 has been allocated to the host #116
2110.50: VM #317 has been allocated to the host #117
2110.50: VM #318 has been allocated to the host #118
2110.50: VM #319 has been allocated to the host #119
2110.599999999999: broker_34: VM #313 has been created in Datacenter #3, Host #113
2110.599999999999: broker_34: VM #314 has been created in Datacenter #3, Host #114
2110.599999999999: broker_34: VM #315 has been created in Datacenter #3, Host #115
2110.599999999999: broker_34: VM #316 has been created in Datacenter #3, Host #116
2110.599999999999: broker_34: VM #317 has been created in Datacenter #3, Host #117
2110.599999999999: broker_34: VM #318 has been created in Datacenter #3, Host #118
2110.599999999999: broker_34: VM #319 has been created in Datacenter #3, Host #119
2110.599999999999: broker_34: Sending cloudlet 313 to VM #313
2110.599999999999: broker_34: Sending cloudlet 314 to VM #314
2110.599999999999: broker_34: Sending cloudlet 315 to VM #315
2110.599999999999: broker_34: Sending cloudlet 316 to VM #316
2110.599999999999: broker_34: Sending cloudlet 317 to VM #317
2110.599999999999: broker_34: Sending cloudlet 318 to VM #318
2110.599999999999: broker_34: Sending cloudlet 319 to VM #319


--------------------------------------------------------------


New resource usage for the time frame starting at 2170.60:
Adding: broker_35
broker_35 is starting...
2170.7999999999993: broker_35: Cloud Resource List received with 1 resource(s)
2170.7999999999993: broker_35: Trying to Create VM #320 in Datacenter
2170.7999999999993: broker_35: Trying to Create VM #321 in Datacenter
2170.7999999999993: broker_35: Trying to Create VM #322 in Datacenter
2170.7999999999993: broker_35: Trying to Create VM #323 in Datacenter
2170.7999999999993: broker_35: Trying to Create VM #324 in Datacenter
2170.7999999999993: broker_35: Trying to Create VM #325 in Datacenter
2170.7999999999993: broker_35: Trying to Create VM #326 in Datacenter
2170.7999999999993: broker_35: Trying to Create VM #327 in Datacenter
2170.80: VM #320 has been allocated to the host #120
2170.80: VM #321 has been allocated to the host #121
2170.80: VM #322 has been allocated to the host #122
2170.80: VM #323 has been allocated to the host #123
2170.80: VM #324 has been allocated to the host #124
2170.80: VM #325 has been allocated to the host #125
2170.80: VM #326 has been allocated to the host #126
2170.80: VM #327 has been allocated to the host #127
2170.899999999999: broker_35: VM #320 has been created in Datacenter #3, Host #120
2170.899999999999: broker_35: VM #321 has been created in Datacenter #3, Host #121
2170.899999999999: broker_35: VM #322 has been created in Datacenter #3, Host #122
2170.899999999999: broker_35: VM #323 has been created in Datacenter #3, Host #123
2170.899999999999: broker_35: VM #324 has been created in Datacenter #3, Host #124
2170.899999999999: broker_35: VM #325 has been created in Datacenter #3, Host #125
2170.899999999999: broker_35: VM #326 has been created in Datacenter #3, Host #126
2170.899999999999: broker_35: VM #327 has been created in Datacenter #3, Host #127
2170.899999999999: broker_35: Sending cloudlet 320 to VM #320
2170.899999999999: broker_35: Sending cloudlet 321 to VM #321
2170.899999999999: broker_35: Sending cloudlet 322 to VM #322
2170.899999999999: broker_35: Sending cloudlet 323 to VM #323
2170.899999999999: broker_35: Sending cloudlet 324 to VM #324
2170.899999999999: broker_35: Sending cloudlet 325 to VM #325
2170.899999999999: broker_35: Sending cloudlet 326 to VM #326
2170.899999999999: broker_35: Sending cloudlet 327 to VM #327


--------------------------------------------------------------


New resource usage for the time frame starting at 2230.90:
Adding: broker_36
broker_36 is starting...
2231.0999999999995: broker_36: Cloud Resource List received with 1 resource(s)
2231.0999999999995: broker_36: Trying to Create VM #328 in Datacenter
2231.0999999999995: broker_36: Trying to Create VM #329 in Datacenter
2231.0999999999995: broker_36: Trying to Create VM #330 in Datacenter
2231.0999999999995: broker_36: Trying to Create VM #331 in Datacenter
2231.0999999999995: broker_36: Trying to Create VM #332 in Datacenter
2231.0999999999995: broker_36: Trying to Create VM #333 in Datacenter
2231.0999999999995: broker_36: Trying to Create VM #334 in Datacenter
2231.0999999999995: broker_36: Trying to Create VM #335 in Datacenter
2231.0999999999995: broker_36: Trying to Create VM #336 in Datacenter
2231.0999999999995: broker_36: Trying to Create VM #337 in Datacenter
2231.0999999999995: broker_36: Trying to Create VM #338 in Datacenter
2231.0999999999995: broker_36: Trying to Create VM #339 in Datacenter
2231.0999999999995: broker_36: Trying to Create VM #340 in Datacenter
2231.10: VM #328 has been allocated to the host #128
2231.10: VM #329 has been allocated to the host #129
2231.10: VM #330 has been allocated to the host #130
2231.10: VM #331 has been allocated to the host #131
2231.10: VM #332 has been allocated to the host #132
2231.10: VM #333 has been allocated to the host #133
2231.10: VM #334 has been allocated to the host #134
2231.10: VM #335 has been allocated to the host #135
2231.10: VM #336 has been allocated to the host #136
2231.10: VM #337 has been allocated to the host #137
2231.10: VM #338 has been allocated to the host #138
2231.10: VM #339 has been allocated to the host #139
2231.10: VM #340 has been allocated to the host #140
2231.1999999999994: broker_36: VM #328 has been created in Datacenter #3, Host #128
2231.1999999999994: broker_36: VM #329 has been created in Datacenter #3, Host #129
2231.1999999999994: broker_36: VM #330 has been created in Datacenter #3, Host #130
2231.1999999999994: broker_36: VM #331 has been created in Datacenter #3, Host #131
2231.1999999999994: broker_36: VM #332 has been created in Datacenter #3, Host #132
2231.1999999999994: broker_36: VM #333 has been created in Datacenter #3, Host #133
2231.1999999999994: broker_36: VM #334 has been created in Datacenter #3, Host #134
2231.1999999999994: broker_36: VM #335 has been created in Datacenter #3, Host #135
2231.1999999999994: broker_36: VM #336 has been created in Datacenter #3, Host #136
2231.1999999999994: broker_36: VM #337 has been created in Datacenter #3, Host #137
2231.1999999999994: broker_36: VM #338 has been created in Datacenter #3, Host #138
2231.1999999999994: broker_36: VM #339 has been created in Datacenter #3, Host #139
2231.1999999999994: broker_36: VM #340 has been created in Datacenter #3, Host #140
2231.1999999999994: broker_36: Sending cloudlet 328 to VM #328
2231.1999999999994: broker_36: Sending cloudlet 329 to VM #329
2231.1999999999994: broker_36: Sending cloudlet 330 to VM #330
2231.1999999999994: broker_36: Sending cloudlet 331 to VM #331
2231.1999999999994: broker_36: Sending cloudlet 332 to VM #332
2231.1999999999994: broker_36: Sending cloudlet 333 to VM #333
2231.1999999999994: broker_36: Sending cloudlet 334 to VM #334
2231.1999999999994: broker_36: Sending cloudlet 335 to VM #335
2231.1999999999994: broker_36: Sending cloudlet 336 to VM #336
2231.1999999999994: broker_36: Sending cloudlet 337 to VM #337
2231.1999999999994: broker_36: Sending cloudlet 338 to VM #338
2231.1999999999994: broker_36: Sending cloudlet 339 to VM #339
2231.1999999999994: broker_36: Sending cloudlet 340 to VM #340


--------------------------------------------------------------


New resource usage for the time frame starting at 2291.20:
Adding: broker_37
broker_37 is starting...
2291.3999999999996: broker_37: Cloud Resource List received with 1 resource(s)
2291.3999999999996: broker_37: Trying to Create VM #341 in Datacenter
2291.3999999999996: broker_37: Trying to Create VM #342 in Datacenter
2291.3999999999996: broker_37: Trying to Create VM #343 in Datacenter
2291.3999999999996: broker_37: Trying to Create VM #344 in Datacenter
2291.3999999999996: broker_37: Trying to Create VM #345 in Datacenter
2291.3999999999996: broker_37: Trying to Create VM #346 in Datacenter
2291.3999999999996: broker_37: Trying to Create VM #347 in Datacenter
2291.3999999999996: broker_37: Trying to Create VM #348 in Datacenter
2291.3999999999996: broker_37: Trying to Create VM #349 in Datacenter
2291.3999999999996: broker_37: Trying to Create VM #350 in Datacenter
2291.3999999999996: broker_37: Trying to Create VM #351 in Datacenter
2291.3999999999996: broker_37: Trying to Create VM #352 in Datacenter
2291.3999999999996: broker_37: Trying to Create VM #353 in Datacenter
2291.3999999999996: broker_37: Trying to Create VM #354 in Datacenter
2291.3999999999996: broker_37: Trying to Create VM #355 in Datacenter
2291.3999999999996: broker_37: Trying to Create VM #356 in Datacenter
2291.3999999999996: broker_37: Trying to Create VM #357 in Datacenter
2291.3999999999996: broker_37: Trying to Create VM #358 in Datacenter
2291.3999999999996: broker_37: Trying to Create VM #359 in Datacenter
2291.40: VM #341 has been allocated to the host #141
2291.40: VM #342 has been allocated to the host #142
2291.40: VM #343 has been allocated to the host #143
2291.40: VM #344 has been allocated to the host #144
2291.40: VM #345 has been allocated to the host #145
2291.40: VM #346 has been allocated to the host #146
2291.40: VM #347 has been allocated to the host #147
2291.40: VM #348 has been allocated to the host #148
2291.40: VM #349 has been allocated to the host #149
2291.40: VM #350 has been allocated to the host #150
2291.40: VM #351 has been allocated to the host #151
2291.40: VM #352 has been allocated to the host #152
2291.40: VM #353 has been allocated to the host #153
2291.40: VM #354 has been allocated to the host #154
2291.40: VM #355 has been allocated to the host #155
2291.40: VM #356 has been allocated to the host #156
2291.40: VM #357 has been allocated to the host #157
2291.40: VM #358 has been allocated to the host #158
2291.40: VM #359 has been allocated to the host #159
2291.4999999999995: broker_37: VM #341 has been created in Datacenter #3, Host #141
