Initialising...
0.00: VmsThreatScore:
Starting CloudSim version 3.0
GlobalBroker is starting...
Datacenter is starting...
Entities started.
Adding: broker_0
broker_0 is starting...
600.3: broker_0: Cloud Resource List received with 1 resource(s)
600.3: broker_0: Trying to Create VM #0 in Datacenter
600.3: broker_0: Trying to Create VM #1 in Datacenter
600.3: broker_0: Trying to Create VM #2 in Datacenter
600.3: broker_0: Trying to Create VM #3 in Datacenter
600.3: broker_0: Trying to Create VM #4 in Datacenter
600.3: broker_0: Trying to Create VM #5 in Datacenter
600.3: broker_0: Trying to Create VM #6 in Datacenter
600.3: broker_0: Trying to Create VM #7 in Datacenter
600.3: broker_0: Trying to Create VM #8 in Datacenter
600.3: broker_0: Trying to Create VM #9 in Datacenter
600.3: broker_0: Trying to Create VM #10 in Datacenter
600.3: broker_0: Trying to Create VM #11 in Datacenter
600.3: broker_0: Trying to Create VM #12 in Datacenter
600.3: broker_0: Trying to Create VM #13 in Datacenter
600.3: broker_0: Trying to Create VM #14 in Datacenter
600.3: broker_0: Trying to Create VM #15 in Datacenter
600.3: broker_0: Trying to Create VM #16 in Datacenter
600.3: broker_0: Trying to Create VM #17 in Datacenter
600.3: broker_0: Trying to Create VM #18 in Datacenter
600.3: broker_0: Trying to Create VM #19 in Datacenter
600.3: broker_0: Trying to Create VM #20 in Datacenter
600.3: broker_0: Trying to Create VM #21 in Datacenter
600.3: broker_0: Trying to Create VM #22 in Datacenter
600.3: broker_0: Trying to Create VM #23 in Datacenter
600.3: broker_0: Trying to Create VM #24 in Datacenter
600.3: broker_0: Trying to Create VM #25 in Datacenter
600.3: broker_0: Trying to Create VM #26 in Datacenter
600.3: broker_0: Trying to Create VM #27 in Datacenter
600.3: broker_0: Trying to Create VM #28 in Datacenter
600.3: broker_0: Trying to Create VM #29 in Datacenter
600.3: broker_0: Trying to Create VM #30 in Datacenter
600.3: broker_0: Trying to Create VM #31 in Datacenter
600.3: broker_0: Trying to Create VM #32 in Datacenter
600.3: broker_0: Trying to Create VM #33 in Datacenter
600.3: broker_0: Trying to Create VM #34 in Datacenter
600.3: broker_0: Trying to Create VM #35 in Datacenter
600.3: broker_0: Trying to Create VM #36 in Datacenter
600.3: broker_0: Trying to Create VM #37 in Datacenter
600.3: broker_0: Trying to Create VM #38 in Datacenter
600.3: broker_0: Trying to Create VM #39 in Datacenter
600.3: broker_0: Trying to Create VM #40 in Datacenter
600.3: broker_0: Trying to Create VM #41 in Datacenter
600.3: broker_0: Trying to Create VM #42 in Datacenter
600.3: broker_0: Trying to Create VM #43 in Datacenter
600.3: broker_0: Trying to Create VM #44 in Datacenter
600.3: broker_0: Trying to Create VM #45 in Datacenter
600.3: broker_0: Trying to Create VM #46 in Datacenter
600.3: broker_0: Trying to Create VM #47 in Datacenter
600.3: broker_0: Trying to Create VM #48 in Datacenter
600.3: broker_0: Trying to Create VM #49 in Datacenter
600.3: broker_0: Trying to Create VM #50 in Datacenter
600.3: broker_0: Trying to Create VM #51 in Datacenter
600.3: broker_0: Trying to Create VM #52 in Datacenter
600.3: broker_0: Trying to Create VM #53 in Datacenter
600.3: broker_0: Trying to Create VM #54 in Datacenter
600.3: broker_0: Trying to Create VM #55 in Datacenter
600.3: broker_0: Trying to Create VM #56 in Datacenter
600.3: broker_0: Trying to Create VM #57 in Datacenter
600.3: broker_0: Trying to Create VM #58 in Datacenter
600.3: broker_0: Trying to Create VM #59 in Datacenter
600.3: broker_0: Trying to Create VM #60 in Datacenter
600.3: broker_0: Trying to Create VM #61 in Datacenter
600.3: broker_0: Trying to Create VM #62 in Datacenter
600.3: broker_0: Trying to Create VM #63 in Datacenter
600.3: broker_0: Trying to Create VM #64 in Datacenter
600.3: broker_0: Trying to Create VM #65 in Datacenter
600.3: broker_0: Trying to Create VM #66 in Datacenter
600.3: broker_0: Trying to Create VM #67 in Datacenter
600.3: broker_0: Trying to Create VM #68 in Datacenter
600.3: broker_0: Trying to Create VM #69 in Datacenter
600.3: broker_0: Trying to Create VM #70 in Datacenter
600.3: broker_0: Trying to Create VM #71 in Datacenter
600.3: broker_0: Trying to Create VM #72 in Datacenter
600.3: broker_0: Trying to Create VM #73 in Datacenter
600.3: broker_0: Trying to Create VM #74 in Datacenter
600.3: broker_0: Trying to Create VM #75 in Datacenter
600.3: broker_0: Trying to Create VM #76 in Datacenter
600.3: broker_0: Trying to Create VM #77 in Datacenter
600.3: broker_0: Trying to Create VM #78 in Datacenter
600.3: broker_0: Trying to Create VM #79 in Datacenter
600.3: broker_0: Trying to Create VM #80 in Datacenter
600.3: broker_0: Trying to Create VM #81 in Datacenter
600.3: broker_0: Trying to Create VM #82 in Datacenter
600.3: broker_0: Trying to Create VM #83 in Datacenter
600.3: broker_0: Trying to Create VM #84 in Datacenter
600.3: broker_0: Trying to Create VM #85 in Datacenter
600.3: broker_0: Trying to Create VM #86 in Datacenter
600.3: broker_0: Trying to Create VM #87 in Datacenter
600.3: broker_0: Trying to Create VM #88 in Datacenter
600.3: broker_0: Trying to Create VM #89 in Datacenter
600.3: broker_0: Trying to Create VM #90 in Datacenter
600.3: broker_0: Trying to Create VM #91 in Datacenter
600.3: broker_0: Trying to Create VM #92 in Datacenter
600.3: broker_0: Trying to Create VM #93 in Datacenter
600.3: broker_0: Trying to Create VM #94 in Datacenter
600.3: broker_0: Trying to Create VM #95 in Datacenter
600.3: broker_0: Trying to Create VM #96 in Datacenter
600.3: broker_0: Trying to Create VM #97 in Datacenter
600.3: broker_0: Trying to Create VM #98 in Datacenter
600.3: broker_0: Trying to Create VM #99 in Datacenter
600.3: broker_0: Trying to Create VM #100 in Datacenter
600.3: broker_0: Trying to Create VM #101 in Datacenter
600.3: broker_0: Trying to Create VM #102 in Datacenter
600.3: broker_0: Trying to Create VM #103 in Datacenter
600.3: broker_0: Trying to Create VM #104 in Datacenter
600.3: broker_0: Trying to Create VM #105 in Datacenter
600.3: broker_0: Trying to Create VM #106 in Datacenter
600.3: broker_0: Trying to Create VM #107 in Datacenter
600.3: broker_0: Trying to Create VM #108 in Datacenter
600.3: broker_0: Trying to Create VM #109 in Datacenter
600.3: broker_0: Trying to Create VM #110 in Datacenter
600.3: broker_0: Trying to Create VM #111 in Datacenter
600.3: broker_0: Trying to Create VM #112 in Datacenter
600.3: broker_0: Trying to Create VM #113 in Datacenter
600.3: broker_0: Trying to Create VM #114 in Datacenter
600.3: broker_0: Trying to Create VM #115 in Datacenter
600.3: broker_0: Trying to Create VM #116 in Datacenter
600.3: broker_0: Trying to Create VM #117 in Datacenter
600.3: broker_0: Trying to Create VM #118 in Datacenter
600.3: broker_0: Trying to Create VM #119 in Datacenter
600.3: broker_0: Trying to Create VM #120 in Datacenter
600.3: broker_0: Trying to Create VM #121 in Datacenter
600.3: broker_0: Trying to Create VM #122 in Datacenter
600.3: broker_0: Trying to Create VM #123 in Datacenter
600.3: broker_0: Trying to Create VM #124 in Datacenter
600.3: broker_0: Trying to Create VM #125 in Datacenter
600.3: broker_0: Trying to Create VM #126 in Datacenter
600.3: broker_0: Trying to Create VM #127 in Datacenter
600.3: broker_0: Trying to Create VM #128 in Datacenter
600.3: broker_0: Trying to Create VM #129 in Datacenter
600.3: broker_0: Trying to Create VM #130 in Datacenter
600.3: broker_0: Trying to Create VM #131 in Datacenter
600.3: broker_0: Trying to Create VM #132 in Datacenter
600.3: broker_0: Trying to Create VM #133 in Datacenter
600.3: broker_0: Trying to Create VM #134 in Datacenter
600.3: broker_0: Trying to Create VM #135 in Datacenter
600.3: broker_0: Trying to Create VM #136 in Datacenter
600.3: broker_0: Trying to Create VM #137 in Datacenter
600.3: broker_0: Trying to Create VM #138 in Datacenter
600.3: broker_0: Trying to Create VM #139 in Datacenter
600.3: broker_0: Trying to Create VM #140 in Datacenter
600.3: broker_0: Trying to Create VM #141 in Datacenter
600.3: broker_0: Trying to Create VM #142 in Datacenter
600.3: broker_0: Trying to Create VM #143 in Datacenter
600.3: broker_0: Trying to Create VM #144 in Datacenter
600.3: broker_0: Trying to Create VM #145 in Datacenter
600.3: broker_0: Trying to Create VM #146 in Datacenter
600.3: broker_0: Trying to Create VM #147 in Datacenter
600.3: broker_0: Trying to Create VM #148 in Datacenter
600.3: broker_0: Trying to Create VM #149 in Datacenter
600.3: broker_0: Trying to Create VM #150 in Datacenter
600.3: broker_0: Trying to Create VM #151 in Datacenter
600.3: broker_0: Trying to Create VM #152 in Datacenter
600.3: broker_0: Trying to Create VM #153 in Datacenter
600.3: broker_0: Trying to Create VM #154 in Datacenter
600.3: broker_0: Trying to Create VM #155 in Datacenter
600.3: broker_0: Trying to Create VM #156 in Datacenter
600.3: broker_0: Trying to Create VM #157 in Datacenter
600.3: broker_0: Trying to Create VM #158 in Datacenter
600.3: broker_0: Trying to Create VM #159 in Datacenter
600.3: broker_0: Trying to Create VM #160 in Datacenter
600.3: broker_0: Trying to Create VM #161 in Datacenter
600.3: broker_0: Trying to Create VM #162 in Datacenter
600.3: broker_0: Trying to Create VM #163 in Datacenter
600.3: broker_0: Trying to Create VM #164 in Datacenter
600.3: broker_0: Trying to Create VM #165 in Datacenter
600.3: broker_0: Trying to Create VM #166 in Datacenter
600.3: broker_0: Trying to Create VM #167 in Datacenter
600.3: broker_0: Trying to Create VM #168 in Datacenter
600.3: broker_0: Trying to Create VM #169 in Datacenter
600.3: broker_0: Trying to Create VM #170 in Datacenter
600.3: broker_0: Trying to Create VM #171 in Datacenter
600.3: broker_0: Trying to Create VM #172 in Datacenter
600.3: broker_0: Trying to Create VM #173 in Datacenter
600.3: broker_0: Trying to Create VM #174 in Datacenter
600.3: broker_0: Trying to Create VM #175 in Datacenter
600.3: broker_0: Trying to Create VM #176 in Datacenter
600.3: broker_0: Trying to Create VM #177 in Datacenter
600.3: broker_0: Trying to Create VM #178 in Datacenter
600.3: broker_0: Trying to Create VM #179 in Datacenter
600.3: broker_0: Trying to Create VM #180 in Datacenter
600.3: broker_0: Trying to Create VM #181 in Datacenter
600.3: broker_0: Trying to Create VM #182 in Datacenter
600.3: broker_0: Trying to Create VM #183 in Datacenter
600.3: broker_0: Trying to Create VM #184 in Datacenter
600.3: broker_0: Trying to Create VM #185 in Datacenter
600.3: broker_0: Trying to Create VM #186 in Datacenter
600.3: broker_0: Trying to Create VM #187 in Datacenter
600.3: broker_0: Trying to Create VM #188 in Datacenter
600.3: broker_0: Trying to Create VM #189 in Datacenter
600.3: broker_0: Trying to Create VM #190 in Datacenter
600.3: broker_0: Trying to Create VM #191 in Datacenter
600.3: broker_0: Trying to Create VM #192 in Datacenter
600.3: broker_0: Trying to Create VM #193 in Datacenter
600.3: broker_0: Trying to Create VM #194 in Datacenter
600.3: broker_0: Trying to Create VM #195 in Datacenter
600.3: broker_0: Trying to Create VM #196 in Datacenter
600.3: broker_0: Trying to Create VM #197 in Datacenter
600.3: broker_0: Trying to Create VM #198 in Datacenter
600.3: broker_0: Trying to Create VM #199 in Datacenter
600.3: broker_0: Trying to Create VM #200 in Datacenter
600.3: broker_0: Trying to Create VM #201 in Datacenter
600.3: broker_0: Trying to Create VM #202 in Datacenter
600.3: broker_0: Trying to Create VM #203 in Datacenter
600.3: broker_0: Trying to Create VM #204 in Datacenter
600.3: broker_0: Trying to Create VM #205 in Datacenter
600.3: broker_0: Trying to Create VM #206 in Datacenter
600.3: broker_0: Trying to Create VM #207 in Datacenter
600.3: broker_0: Trying to Create VM #208 in Datacenter
600.3: broker_0: Trying to Create VM #209 in Datacenter
600.3: broker_0: Trying to Create VM #210 in Datacenter
600.3: broker_0: Trying to Create VM #211 in Datacenter
600.3: broker_0: Trying to Create VM #212 in Datacenter
600.3: broker_0: Trying to Create VM #213 in Datacenter
600.3: broker_0: Trying to Create VM #214 in Datacenter
600.3: broker_0: Trying to Create VM #215 in Datacenter
600.3: broker_0: Trying to Create VM #216 in Datacenter
600.3: broker_0: Trying to Create VM #217 in Datacenter
600.3: broker_0: Trying to Create VM #218 in Datacenter
600.3: broker_0: Trying to Create VM #219 in Datacenter
600.3: broker_0: Trying to Create VM #220 in Datacenter
600.3: broker_0: Trying to Create VM #221 in Datacenter
600.3: broker_0: Trying to Create VM #222 in Datacenter
600.3: broker_0: Trying to Create VM #223 in Datacenter
600.3: broker_0: Trying to Create VM #224 in Datacenter
600.3: broker_0: Trying to Create VM #225 in Datacenter
600.3: broker_0: Trying to Create VM #226 in Datacenter
600.3: broker_0: Trying to Create VM #227 in Datacenter
600.3: broker_0: Trying to Create VM #228 in Datacenter
600.3: broker_0: Trying to Create VM #229 in Datacenter
600.3: broker_0: Trying to Create VM #230 in Datacenter
600.3: broker_0: Trying to Create VM #231 in Datacenter
600.3: broker_0: Trying to Create VM #232 in Datacenter
600.3: broker_0: Trying to Create VM #233 in Datacenter
600.3: broker_0: Trying to Create VM #234 in Datacenter
600.3: broker_0: Trying to Create VM #235 in Datacenter
600.3: broker_0: Trying to Create VM #236 in Datacenter
600.3: broker_0: Trying to Create VM #237 in Datacenter
600.3: broker_0: Trying to Create VM #238 in Datacenter
600.3: broker_0: Trying to Create VM #239 in Datacenter
600.3: broker_0: Trying to Create VM #240 in Datacenter
600.3: broker_0: Trying to Create VM #241 in Datacenter
600.3: broker_0: Trying to Create VM #242 in Datacenter
600.3: broker_0: Trying to Create VM #243 in Datacenter
600.3: broker_0: Trying to Create VM #244 in Datacenter
600.3: broker_0: Trying to Create VM #245 in Datacenter
600.3: broker_0: Trying to Create VM #246 in Datacenter
600.3: broker_0: Trying to Create VM #247 in Datacenter
600.3: broker_0: Trying to Create VM #248 in Datacenter
600.3: broker_0: Trying to Create VM #249 in Datacenter
600.3: broker_0: Trying to Create VM #250 in Datacenter
600.3: broker_0: Trying to Create VM #251 in Datacenter
600.3: broker_0: Trying to Create VM #252 in Datacenter
600.3: broker_0: Trying to Create VM #253 in Datacenter
600.3: broker_0: Trying to Create VM #254 in Datacenter
600.3: broker_0: Trying to Create VM #255 in Datacenter
600.3: broker_0: Trying to Create VM #256 in Datacenter
600.3: broker_0: Trying to Create VM #257 in Datacenter
600.3: broker_0: Trying to Create VM #258 in Datacenter
600.3: broker_0: Trying to Create VM #259 in Datacenter
600.3: broker_0: Trying to Create VM #260 in Datacenter
600.3: broker_0: Trying to Create VM #261 in Datacenter
600.3: broker_0: Trying to Create VM #262 in Datacenter
600.3: broker_0: Trying to Create VM #263 in Datacenter
600.3: broker_0: Trying to Create VM #264 in Datacenter
600.3: broker_0: Trying to Create VM #265 in Datacenter
600.3: broker_0: Trying to Create VM #266 in Datacenter
600.3: broker_0: Trying to Create VM #267 in Datacenter
600.3: broker_0: Trying to Create VM #268 in Datacenter
600.3: broker_0: Trying to Create VM #269 in Datacenter
600.3: broker_0: Trying to Create VM #270 in Datacenter
600.3: broker_0: Trying to Create VM #271 in Datacenter
600.3: broker_0: Trying to Create VM #272 in Datacenter
600.3: broker_0: Trying to Create VM #273 in Datacenter
600.3: broker_0: Trying to Create VM #274 in Datacenter
600.3: broker_0: Trying to Create VM #275 in Datacenter
600.3: broker_0: Trying to Create VM #276 in Datacenter
600.3: broker_0: Trying to Create VM #277 in Datacenter
600.3: broker_0: Trying to Create VM #278 in Datacenter
600.3: broker_0: Trying to Create VM #279 in Datacenter
600.3: broker_0: Trying to Create VM #280 in Datacenter
600.3: broker_0: Trying to Create VM #281 in Datacenter
600.3: broker_0: Trying to Create VM #282 in Datacenter
600.3: broker_0: Trying to Create VM #283 in Datacenter
600.3: broker_0: Trying to Create VM #284 in Datacenter
600.3: broker_0: Trying to Create VM #285 in Datacenter
600.3: broker_0: Trying to Create VM #286 in Datacenter
600.3: broker_0: Trying to Create VM #287 in Datacenter
600.3: broker_0: Trying to Create VM #288 in Datacenter
600.3: broker_0: Trying to Create VM #289 in Datacenter
600.3: broker_0: Trying to Create VM #290 in Datacenter
600.3: broker_0: Trying to Create VM #291 in Datacenter
600.3: broker_0: Trying to Create VM #292 in Datacenter
600.3: broker_0: Trying to Create VM #293 in Datacenter
600.3: broker_0: Trying to Create VM #294 in Datacenter
600.3: broker_0: Trying to Create VM #295 in Datacenter
600.3: broker_0: Trying to Create VM #296 in Datacenter
600.3: broker_0: Trying to Create VM #297 in Datacenter
600.3: broker_0: Trying to Create VM #298 in Datacenter
600.3: broker_0: Trying to Create VM #299 in Datacenter
600.3: broker_0: Trying to Create VM #300 in Datacenter
600.3: broker_0: Trying to Create VM #301 in Datacenter
600.3: broker_0: Trying to Create VM #302 in Datacenter
600.3: broker_0: Trying to Create VM #303 in Datacenter
600.3: broker_0: Trying to Create VM #304 in Datacenter
600.3: broker_0: Trying to Create VM #305 in Datacenter
600.3: broker_0: Trying to Create VM #306 in Datacenter
600.3: broker_0: Trying to Create VM #307 in Datacenter
600.3: broker_0: Trying to Create VM #308 in Datacenter
600.3: broker_0: Trying to Create VM #309 in Datacenter
600.3: broker_0: Trying to Create VM #310 in Datacenter
600.3: broker_0: Trying to Create VM #311 in Datacenter
600.3: broker_0: Trying to Create VM #312 in Datacenter
600.3: broker_0: Trying to Create VM #313 in Datacenter
600.3: broker_0: Trying to Create VM #314 in Datacenter
600.3: broker_0: Trying to Create VM #315 in Datacenter
600.3: broker_0: Trying to Create VM #316 in Datacenter
600.3: broker_0: Trying to Create VM #317 in Datacenter
600.3: broker_0: Trying to Create VM #318 in Datacenter
600.3: broker_0: Trying to Create VM #319 in Datacenter
600.3: broker_0: Trying to Create VM #320 in Datacenter
600.3: broker_0: Trying to Create VM #321 in Datacenter
600.3: broker_0: Trying to Create VM #322 in Datacenter
600.3: broker_0: Trying to Create VM #323 in Datacenter
600.3: broker_0: Trying to Create VM #324 in Datacenter
600.3: broker_0: Trying to Create VM #325 in Datacenter
600.3: broker_0: Trying to Create VM #326 in Datacenter
600.3: broker_0: Trying to Create VM #327 in Datacenter
600.3: broker_0: Trying to Create VM #328 in Datacenter
600.3: broker_0: Trying to Create VM #329 in Datacenter
600.3: broker_0: Trying to Create VM #330 in Datacenter
600.3: broker_0: Trying to Create VM #331 in Datacenter
600.3: broker_0: Trying to Create VM #332 in Datacenter
600.3: broker_0: Trying to Create VM #333 in Datacenter
600.3: broker_0: Trying to Create VM #334 in Datacenter
600.3: broker_0: Trying to Create VM #335 in Datacenter
600.3: broker_0: Trying to Create VM #336 in Datacenter
600.3: broker_0: Trying to Create VM #337 in Datacenter
600.3: broker_0: Trying to Create VM #338 in Datacenter
600.3: broker_0: Trying to Create VM #339 in Datacenter
600.3: broker_0: Trying to Create VM #340 in Datacenter
600.3: broker_0: Trying to Create VM #341 in Datacenter
600.3: broker_0: Trying to Create VM #342 in Datacenter
600.3: broker_0: Trying to Create VM #343 in Datacenter
600.3: broker_0: Trying to Create VM #344 in Datacenter
600.3: broker_0: Trying to Create VM #345 in Datacenter
600.3: broker_0: Trying to Create VM #346 in Datacenter
600.3: broker_0: Trying to Create VM #347 in Datacenter
600.3: broker_0: Trying to Create VM #348 in Datacenter
600.3: broker_0: Trying to Create VM #349 in Datacenter
600.3: broker_0: Trying to Create VM #350 in Datacenter
600.3: broker_0: Trying to Create VM #351 in Datacenter
600.3: broker_0: Trying to Create VM #352 in Datacenter
600.3: broker_0: Trying to Create VM #353 in Datacenter
600.3: broker_0: Trying to Create VM #354 in Datacenter
600.3: broker_0: Trying to Create VM #355 in Datacenter
600.3: broker_0: Trying to Create VM #356 in Datacenter
600.3: broker_0: Trying to Create VM #357 in Datacenter
600.3: broker_0: Trying to Create VM #358 in Datacenter
600.3: broker_0: Trying to Create VM #359 in Datacenter
600.3: broker_0: Trying to Create VM #360 in Datacenter
600.3: broker_0: Trying to Create VM #361 in Datacenter
600.3: broker_0: Trying to Create VM #362 in Datacenter
600.3: broker_0: Trying to Create VM #363 in Datacenter
600.3: broker_0: Trying to Create VM #364 in Datacenter
600.3: broker_0: Trying to Create VM #365 in Datacenter
600.3: broker_0: Trying to Create VM #366 in Datacenter
600.3: broker_0: Trying to Create VM #367 in Datacenter
600.3: broker_0: Trying to Create VM #368 in Datacenter
600.3: broker_0: Trying to Create VM #369 in Datacenter
600.3: broker_0: Trying to Create VM #370 in Datacenter
600.3: broker_0: Trying to Create VM #371 in Datacenter
600.3: broker_0: Trying to Create VM #372 in Datacenter
600.3: broker_0: Trying to Create VM #373 in Datacenter
600.3: broker_0: Trying to Create VM #374 in Datacenter
600.3: broker_0: Trying to Create VM #375 in Datacenter
600.3: broker_0: Trying to Create VM #376 in Datacenter
600.3: broker_0: Trying to Create VM #377 in Datacenter
600.3: broker_0: Trying to Create VM #378 in Datacenter
600.3: broker_0: Trying to Create VM #379 in Datacenter
600.3: broker_0: Trying to Create VM #380 in Datacenter
600.3: broker_0: Trying to Create VM #381 in Datacenter
600.3: broker_0: Trying to Create VM #382 in Datacenter
600.3: broker_0: Trying to Create VM #383 in Datacenter
600.3: broker_0: Trying to Create VM #384 in Datacenter
600.3: broker_0: Trying to Create VM #385 in Datacenter
600.3: broker_0: Trying to Create VM #386 in Datacenter
600.3: broker_0: Trying to Create VM #387 in Datacenter
600.3: broker_0: Trying to Create VM #388 in Datacenter
600.3: broker_0: Trying to Create VM #389 in Datacenter
600.3: broker_0: Trying to Create VM #390 in Datacenter
600.3: broker_0: Trying to Create VM #391 in Datacenter
600.3: broker_0: Trying to Create VM #392 in Datacenter
600.3: broker_0: Trying to Create VM #393 in Datacenter
600.3: broker_0: Trying to Create VM #394 in Datacenter
600.3: broker_0: Trying to Create VM #395 in Datacenter
600.3: broker_0: Trying to Create VM #396 in Datacenter
600.3: broker_0: Trying to Create VM #397 in Datacenter
600.3: broker_0: Trying to Create VM #398 in Datacenter
600.3: broker_0: Trying to Create VM #399 in Datacenter
600.3: broker_0: Trying to Create VM #400 in Datacenter
600.3: broker_0: Trying to Create VM #401 in Datacenter
600.3: broker_0: Trying to Create VM #402 in Datacenter
600.3: broker_0: Trying to Create VM #403 in Datacenter
600.3: broker_0: Trying to Create VM #404 in Datacenter
600.3: broker_0: Trying to Create VM #405 in Datacenter
600.3: broker_0: Trying to Create VM #406 in Datacenter
600.3: broker_0: Trying to Create VM #407 in Datacenter
600.3: broker_0: Trying to Create VM #408 in Datacenter
600.3: broker_0: Trying to Create VM #409 in Datacenter
600.3: broker_0: Trying to Create VM #410 in Datacenter
600.3: broker_0: Trying to Create VM #411 in Datacenter
600.3: broker_0: Trying to Create VM #412 in Datacenter
600.3: broker_0: Trying to Create VM #413 in Datacenter
600.3: broker_0: Trying to Create VM #414 in Datacenter
600.3: broker_0: Trying to Create VM #415 in Datacenter
600.3: broker_0: Trying to Create VM #416 in Datacenter
600.3: broker_0: Trying to Create VM #417 in Datacenter
600.3: broker_0: Trying to Create VM #418 in Datacenter
600.3: broker_0: Trying to Create VM #419 in Datacenter
600.3: broker_0: Trying to Create VM #420 in Datacenter
600.3: broker_0: Trying to Create VM #421 in Datacenter
600.3: broker_0: Trying to Create VM #422 in Datacenter
600.3: broker_0: Trying to Create VM #423 in Datacenter
600.3: broker_0: Trying to Create VM #424 in Datacenter
600.3: broker_0: Trying to Create VM #425 in Datacenter
600.3: broker_0: Trying to Create VM #426 in Datacenter
600.3: broker_0: Trying to Create VM #427 in Datacenter
600.3: broker_0: Trying to Create VM #428 in Datacenter
600.3: broker_0: Trying to Create VM #429 in Datacenter
600.3: broker_0: Trying to Create VM #430 in Datacenter
600.3: broker_0: Trying to Create VM #431 in Datacenter
600.3: broker_0: Trying to Create VM #432 in Datacenter
600.3: broker_0: Trying to Create VM #433 in Datacenter
600.3: broker_0: Trying to Create VM #434 in Datacenter
600.3: broker_0: Trying to Create VM #435 in Datacenter
600.3: broker_0: Trying to Create VM #436 in Datacenter
600.3: broker_0: Trying to Create VM #437 in Datacenter
600.3: broker_0: Trying to Create VM #438 in Datacenter
600.3: broker_0: Trying to Create VM #439 in Datacenter
600.3: broker_0: Trying to Create VM #440 in Datacenter
600.3: broker_0: Trying to Create VM #441 in Datacenter
600.3: broker_0: Trying to Create VM #442 in Datacenter
600.3: broker_0: Trying to Create VM #443 in Datacenter
600.3: broker_0: Trying to Create VM #444 in Datacenter
600.3: broker_0: Trying to Create VM #445 in Datacenter
600.3: broker_0: Trying to Create VM #446 in Datacenter
600.3: broker_0: Trying to Create VM #447 in Datacenter
600.3: broker_0: Trying to Create VM #448 in Datacenter
600.3: broker_0: Trying to Create VM #449 in Datacenter
600.3: broker_0: Trying to Create VM #450 in Datacenter
600.3: broker_0: Trying to Create VM #451 in Datacenter
600.3: broker_0: Trying to Create VM #452 in Datacenter
600.3: broker_0: Trying to Create VM #453 in Datacenter
600.3: broker_0: Trying to Create VM #454 in Datacenter
600.3: broker_0: Trying to Create VM #455 in Datacenter
600.3: broker_0: Trying to Create VM #456 in Datacenter
600.3: broker_0: Trying to Create VM #457 in Datacenter
600.3: broker_0: Trying to Create VM #458 in Datacenter
600.3: broker_0: Trying to Create VM #459 in Datacenter
600.3: broker_0: Trying to Create VM #460 in Datacenter
600.3: broker_0: Trying to Create VM #461 in Datacenter
600.3: broker_0: Trying to Create VM #462 in Datacenter
600.3: broker_0: Trying to Create VM #463 in Datacenter
600.3: broker_0: Trying to Create VM #464 in Datacenter
600.3: broker_0: Trying to Create VM #465 in Datacenter
600.3: broker_0: Trying to Create VM #466 in Datacenter
600.3: broker_0: Trying to Create VM #467 in Datacenter
600.3: broker_0: Trying to Create VM #468 in Datacenter
600.3: broker_0: Trying to Create VM #469 in Datacenter
600.3: broker_0: Trying to Create VM #470 in Datacenter
600.3: broker_0: Trying to Create VM #471 in Datacenter
600.3: broker_0: Trying to Create VM #472 in Datacenter
600.3: broker_0: Trying to Create VM #473 in Datacenter
600.3: broker_0: Trying to Create VM #474 in Datacenter
600.3: broker_0: Trying to Create VM #475 in Datacenter
600.3: broker_0: Trying to Create VM #476 in Datacenter
600.3: broker_0: Trying to Create VM #477 in Datacenter
600.3: broker_0: Trying to Create VM #478 in Datacenter
600.3: broker_0: Trying to Create VM #479 in Datacenter
600.3: broker_0: Trying to Create VM #480 in Datacenter
600.3: broker_0: Trying to Create VM #481 in Datacenter
600.3: broker_0: Trying to Create VM #482 in Datacenter
600.3: broker_0: Trying to Create VM #483 in Datacenter
600.3: broker_0: Trying to Create VM #484 in Datacenter
600.3: broker_0: Trying to Create VM #485 in Datacenter
600.3: broker_0: Trying to Create VM #486 in Datacenter
600.3: broker_0: Trying to Create VM #487 in Datacenter
600.3: broker_0: Trying to Create VM #488 in Datacenter
600.3: broker_0: Trying to Create VM #489 in Datacenter
600.3: broker_0: Trying to Create VM #490 in Datacenter
600.3: broker_0: Trying to Create VM #491 in Datacenter
600.3: broker_0: Trying to Create VM #492 in Datacenter
600.3: broker_0: Trying to Create VM #493 in Datacenter
600.3: broker_0: Trying to Create VM #494 in Datacenter
600.3: broker_0: Trying to Create VM #495 in Datacenter
600.3: broker_0: Trying to Create VM #496 in Datacenter
600.3: broker_0: Trying to Create VM #497 in Datacenter
600.3: broker_0: Trying to Create VM #498 in Datacenter
600.3: broker_0: Trying to Create VM #499 in Datacenter
600.3: broker_0: Trying to Create VM #500 in Datacenter
600.3: broker_0: Trying to Create VM #501 in Datacenter
600.3: broker_0: Trying to Create VM #502 in Datacenter
600.3: broker_0: Trying to Create VM #503 in Datacenter
600.3: broker_0: Trying to Create VM #504 in Datacenter
600.3: broker_0: Trying to Create VM #505 in Datacenter
600.3: broker_0: Trying to Create VM #506 in Datacenter
600.3: broker_0: Trying to Create VM #507 in Datacenter
600.3: broker_0: Trying to Create VM #508 in Datacenter
600.3: broker_0: Trying to Create VM #509 in Datacenter
600.3: broker_0: Trying to Create VM #510 in Datacenter
600.3: broker_0: Trying to Create VM #511 in Datacenter
600.3: broker_0: Trying to Create VM #512 in Datacenter
600.3: broker_0: Trying to Create VM #513 in Datacenter
600.3: broker_0: Trying to Create VM #514 in Datacenter
600.3: broker_0: Trying to Create VM #515 in Datacenter
600.3: broker_0: Trying to Create VM #516 in Datacenter
600.3: broker_0: Trying to Create VM #517 in Datacenter
600.3: broker_0: Trying to Create VM #518 in Datacenter
600.3: broker_0: Trying to Create VM #519 in Datacenter
600.3: broker_0: Trying to Create VM #520 in Datacenter
600.3: broker_0: Trying to Create VM #521 in Datacenter
600.3: broker_0: Trying to Create VM #522 in Datacenter
600.3: broker_0: Trying to Create VM #523 in Datacenter
600.3: broker_0: Trying to Create VM #524 in Datacenter
600.3: broker_0: Trying to Create VM #525 in Datacenter
600.3: broker_0: Trying to Create VM #526 in Datacenter
600.3: broker_0: Trying to Create VM #527 in Datacenter
600.3: broker_0: Trying to Create VM #528 in Datacenter
600.3: broker_0: Trying to Create VM #529 in Datacenter
600.3: broker_0: Trying to Create VM #530 in Datacenter
600.3: broker_0: Trying to Create VM #531 in Datacenter
600.3: broker_0: Trying to Create VM #532 in Datacenter
600.3: broker_0: Trying to Create VM #533 in Datacenter
600.3: broker_0: Trying to Create VM #534 in Datacenter
600.3: broker_0: Trying to Create VM #535 in Datacenter
600.3: broker_0: Trying to Create VM #536 in Datacenter
600.3: broker_0: Trying to Create VM #537 in Datacenter
600.3: broker_0: Trying to Create VM #538 in Datacenter
600.3: broker_0: Trying to Create VM #539 in Datacenter
600.3: broker_0: Trying to Create VM #540 in Datacenter
600.3: broker_0: Trying to Create VM #541 in Datacenter
600.3: broker_0: Trying to Create VM #542 in Datacenter
600.3: broker_0: Trying to Create VM #543 in Datacenter
600.3: broker_0: Trying to Create VM #544 in Datacenter
600.3: broker_0: Trying to Create VM #545 in Datacenter
600.3: broker_0: Trying to Create VM #546 in Datacenter
600.3: broker_0: Trying to Create VM #547 in Datacenter
600.3: broker_0: Trying to Create VM #548 in Datacenter
600.3: broker_0: Trying to Create VM #549 in Datacenter
600.3: broker_0: Trying to Create VM #550 in Datacenter
600.3: broker_0: Trying to Create VM #551 in Datacenter
600.3: broker_0: Trying to Create VM #552 in Datacenter
600.3: broker_0: Trying to Create VM #553 in Datacenter
600.3: broker_0: Trying to Create VM #554 in Datacenter
600.3: broker_0: Trying to Create VM #555 in Datacenter
600.3: broker_0: Trying to Create VM #556 in Datacenter
600.3: broker_0: Trying to Create VM #557 in Datacenter
600.3: broker_0: Trying to Create VM #558 in Datacenter
600.3: broker_0: Trying to Create VM #559 in Datacenter
600.3: broker_0: Trying to Create VM #560 in Datacenter
600.3: broker_0: Trying to Create VM #561 in Datacenter
600.3: broker_0: Trying to Create VM #562 in Datacenter
600.3: broker_0: Trying to Create VM #563 in Datacenter
600.3: broker_0: Trying to Create VM #564 in Datacenter
600.3: broker_0: Trying to Create VM #565 in Datacenter
600.3: broker_0: Trying to Create VM #566 in Datacenter
600.3: broker_0: Trying to Create VM #567 in Datacenter
600.3: broker_0: Trying to Create VM #568 in Datacenter
600.3: broker_0: Trying to Create VM #569 in Datacenter
600.3: broker_0: Trying to Create VM #570 in Datacenter
600.3: broker_0: Trying to Create VM #571 in Datacenter
600.3: broker_0: Trying to Create VM #572 in Datacenter
600.3: broker_0: Trying to Create VM #573 in Datacenter
600.3: broker_0: Trying to Create VM #574 in Datacenter
600.3: broker_0: Trying to Create VM #575 in Datacenter
600.3: broker_0: Trying to Create VM #576 in Datacenter
600.3: broker_0: Trying to Create VM #577 in Datacenter
600.3: broker_0: Trying to Create VM #578 in Datacenter
600.3: broker_0: Trying to Create VM #579 in Datacenter
600.3: broker_0: Trying to Create VM #580 in Datacenter
600.3: broker_0: Trying to Create VM #581 in Datacenter
600.3: broker_0: Trying to Create VM #582 in Datacenter
600.3: broker_0: Trying to Create VM #583 in Datacenter
600.3: broker_0: Trying to Create VM #584 in Datacenter
600.3: broker_0: Trying to Create VM #585 in Datacenter
600.3: broker_0: Trying to Create VM #586 in Datacenter
600.3: broker_0: Trying to Create VM #587 in Datacenter
600.3: broker_0: Trying to Create VM #588 in Datacenter
600.3: broker_0: Trying to Create VM #589 in Datacenter
600.3: broker_0: Trying to Create VM #590 in Datacenter
600.3: broker_0: Trying to Create VM #591 in Datacenter
600.3: broker_0: Trying to Create VM #592 in Datacenter
600.3: broker_0: Trying to Create VM #593 in Datacenter
600.3: broker_0: Trying to Create VM #594 in Datacenter
600.3: broker_0: Trying to Create VM #595 in Datacenter
600.3: broker_0: Trying to Create VM #596 in Datacenter
600.3: broker_0: Trying to Create VM #597 in Datacenter
600.3: broker_0: Trying to Create VM #598 in Datacenter
600.3: broker_0: Trying to Create VM #599 in Datacenter
600.3: broker_0: Trying to Create VM #600 in Datacenter
600.3: broker_0: Trying to Create VM #601 in Datacenter
600.3: broker_0: Trying to Create VM #602 in Datacenter
600.3: broker_0: Trying to Create VM #603 in Datacenter
600.3: broker_0: Trying to Create VM #604 in Datacenter
600.3: broker_0: Trying to Create VM #605 in Datacenter
600.3: broker_0: Trying to Create VM #606 in Datacenter
600.3: broker_0: Trying to Create VM #607 in Datacenter
600.3: broker_0: Trying to Create VM #608 in Datacenter
600.3: broker_0: Trying to Create VM #609 in Datacenter
600.3: broker_0: Trying to Create VM #610 in Datacenter
600.3: broker_0: Trying to Create VM #611 in Datacenter
600.3: broker_0: Trying to Create VM #612 in Datacenter
600.3: broker_0: Trying to Create VM #613 in Datacenter
600.3: broker_0: Trying to Create VM #614 in Datacenter
600.3: broker_0: Trying to Create VM #615 in Datacenter
600.3: broker_0: Trying to Create VM #616 in Datacenter
600.3: broker_0: Trying to Create VM #617 in Datacenter
600.3: broker_0: Trying to Create VM #618 in Datacenter
600.3: broker_0: Trying to Create VM #619 in Datacenter
600.3: broker_0: Trying to Create VM #620 in Datacenter
600.3: broker_0: Trying to Create VM #621 in Datacenter
600.3: broker_0: Trying to Create VM #622 in Datacenter
600.3: broker_0: Trying to Create VM #623 in Datacenter
600.3: broker_0: Trying to Create VM #624 in Datacenter
600.3: broker_0: Trying to Create VM #625 in Datacenter
600.3: broker_0: Trying to Create VM #626 in Datacenter
600.3: broker_0: Trying to Create VM #627 in Datacenter
600.3: broker_0: Trying to Create VM #628 in Datacenter
600.3: broker_0: Trying to Create VM #629 in Datacenter
600.3: broker_0: Trying to Create VM #630 in Datacenter
600.3: broker_0: Trying to Create VM #631 in Datacenter
600.3: broker_0: Trying to Create VM #632 in Datacenter
600.3: broker_0: Trying to Create VM #633 in Datacenter
600.3: broker_0: Trying to Create VM #634 in Datacenter
600.3: broker_0: Trying to Create VM #635 in Datacenter
600.3: broker_0: Trying to Create VM #636 in Datacenter
600.3: broker_0: Trying to Create VM #637 in Datacenter
600.3: broker_0: Trying to Create VM #638 in Datacenter
600.3: broker_0: Trying to Create VM #639 in Datacenter
600.3: broker_0: Trying to Create VM #640 in Datacenter
600.3: broker_0: Trying to Create VM #641 in Datacenter
600.3: broker_0: Trying to Create VM #642 in Datacenter
600.3: broker_0: Trying to Create VM #643 in Datacenter
600.3: broker_0: Trying to Create VM #644 in Datacenter
600.3: broker_0: Trying to Create VM #645 in Datacenter
600.3: broker_0: Trying to Create VM #646 in Datacenter
600.3: broker_0: Trying to Create VM #647 in Datacenter
600.3: broker_0: Trying to Create VM #648 in Datacenter
600.3: broker_0: Trying to Create VM #649 in Datacenter
600.3: broker_0: Trying to Create VM #650 in Datacenter
600.3: broker_0: Trying to Create VM #651 in Datacenter
600.3: broker_0: Trying to Create VM #652 in Datacenter
600.3: broker_0: Trying to Create VM #653 in Datacenter
600.3: broker_0: Trying to Create VM #654 in Datacenter
600.3: broker_0: Trying to Create VM #655 in Datacenter
600.3: broker_0: Trying to Create VM #656 in Datacenter
600.3: broker_0: Trying to Create VM #657 in Datacenter
600.3: broker_0: Trying to Create VM #658 in Datacenter
600.3: broker_0: Trying to Create VM #659 in Datacenter
600.3: broker_0: Trying to Create VM #660 in Datacenter
600.3: broker_0: Trying to Create VM #661 in Datacenter
600.3: broker_0: Trying to Create VM #662 in Datacenter
600.3: broker_0: Trying to Create VM #663 in Datacenter
600.3: broker_0: Trying to Create VM #664 in Datacenter
600.3: broker_0: Trying to Create VM #665 in Datacenter
600.3: broker_0: Trying to Create VM #666 in Datacenter
600.3: broker_0: Trying to Create VM #667 in Datacenter
600.3: broker_0: Trying to Create VM #668 in Datacenter
600.3: broker_0: Trying to Create VM #669 in Datacenter
600.3: broker_0: Trying to Create VM #670 in Datacenter
600.3: broker_0: Trying to Create VM #671 in Datacenter
600.3: broker_0: Trying to Create VM #672 in Datacenter
600.3: broker_0: Trying to Create VM #673 in Datacenter
600.3: broker_0: Trying to Create VM #674 in Datacenter
600.3: broker_0: Trying to Create VM #675 in Datacenter
600.3: broker_0: Trying to Create VM #676 in Datacenter
600.3: broker_0: Trying to Create VM #677 in Datacenter
600.3: broker_0: Trying to Create VM #678 in Datacenter
600.3: broker_0: Trying to Create VM #679 in Datacenter
600.3: broker_0: Trying to Create VM #680 in Datacenter
600.3: broker_0: Trying to Create VM #681 in Datacenter
600.3: broker_0: Trying to Create VM #682 in Datacenter
600.3: broker_0: Trying to Create VM #683 in Datacenter
600.3: broker_0: Trying to Create VM #684 in Datacenter
600.3: broker_0: Trying to Create VM #685 in Datacenter
600.3: broker_0: Trying to Create VM #686 in Datacenter
600.3: broker_0: Trying to Create VM #687 in Datacenter
600.3: broker_0: Trying to Create VM #688 in Datacenter
600.3: broker_0: Trying to Create VM #689 in Datacenter
600.3: broker_0: Trying to Create VM #690 in Datacenter
600.3: broker_0: Trying to Create VM #691 in Datacenter
600.3: broker_0: Trying to Create VM #692 in Datacenter
600.3: broker_0: Trying to Create VM #693 in Datacenter
600.3: broker_0: Trying to Create VM #694 in Datacenter
600.3: broker_0: Trying to Create VM #695 in Datacenter
600.3: broker_0: Trying to Create VM #696 in Datacenter
600.3: broker_0: Trying to Create VM #697 in Datacenter
600.3: broker_0: Trying to Create VM #698 in Datacenter
600.3: broker_0: Trying to Create VM #699 in Datacenter
600.3: broker_0: Trying to Create VM #700 in Datacenter
600.3: broker_0: Trying to Create VM #701 in Datacenter
600.3: broker_0: Trying to Create VM #702 in Datacenter
600.3: broker_0: Trying to Create VM #703 in Datacenter
600.3: broker_0: Trying to Create VM #704 in Datacenter
600.3: broker_0: Trying to Create VM #705 in Datacenter
600.3: broker_0: Trying to Create VM #706 in Datacenter
600.3: broker_0: Trying to Create VM #707 in Datacenter
600.3: broker_0: Trying to Create VM #708 in Datacenter
600.3: broker_0: Trying to Create VM #709 in Datacenter
600.3: broker_0: Trying to Create VM #710 in Datacenter
600.3: broker_0: Trying to Create VM #711 in Datacenter
600.3: broker_0: Trying to Create VM #712 in Datacenter
600.3: broker_0: Trying to Create VM #713 in Datacenter
600.3: broker_0: Trying to Create VM #714 in Datacenter
600.3: broker_0: Trying to Create VM #715 in Datacenter
600.3: broker_0: Trying to Create VM #716 in Datacenter
600.3: broker_0: Trying to Create VM #717 in Datacenter
600.3: broker_0: Trying to Create VM #718 in Datacenter
600.3: broker_0: Trying to Create VM #719 in Datacenter
600.3: broker_0: Trying to Create VM #720 in Datacenter
600.3: broker_0: Trying to Create VM #721 in Datacenter
600.3: broker_0: Trying to Create VM #722 in Datacenter
600.3: broker_0: Trying to Create VM #723 in Datacenter
600.3: broker_0: Trying to Create VM #724 in Datacenter
600.3: broker_0: Trying to Create VM #725 in Datacenter
600.3: broker_0: Trying to Create VM #726 in Datacenter
600.3: broker_0: Trying to Create VM #727 in Datacenter
600.3: broker_0: Trying to Create VM #728 in Datacenter
600.3: broker_0: Trying to Create VM #729 in Datacenter
600.3: broker_0: Trying to Create VM #730 in Datacenter
600.3: broker_0: Trying to Create VM #731 in Datacenter
600.3: broker_0: Trying to Create VM #732 in Datacenter
600.3: broker_0: Trying to Create VM #733 in Datacenter
600.3: broker_0: Trying to Create VM #734 in Datacenter
600.3: broker_0: Trying to Create VM #735 in Datacenter
600.3: broker_0: Trying to Create VM #736 in Datacenter
600.3: broker_0: Trying to Create VM #737 in Datacenter
600.3: broker_0: Trying to Create VM #738 in Datacenter
600.3: broker_0: Trying to Create VM #739 in Datacenter
600.3: broker_0: Trying to Create VM #740 in Datacenter
600.3: broker_0: Trying to Create VM #741 in Datacenter
600.3: broker_0: Trying to Create VM #742 in Datacenter
600.3: broker_0: Trying to Create VM #743 in Datacenter
600.3: broker_0: Trying to Create VM #744 in Datacenter
600.3: broker_0: Trying to Create VM #745 in Datacenter
600.3: broker_0: Trying to Create VM #746 in Datacenter
600.3: broker_0: Trying to Create VM #747 in Datacenter
600.3: broker_0: Trying to Create VM #748 in Datacenter
600.3: broker_0: Trying to Create VM #749 in Datacenter
600.3: broker_0: Trying to Create VM #750 in Datacenter
600.3: broker_0: Trying to Create VM #751 in Datacenter
600.3: broker_0: Trying to Create VM #752 in Datacenter
600.3: broker_0: Trying to Create VM #753 in Datacenter
600.3: broker_0: Trying to Create VM #754 in Datacenter
600.3: broker_0: Trying to Create VM #755 in Datacenter
600.3: broker_0: Trying to Create VM #756 in Datacenter
600.3: broker_0: Trying to Create VM #757 in Datacenter
600.3: broker_0: Trying to Create VM #758 in Datacenter
600.3: broker_0: Trying to Create VM #759 in Datacenter
600.3: broker_0: Trying to Create VM #760 in Datacenter
600.3: broker_0: Trying to Create VM #761 in Datacenter
600.3: broker_0: Trying to Create VM #762 in Datacenter
600.3: broker_0: Trying to Create VM #763 in Datacenter
600.3: broker_0: Trying to Create VM #764 in Datacenter
600.3: broker_0: Trying to Create VM #765 in Datacenter
600.3: broker_0: Trying to Create VM #766 in Datacenter
600.3: broker_0: Trying to Create VM #767 in Datacenter
600.3: broker_0: Trying to Create VM #768 in Datacenter
600.3: broker_0: Trying to Create VM #769 in Datacenter
600.3: broker_0: Trying to Create VM #770 in Datacenter
600.3: broker_0: Trying to Create VM #771 in Datacenter
600.3: broker_0: Trying to Create VM #772 in Datacenter
600.3: broker_0: Trying to Create VM #773 in Datacenter
600.3: broker_0: Trying to Create VM #774 in Datacenter
600.3: broker_0: Trying to Create VM #775 in Datacenter
600.3: broker_0: Trying to Create VM #776 in Datacenter
600.3: broker_0: Trying to Create VM #777 in Datacenter
600.3: broker_0: Trying to Create VM #778 in Datacenter
600.3: broker_0: Trying to Create VM #779 in Datacenter
600.3: broker_0: Trying to Create VM #780 in Datacenter
600.3: broker_0: Trying to Create VM #781 in Datacenter
600.3: broker_0: Trying to Create VM #782 in Datacenter
600.3: broker_0: Trying to Create VM #783 in Datacenter
600.3: broker_0: Trying to Create VM #784 in Datacenter
600.3: broker_0: Trying to Create VM #785 in Datacenter
600.3: broker_0: Trying to Create VM #786 in Datacenter
600.3: broker_0: Trying to Create VM #787 in Datacenter
600.3: broker_0: Trying to Create VM #788 in Datacenter
600.3: broker_0: Trying to Create VM #789 in Datacenter
600.3: broker_0: Trying to Create VM #790 in Datacenter
600.3: broker_0: Trying to Create VM #791 in Datacenter
600.3: broker_0: Trying to Create VM #792 in Datacenter
600.3: broker_0: Trying to Create VM #793 in Datacenter
600.3: broker_0: Trying to Create VM #794 in Datacenter
600.3: broker_0: Trying to Create VM #795 in Datacenter
600.3: broker_0: Trying to Create VM #796 in Datacenter
600.3: broker_0: Trying to Create VM #797 in Datacenter
600.3: broker_0: Trying to Create VM #798 in Datacenter
600.3: broker_0: Trying to Create VM #799 in Datacenter
600.3: broker_0: Trying to Create VM #800 in Datacenter
600.3: broker_0: Trying to Create VM #801 in Datacenter
600.3: broker_0: Trying to Create VM #802 in Datacenter
600.3: broker_0: Trying to Create VM #803 in Datacenter
600.3: broker_0: Trying to Create VM #804 in Datacenter
600.3: broker_0: Trying to Create VM #805 in Datacenter
600.3: broker_0: Trying to Create VM #806 in Datacenter
600.3: broker_0: Trying to Create VM #807 in Datacenter
600.3: broker_0: Trying to Create VM #808 in Datacenter
600.3: broker_0: Trying to Create VM #809 in Datacenter
600.3: broker_0: Trying to Create VM #810 in Datacenter
600.3: broker_0: Trying to Create VM #811 in Datacenter
600.3: broker_0: Trying to Create VM #812 in Datacenter
600.3: broker_0: Trying to Create VM #813 in Datacenter
600.3: broker_0: Trying to Create VM #814 in Datacenter
600.3: broker_0: Trying to Create VM #815 in Datacenter
600.3: broker_0: Trying to Create VM #816 in Datacenter
600.3: broker_0: Trying to Create VM #817 in Datacenter
600.3: broker_0: Trying to Create VM #818 in Datacenter
600.3: broker_0: Trying to Create VM #819 in Datacenter
600.3: broker_0: Trying to Create VM #820 in Datacenter
600.3: broker_0: Trying to Create VM #821 in Datacenter
600.3: broker_0: Trying to Create VM #822 in Datacenter
600.3: broker_0: Trying to Create VM #823 in Datacenter
600.3: broker_0: Trying to Create VM #824 in Datacenter
600.3: broker_0: Trying to Create VM #825 in Datacenter
600.3: broker_0: Trying to Create VM #826 in Datacenter
600.3: broker_0: Trying to Create VM #827 in Datacenter
600.3: broker_0: Trying to Create VM #828 in Datacenter
600.3: broker_0: Trying to Create VM #829 in Datacenter
600.3: broker_0: Trying to Create VM #830 in Datacenter
600.3: broker_0: Trying to Create VM #831 in Datacenter
600.3: broker_0: Trying to Create VM #832 in Datacenter
600.3: broker_0: Trying to Create VM #833 in Datacenter
600.3: broker_0: Trying to Create VM #834 in Datacenter
600.3: broker_0: Trying to Create VM #835 in Datacenter
600.3: broker_0: Trying to Create VM #836 in Datacenter
600.3: broker_0: Trying to Create VM #837 in Datacenter
600.3: broker_0: Trying to Create VM #838 in Datacenter
600.3: broker_0: Trying to Create VM #839 in Datacenter
600.3: broker_0: Trying to Create VM #840 in Datacenter
600.3: broker_0: Trying to Create VM #841 in Datacenter
600.3: broker_0: Trying to Create VM #842 in Datacenter
600.3: broker_0: Trying to Create VM #843 in Datacenter
600.3: broker_0: Trying to Create VM #844 in Datacenter
600.3: broker_0: Trying to Create VM #845 in Datacenter
600.3: broker_0: Trying to Create VM #846 in Datacenter
600.3: broker_0: Trying to Create VM #847 in Datacenter
600.3: broker_0: Trying to Create VM #848 in Datacenter
600.3: broker_0: Trying to Create VM #849 in Datacenter
600.3: broker_0: Trying to Create VM #850 in Datacenter
600.3: broker_0: Trying to Create VM #851 in Datacenter
600.3: broker_0: Trying to Create VM #852 in Datacenter
600.3: broker_0: Trying to Create VM #853 in Datacenter
600.3: broker_0: Trying to Create VM #854 in Datacenter
600.3: broker_0: Trying to Create VM #855 in Datacenter
600.3: broker_0: Trying to Create VM #856 in Datacenter
600.3: broker_0: Trying to Create VM #857 in Datacenter
600.3: broker_0: Trying to Create VM #858 in Datacenter
600.3: broker_0: Trying to Create VM #859 in Datacenter
600.3: broker_0: Trying to Create VM #860 in Datacenter
600.3: broker_0: Trying to Create VM #861 in Datacenter
600.3: broker_0: Trying to Create VM #862 in Datacenter
600.3: broker_0: Trying to Create VM #863 in Datacenter
600.3: broker_0: Trying to Create VM #864 in Datacenter
600.3: broker_0: Trying to Create VM #865 in Datacenter
600.3: broker_0: Trying to Create VM #866 in Datacenter
600.3: broker_0: Trying to Create VM #867 in Datacenter
600.3: broker_0: Trying to Create VM #868 in Datacenter
600.3: broker_0: Trying to Create VM #869 in Datacenter
600.3: broker_0: Trying to Create VM #870 in Datacenter
600.3: broker_0: Trying to Create VM #871 in Datacenter
600.3: broker_0: Trying to Create VM #872 in Datacenter
600.3: broker_0: Trying to Create VM #873 in Datacenter
600.3: broker_0: Trying to Create VM #874 in Datacenter
600.3: broker_0: Trying to Create VM #875 in Datacenter
600.3: broker_0: Trying to Create VM #876 in Datacenter
600.3: broker_0: Trying to Create VM #877 in Datacenter
600.3: broker_0: Trying to Create VM #878 in Datacenter
600.3: broker_0: Trying to Create VM #879 in Datacenter
600.3: broker_0: Trying to Create VM #880 in Datacenter
600.3: broker_0: Trying to Create VM #881 in Datacenter
600.3: broker_0: Trying to Create VM #882 in Datacenter
600.3: broker_0: Trying to Create VM #883 in Datacenter
600.3: broker_0: Trying to Create VM #884 in Datacenter
600.3: broker_0: Trying to Create VM #885 in Datacenter
600.3: broker_0: Trying to Create VM #886 in Datacenter
600.3: broker_0: Trying to Create VM #887 in Datacenter
600.3: broker_0: Trying to Create VM #888 in Datacenter
600.3: broker_0: Trying to Create VM #889 in Datacenter
600.3: broker_0: Trying to Create VM #890 in Datacenter
600.3: broker_0: Trying to Create VM #891 in Datacenter
600.3: broker_0: Trying to Create VM #892 in Datacenter
600.3: broker_0: Trying to Create VM #893 in Datacenter
600.3: broker_0: Trying to Create VM #894 in Datacenter
600.3: broker_0: Trying to Create VM #895 in Datacenter
600.3: broker_0: Trying to Create VM #896 in Datacenter
600.3: broker_0: Trying to Create VM #897 in Datacenter
600.3: broker_0: Trying to Create VM #898 in Datacenter
600.3: broker_0: Trying to Create VM #899 in Datacenter
600.3: broker_0: Trying to Create VM #900 in Datacenter
600.3: broker_0: Trying to Create VM #901 in Datacenter
600.3: broker_0: Trying to Create VM #902 in Datacenter
600.3: broker_0: Trying to Create VM #903 in Datacenter
600.3: broker_0: Trying to Create VM #904 in Datacenter
600.3: broker_0: Trying to Create VM #905 in Datacenter
600.3: broker_0: Trying to Create VM #906 in Datacenter
600.3: broker_0: Trying to Create VM #907 in Datacenter
600.3: broker_0: Trying to Create VM #908 in Datacenter
600.3: broker_0: Trying to Create VM #909 in Datacenter
600.3: broker_0: Trying to Create VM #910 in Datacenter
600.3: broker_0: Trying to Create VM #911 in Datacenter
600.3: broker_0: Trying to Create VM #912 in Datacenter
600.3: broker_0: Trying to Create VM #913 in Datacenter
600.3: broker_0: Trying to Create VM #914 in Datacenter
600.3: broker_0: Trying to Create VM #915 in Datacenter
600.3: broker_0: Trying to Create VM #916 in Datacenter
600.3: broker_0: Trying to Create VM #917 in Datacenter
600.3: broker_0: Trying to Create VM #918 in Datacenter
600.3: broker_0: Trying to Create VM #919 in Datacenter
600.3: broker_0: Trying to Create VM #920 in Datacenter
600.3: broker_0: Trying to Create VM #921 in Datacenter
600.3: broker_0: Trying to Create VM #922 in Datacenter
600.3: broker_0: Trying to Create VM #923 in Datacenter
600.3: broker_0: Trying to Create VM #924 in Datacenter
600.3: broker_0: Trying to Create VM #925 in Datacenter
600.3: broker_0: Trying to Create VM #926 in Datacenter
600.3: broker_0: Trying to Create VM #927 in Datacenter
600.3: broker_0: Trying to Create VM #928 in Datacenter
600.3: broker_0: Trying to Create VM #929 in Datacenter
600.3: broker_0: Trying to Create VM #930 in Datacenter
600.3: broker_0: Trying to Create VM #931 in Datacenter
600.3: broker_0: Trying to Create VM #932 in Datacenter
600.3: broker_0: Trying to Create VM #933 in Datacenter
600.3: broker_0: Trying to Create VM #934 in Datacenter
600.3: broker_0: Trying to Create VM #935 in Datacenter
600.3: broker_0: Trying to Create VM #936 in Datacenter
600.3: broker_0: Trying to Create VM #937 in Datacenter
600.3: broker_0: Trying to Create VM #938 in Datacenter
600.3: broker_0: Trying to Create VM #939 in Datacenter
600.3: broker_0: Trying to Create VM #940 in Datacenter
600.3: broker_0: Trying to Create VM #941 in Datacenter
600.3: broker_0: Trying to Create VM #942 in Datacenter
600.3: broker_0: Trying to Create VM #943 in Datacenter
600.3: broker_0: Trying to Create VM #944 in Datacenter
600.3: broker_0: Trying to Create VM #945 in Datacenter
600.3: broker_0: Trying to Create VM #946 in Datacenter
600.3: broker_0: Trying to Create VM #947 in Datacenter
600.3: broker_0: Trying to Create VM #948 in Datacenter
600.3: broker_0: Trying to Create VM #949 in Datacenter
600.3: broker_0: Trying to Create VM #950 in Datacenter
600.3: broker_0: Trying to Create VM #951 in Datacenter
600.3: broker_0: Trying to Create VM #952 in Datacenter
600.3: broker_0: Trying to Create VM #953 in Datacenter
600.3: broker_0: Trying to Create VM #954 in Datacenter
600.3: broker_0: Trying to Create VM #955 in Datacenter
600.3: broker_0: Trying to Create VM #956 in Datacenter
600.3: broker_0: Trying to Create VM #957 in Datacenter
600.3: broker_0: Trying to Create VM #958 in Datacenter
600.3: broker_0: Trying to Create VM #959 in Datacenter
600.3: broker_0: Trying to Create VM #960 in Datacenter
600.3: broker_0: Trying to Create VM #961 in Datacenter
600.3: broker_0: Trying to Create VM #962 in Datacenter
600.3: broker_0: Trying to Create VM #963 in Datacenter
600.3: broker_0: Trying to Create VM #964 in Datacenter
600.3: broker_0: Trying to Create VM #965 in Datacenter
600.3: broker_0: Trying to Create VM #966 in Datacenter
600.3: broker_0: Trying to Create VM #967 in Datacenter
600.3: broker_0: Trying to Create VM #968 in Datacenter
600.3: broker_0: Trying to Create VM #969 in Datacenter
600.3: broker_0: Trying to Create VM #970 in Datacenter
600.3: broker_0: Trying to Create VM #971 in Datacenter
600.3: broker_0: Trying to Create VM #972 in Datacenter
600.3: broker_0: Trying to Create VM #973 in Datacenter
600.3: broker_0: Trying to Create VM #974 in Datacenter
600.3: broker_0: Trying to Create VM #975 in Datacenter
600.3: broker_0: Trying to Create VM #976 in Datacenter
600.3: broker_0: Trying to Create VM #977 in Datacenter
600.3: broker_0: Trying to Create VM #978 in Datacenter
600.3: broker_0: Trying to Create VM #979 in Datacenter
600.3: broker_0: Trying to Create VM #980 in Datacenter
600.3: broker_0: Trying to Create VM #981 in Datacenter
600.3: broker_0: Trying to Create VM #982 in Datacenter
600.3: broker_0: Trying to Create VM #983 in Datacenter
600.3: broker_0: Trying to Create VM #984 in Datacenter
600.3: broker_0: Trying to Create VM #985 in Datacenter
600.3: broker_0: Trying to Create VM #986 in Datacenter
600.3: broker_0: Trying to Create VM #987 in Datacenter
600.3: broker_0: Trying to Create VM #988 in Datacenter
600.3: broker_0: Trying to Create VM #989 in Datacenter
600.3: broker_0: Trying to Create VM #990 in Datacenter
600.3: broker_0: Trying to Create VM #991 in Datacenter
600.3: broker_0: Trying to Create VM #992 in Datacenter
600.3: broker_0: Trying to Create VM #993 in Datacenter
600.3: broker_0: Trying to Create VM #994 in Datacenter
600.3: broker_0: Trying to Create VM #995 in Datacenter
600.3: broker_0: Trying to Create VM #996 in Datacenter
600.3: broker_0: Trying to Create VM #997 in Datacenter
600.3: broker_0: Trying to Create VM #998 in Datacenter
600.3: broker_0: Trying to Create VM #999 in Datacenter
600.30: VM #0 has been allocated to the host #0
600.30: VM #1 has been allocated to the host #0
600.30: VM #2 has been allocated to the host #0
600.30: VM #3 has been allocated to the host #0
600.30: VM #4 has been allocated to the host #0
600.30: VM #5 has been allocated to the host #0
600.30: VM #6 has been allocated to the host #0
600.30: VM #7 has been allocated to the host #0
600.30: VM #8 has been allocated to the host #0
600.30: VM #9 has been allocated to the host #0
600.30: VM #10 has been allocated to the host #1
600.30: VM #11 has been allocated to the host #1
600.30: VM #12 has been allocated to the host #1
600.30: VM #13 has been allocated to the host #1
600.30: VM #14 has been allocated to the host #1
600.30: VM #15 has been allocated to the host #1
600.30: VM #16 has been allocated to the host #1
600.30: VM #17 has been allocated to the host #1
600.30: VM #18 has been allocated to the host #1
600.30: VM #19 has been allocated to the host #1
600.30: VM #20 has been allocated to the host #2
600.30: VM #21 has been allocated to the host #2
600.30: VM #22 has been allocated to the host #2
600.30: VM #23 has been allocated to the host #2
600.30: VM #24 has been allocated to the host #2
600.30: VM #25 has been allocated to the host #2
600.30: VM #26 has been allocated to the host #2
600.30: VM #27 has been allocated to the host #2
600.30: VM #28 has been allocated to the host #2
600.30: VM #29 has been allocated to the host #2
600.30: VM #30 has been allocated to the host #3
600.30: VM #31 has been allocated to the host #3
600.30: VM #32 has been allocated to the host #3
600.30: VM #33 has been allocated to the host #3
600.30: VM #34 has been allocated to the host #3
600.30: VM #35 has been allocated to the host #3
600.30: VM #36 has been allocated to the host #3
600.30: VM #37 has been allocated to the host #3
600.30: VM #38 has been allocated to the host #3
600.30: VM #39 has been allocated to the host #3
600.30: VM #40 has been allocated to the host #4
600.30: VM #41 has been allocated to the host #4
600.30: VM #42 has been allocated to the host #4
600.30: VM #43 has been allocated to the host #4
600.30: VM #44 has been allocated to the host #4
600.30: VM #45 has been allocated to the host #4
600.30: VM #46 has been allocated to the host #4
600.30: VM #47 has been allocated to the host #4
600.30: VM #48 has been allocated to the host #4
600.30: VM #49 has been allocated to the host #4
600.30: VM #50 has been allocated to the host #5
600.30: VM #51 has been allocated to the host #5
600.30: VM #52 has been allocated to the host #5
600.30: VM #53 has been allocated to the host #5
600.30: VM #54 has been allocated to the host #5
600.30: VM #55 has been allocated to the host #5
600.30: VM #56 has been allocated to the host #5
600.30: VM #57 has been allocated to the host #5
600.30: VM #58 has been allocated to the host #5
600.30: VM #59 has been allocated to the host #5
600.30: VM #60 has been allocated to the host #6
600.30: VM #61 has been allocated to the host #6
600.30: VM #62 has been allocated to the host #6
600.30: VM #63 has been allocated to the host #6
600.30: VM #64 has been allocated to the host #6
600.30: VM #65 has been allocated to the host #6
600.30: VM #66 has been allocated to the host #6
600.30: VM #67 has been allocated to the host #6
600.30: VM #68 has been allocated to the host #6
600.30: VM #69 has been allocated to the host #6
600.30: VM #70 has been allocated to the host #7
600.30: VM #71 has been allocated to the host #7
600.30: VM #72 has been allocated to the host #7
600.30: VM #73 has been allocated to the host #7
600.30: VM #74 has been allocated to the host #7
600.30: VM #75 has been allocated to the host #7
600.30: VM #76 has been allocated to the host #7
600.30: VM #77 has been allocated to the host #7
600.30: VM #78 has been allocated to the host #7
600.30: VM #79 has been allocated to the host #7
600.30: VM #80 has been allocated to the host #8
600.30: VM #81 has been allocated to the host #8
600.30: VM #82 has been allocated to the host #8
600.30: VM #83 has been allocated to the host #8
600.30: VM #84 has been allocated to the host #8
600.30: VM #85 has been allocated to the host #8
600.30: VM #86 has been allocated to the host #8
600.30: VM #87 has been allocated to the host #8
600.30: VM #88 has been allocated to the host #8
600.30: VM #89 has been allocated to the host #8
600.30: VM #90 has been allocated to the host #9
600.30: VM #91 has been allocated to the host #9
600.30: VM #92 has been allocated to the host #9
600.30: VM #93 has been allocated to the host #9
600.30: VM #94 has been allocated to the host #9
600.30: VM #95 has been allocated to the host #9
600.30: VM #96 has been allocated to the host #9
600.30: VM #97 has been allocated to the host #9
600.30: VM #98 has been allocated to the host #9
600.30: VM #99 has been allocated to the host #9
600.30: VM #100 has been allocated to the host #10
600.30: VM #101 has been allocated to the host #10
600.30: VM #102 has been allocated to the host #10
600.30: VM #103 has been allocated to the host #10
600.30: VM #104 has been allocated to the host #10
600.30: VM #105 has been allocated to the host #10
600.30: VM #106 has been allocated to the host #10
600.30: VM #107 has been allocated to the host #10
600.30: VM #108 has been allocated to the host #10
600.30: VM #109 has been allocated to the host #10
600.30: VM #110 has been allocated to the host #11
600.30: VM #111 has been allocated to the host #11
600.30: VM #112 has been allocated to the host #11
600.30: VM #113 has been allocated to the host #11
600.30: VM #114 has been allocated to the host #11
600.30: VM #115 has been allocated to the host #11
600.30: VM #116 has been allocated to the host #11
600.30: VM #117 has been allocated to the host #11
600.30: VM #118 has been allocated to the host #11
600.30: VM #119 has been allocated to the host #11
600.30: VM #120 has been allocated to the host #12
600.30: VM #121 has been allocated to the host #12
600.30: VM #122 has been allocated to the host #12
600.30: VM #123 has been allocated to the host #12
600.30: VM #124 has been allocated to the host #12
600.30: VM #125 has been allocated to the host #12
600.30: VM #126 has been allocated to the host #12
600.30: VM #127 has been allocated to the host #12
600.30: VM #128 has been allocated to the host #12
600.30: VM #129 has been allocated to the host #12
600.30: VM #130 has been allocated to the host #13
600.30: VM #131 has been allocated to the host #13
600.30: VM #132 has been allocated to the host #13
600.30: VM #133 has been allocated to the host #13
600.30: VM #134 has been allocated to the host #13
600.30: VM #135 has been allocated to the host #13
600.30: VM #136 has been allocated to the host #13
600.30: VM #137 has been allocated to the host #13
600.30: VM #138 has been allocated to the host #13
600.30: VM #139 has been allocated to the host #13
600.30: VM #140 has been allocated to the host #14
600.30: VM #141 has been allocated to the host #14
600.30: VM #142 has been allocated to the host #14
600.30: VM #143 has been allocated to the host #14
600.30: VM #144 has been allocated to the host #14
600.30: VM #145 has been allocated to the host #14
600.30: VM #146 has been allocated to the host #14
600.30: VM #147 has been allocated to the host #14
600.30: VM #148 has been allocated to the host #14
600.30: VM #149 has been allocated to the host #14
600.30: VM #150 has been allocated to the host #15
600.30: VM #151 has been allocated to the host #15
600.30: VM #152 has been allocated to the host #15
600.30: VM #153 has been allocated to the host #15
600.30: VM #154 has been allocated to the host #15
600.30: VM #155 has been allocated to the host #15
600.30: VM #156 has been allocated to the host #15
600.30: VM #157 has been allocated to the host #15
600.30: VM #158 has been allocated to the host #15
600.30: VM #159 has been allocated to the host #15
600.30: VM #160 has been allocated to the host #16
600.30: VM #161 has been allocated to the host #16
600.30: VM #162 has been allocated to the host #16
600.30: VM #163 has been allocated to the host #16
600.30: VM #164 has been allocated to the host #16
600.30: VM #165 has been allocated to the host #16
600.30: VM #166 has been allocated to the host #16
600.30: VM #167 has been allocated to the host #16
600.30: VM #168 has been allocated to the host #16
600.30: VM #169 has been allocated to the host #16
600.30: VM #170 has been allocated to the host #17
600.30: VM #171 has been allocated to the host #17
600.30: VM #172 has been allocated to the host #17
600.30: VM #173 has been allocated to the host #17
600.30: VM #174 has been allocated to the host #17
600.30: VM #175 has been allocated to the host #17
600.30: VM #176 has been allocated to the host #17
600.30: VM #177 has been allocated to the host #17
600.30: VM #178 has been allocated to the host #17
600.30: VM #179 has been allocated to the host #17
600.30: VM #180 has been allocated to the host #18
600.30: VM #181 has been allocated to the host #18
600.30: VM #182 has been allocated to the host #18
600.30: VM #183 has been allocated to the host #18
600.30: VM #184 has been allocated to the host #18
600.30: VM #185 has been allocated to the host #18
600.30: VM #186 has been allocated to the host #18
600.30: VM #187 has been allocated to the host #18
600.30: VM #188 has been allocated to the host #18
600.30: VM #189 has been allocated to the host #18
600.30: VM #190 has been allocated to the host #19
600.30: VM #191 has been allocated to the host #19
600.30: VM #192 has been allocated to the host #19
600.30: VM #193 has been allocated to the host #19
600.30: VM #194 has been allocated to the host #19
600.30: VM #195 has been allocated to the host #19
600.30: VM #196 has been allocated to the host #19
600.30: VM #197 has been allocated to the host #19
600.30: VM #198 has been allocated to the host #19
600.30: VM #199 has been allocated to the host #19
600.30: VM #200 has been allocated to the host #20
600.30: VM #201 has been allocated to the host #20
600.30: VM #202 has been allocated to the host #20
600.30: VM #203 has been allocated to the host #20
600.30: VM #204 has been allocated to the host #20
600.30: VM #205 has been allocated to the host #20
600.30: VM #206 has been allocated to the host #20
600.30: VM #207 has been allocated to the host #20
600.30: VM #208 has been allocated to the host #20
600.30: VM #209 has been allocated to the host #20
600.30: VM #210 has been allocated to the host #21
600.30: VM #211 has been allocated to the host #21
600.30: VM #212 has been allocated to the host #21
600.30: VM #213 has been allocated to the host #21
600.30: VM #214 has been allocated to the host #21
600.30: VM #215 has been allocated to the host #21
600.30: VM #216 has been allocated to the host #21
600.30: VM #217 has been allocated to the host #21
600.30: VM #218 has been allocated to the host #21
600.30: VM #219 has been allocated to the host #21
600.30: VM #220 has been allocated to the host #22
600.30: VM #221 has been allocated to the host #22
600.30: VM #222 has been allocated to the host #22
600.30: VM #223 has been allocated to the host #22
600.30: VM #224 has been allocated to the host #22
600.30: VM #225 has been allocated to the host #22
600.30: VM #226 has been allocated to the host #22
600.30: VM #227 has been allocated to the host #22
600.30: VM #228 has been allocated to the host #22
600.30: VM #229 has been allocated to the host #22
600.30: VM #230 has been allocated to the host #23
600.30: VM #231 has been allocated to the host #23
600.30: VM #232 has been allocated to the host #23
600.30: VM #233 has been allocated to the host #23
600.30: VM #234 has been allocated to the host #23
600.30: VM #235 has been allocated to the host #23
600.30: VM #236 has been allocated to the host #23
600.30: VM #237 has been allocated to the host #23
600.30: VM #238 has been allocated to the host #23
600.30: VM #239 has been allocated to the host #23
600.30: VM #240 has been allocated to the host #24
600.30: VM #241 has been allocated to the host #24
600.30: VM #242 has been allocated to the host #24
600.30: VM #243 has been allocated to the host #24
600.30: VM #244 has been allocated to the host #24
600.30: VM #245 has been allocated to the host #24
600.30: VM #246 has been allocated to the host #24
600.30: VM #247 has been allocated to the host #24
600.30: VM #248 has been allocated to the host #24
600.30: VM #249 has been allocated to the host #24
600.30: VM #250 has been allocated to the host #25
600.30: VM #251 has been allocated to the host #25
600.30: VM #252 has been allocated to the host #25
600.30: VM #253 has been allocated to the host #25
600.30: VM #254 has been allocated to the host #25
600.30: VM #255 has been allocated to the host #25
600.30: VM #256 has been allocated to the host #25
600.30: VM #257 has been allocated to the host #25
600.30: VM #258 has been allocated to the host #25
600.30: VM #259 has been allocated to the host #25
600.30: VM #260 has been allocated to the host #26
600.30: VM #261 has been allocated to the host #26
600.30: VM #262 has been allocated to the host #26
600.30: VM #263 has been allocated to the host #26
600.30: VM #264 has been allocated to the host #26
600.30: VM #265 has been allocated to the host #26
600.30: VM #266 has been allocated to the host #26
600.30: VM #267 has been allocated to the host #26
600.30: VM #268 has been allocated to the host #26
600.30: VM #269 has been allocated to the host #26
600.30: VM #270 has been allocated to the host #27
600.30: VM #271 has been allocated to the host #27
600.30: VM #272 has been allocated to the host #27
600.30: VM #273 has been allocated to the host #27
600.30: VM #274 has been allocated to the host #27
600.30: VM #275 has been allocated to the host #27
600.30: VM #276 has been allocated to the host #27
600.30: VM #277 has been allocated to the host #27
600.30: VM #278 has been allocated to the host #27
600.30: VM #279 has been allocated to the host #27
600.30: VM #280 has been allocated to the host #28
600.30: VM #281 has been allocated to the host #28
600.30: VM #282 has been allocated to the host #28
600.30: VM #283 has been allocated to the host #28
600.30: VM #284 has been allocated to the host #28
600.30: VM #285 has been allocated to the host #28
600.30: VM #286 has been allocated to the host #28
600.30: VM #287 has been allocated to the host #28
600.30: VM #288 has been allocated to the host #28
600.30: VM #289 has been allocated to the host #28
600.30: VM #290 has been allocated to the host #29
600.30: VM #291 has been allocated to the host #29
600.30: VM #292 has been allocated to the host #29
600.30: VM #293 has been allocated to the host #29
600.30: VM #294 has been allocated to the host #29
600.30: VM #295 has been allocated to the host #29
600.30: VM #296 has been allocated to the host #29
600.30: VM #297 has been allocated to the host #29
600.30: VM #298 has been allocated to the host #29
600.30: VM #299 has been allocated to the host #29
600.30: VM #300 has been allocated to the host #30
600.30: VM #301 has been allocated to the host #30
600.30: VM #302 has been allocated to the host #30
600.30: VM #303 has been allocated to the host #30
600.30: VM #304 has been allocated to the host #30
600.30: VM #305 has been allocated to the host #30
600.30: VM #306 has been allocated to the host #30
600.30: VM #307 has been allocated to the host #30
600.30: VM #308 has been allocated to the host #30
600.30: VM #309 has been allocated to the host #30
600.30: VM #310 has been allocated to the host #31
600.30: VM #311 has been allocated to the host #31
600.30: VM #312 has been allocated to the host #31
600.30: VM #313 has been allocated to the host #31
600.30: VM #314 has been allocated to the host #31
600.30: VM #315 has been allocated to the host #31
600.30: VM #316 has been allocated to the host #31
600.30: VM #317 has been allocated to the host #31
600.30: VM #318 has been allocated to the host #31
600.30: VM #319 has been allocated to the host #31
600.30: VM #320 has been allocated to the host #32
600.30: VM #321 has been allocated to the host #32
600.30: VM #322 has been allocated to the host #32
600.30: VM #323 has been allocated to the host #32
600.30: VM #324 has been allocated to the host #32
600.30: VM #325 has been allocated to the host #32
600.30: VM #326 has been allocated to the host #32
600.30: VM #327 has been allocated to the host #32
600.30: VM #328 has been allocated to the host #32
600.30: VM #329 has been allocated to the host #32
600.30: VM #330 has been allocated to the host #33
600.30: VM #331 has been allocated to the host #33
600.30: VM #332 has been allocated to the host #33
600.30: VM #333 has been allocated to the host #33
600.30: VM #334 has been allocated to the host #33
600.30: VM #335 has been allocated to the host #33
600.30: VM #336 has been allocated to the host #33
600.30: VM #337 has been allocated to the host #33
600.30: VM #338 has been allocated to the host #33
600.30: VM #339 has been allocated to the host #33
600.30: VM #340 has been allocated to the host #34
600.30: VM #341 has been allocated to the host #34
600.30: VM #342 has been allocated to the host #34
600.30: VM #343 has been allocated to the host #34
600.30: VM #344 has been allocated to the host #34
600.30: VM #345 has been allocated to the host #34
600.30: VM #346 has been allocated to the host #34
600.30: VM #347 has been allocated to the host #34
600.30: VM #348 has been allocated to the host #34
600.30: VM #349 has been allocated to the host #34
600.30: VM #350 has been allocated to the host #35
600.30: VM #351 has been allocated to the host #35
600.30: VM #352 has been allocated to the host #35
600.30: VM #353 has been allocated to the host #35
600.30: VM #354 has been allocated to the host #35
600.30: VM #355 has been allocated to the host #35
600.30: VM #356 has been allocated to the host #35
600.30: VM #357 has been allocated to the host #35
600.30: VM #358 has been allocated to the host #35
600.30: VM #359 has been allocated to the host #35
600.30: VM #360 has been allocated to the host #36
600.30: VM #361 has been allocated to the host #36
600.30: VM #362 has been allocated to the host #36
600.30: VM #363 has been allocated to the host #36
600.30: VM #364 has been allocated to the host #36
600.30: VM #365 has been allocated to the host #36
600.30: VM #366 has been allocated to the host #36
600.30: VM #367 has been allocated to the host #36
600.30: VM #368 has been allocated to the host #36
600.30: VM #369 has been allocated to the host #36
600.30: VM #370 has been allocated to the host #37
600.30: VM #371 has been allocated to the host #37
600.30: VM #372 has been allocated to the host #37
600.30: VM #373 has been allocated to the host #37
600.30: VM #374 has been allocated to the host #37
600.30: VM #375 has been allocated to the host #37
600.30: VM #376 has been allocated to the host #37
600.30: VM #377 has been allocated to the host #37
600.30: VM #378 has been allocated to the host #37
600.30: VM #379 has been allocated to the host #37
600.30: VM #380 has been allocated to the host #38
600.30: VM #381 has been allocated to the host #38
600.30: VM #382 has been allocated to the host #38
600.30: VM #383 has been allocated to the host #38
600.30: VM #384 has been allocated to the host #38
600.30: VM #385 has been allocated to the host #38
600.30: VM #386 has been allocated to the host #38
600.30: VM #387 has been allocated to the host #38
600.30: VM #388 has been allocated to the host #38
600.30: VM #389 has been allocated to the host #38
600.30: VM #390 has been allocated to the host #39
600.30: VM #391 has been allocated to the host #39
600.30: VM #392 has been allocated to the host #39
600.30: VM #393 has been allocated to the host #39
600.30: VM #394 has been allocated to the host #39
600.30: VM #395 has been allocated to the host #39
600.30: VM #396 has been allocated to the host #39
600.30: VM #397 has been allocated to the host #39
600.30: VM #398 has been allocated to the host #39
600.30: VM #399 has been allocated to the host #39
600.30: VM #400 has been allocated to the host #40
600.30: VM #401 has been allocated to the host #40
600.30: VM #402 has been allocated to the host #40
600.30: VM #403 has been allocated to the host #40
600.30: VM #404 has been allocated to the host #40
600.30: VM #405 has been allocated to the host #40
600.30: VM #406 has been allocated to the host #40
600.30: VM #407 has been allocated to the host #40
600.30: VM #408 has been allocated to the host #40
600.30: VM #409 has been allocated to the host #40
600.30: VM #410 has been allocated to the host #41
600.30: VM #411 has been allocated to the host #41
600.30: VM #412 has been allocated to the host #41
600.30: VM #413 has been allocated to the host #41
600.30: VM #414 has been allocated to the host #41
600.30: VM #415 has been allocated to the host #41
600.30: VM #416 has been allocated to the host #41
600.30: VM #417 has been allocated to the host #41
600.30: VM #418 has been allocated to the host #41
600.30: VM #419 has been allocated to the host #41
600.30: VM #420 has been allocated to the host #42
600.30: VM #421 has been allocated to the host #42
600.30: VM #422 has been allocated to the host #42
600.30: VM #423 has been allocated to the host #42
600.30: VM #424 has been allocated to the host #42
600.30: VM #425 has been allocated to the host #42
600.30: VM #426 has been allocated to the host #42
600.30: VM #427 has been allocated to the host #42
600.30: VM #428 has been allocated to the host #42
600.30: VM #429 has been allocated to the host #42
600.30: VM #430 has been allocated to the host #43
600.30: VM #431 has been allocated to the host #43
600.30: VM #432 has been allocated to the host #43
600.30: VM #433 has been allocated to the host #43
600.30: VM #434 has been allocated to the host #43
600.30: VM #435 has been allocated to the host #43
600.30: VM #436 has been allocated to the host #43
600.30: VM #437 has been allocated to the host #43
600.30: VM #438 has been allocated to the host #43
600.30: VM #439 has been allocated to the host #43
600.30: VM #440 has been allocated to the host #44
600.30: VM #441 has been allocated to the host #44
600.30: VM #442 has been allocated to the host #44
600.30: VM #443 has been allocated to the host #44
600.30: VM #444 has been allocated to the host #44
600.30: VM #445 has been allocated to the host #44
600.30: VM #446 has been allocated to the host #44
600.30: VM #447 has been allocated to the host #44
600.30: VM #448 has been allocated to the host #44
600.30: VM #449 has been allocated to the host #44
600.30: VM #450 has been allocated to the host #45
600.30: VM #451 has been allocated to the host #45
600.30: VM #452 has been allocated to the host #45
600.30: VM #453 has been allocated to the host #45
600.30: VM #454 has been allocated to the host #45
600.30: VM #455 has been allocated to the host #45
600.30: VM #456 has been allocated to the host #45
600.30: VM #457 has been allocated to the host #45
600.30: VM #458 has been allocated to the host #45
600.30: VM #459 has been allocated to the host #45
600.30: VM #460 has been allocated to the host #46
600.30: VM #461 has been allocated to the host #46
600.30: VM #462 has been allocated to the host #46
600.30: VM #463 has been allocated to the host #46
600.30: VM #464 has been allocated to the host #46
600.30: VM #465 has been allocated to the host #46
600.30: VM #466 has been allocated to the host #46
600.30: VM #467 has been allocated to the host #46
600.30: VM #468 has been allocated to the host #46
600.30: VM #469 has been allocated to the host #46
600.30: VM #470 has been allocated to the host #47
600.30: VM #471 has been allocated to the host #47
600.30: VM #472 has been allocated to the host #47
600.30: VM #473 has been allocated to the host #47
600.30: VM #474 has been allocated to the host #47
600.30: VM #475 has been allocated to the host #47
600.30: VM #476 has been allocated to the host #47
600.30: VM #477 has been allocated to the host #47
600.30: VM #478 has been allocated to the host #47
600.30: VM #479 has been allocated to the host #47
600.30: VM #480 has been allocated to the host #48
600.30: VM #481 has been allocated to the host #48
600.30: VM #482 has been allocated to the host #48
600.30: VM #483 has been allocated to the host #48
600.30: VM #484 has been allocated to the host #48
600.30: VM #485 has been allocated to the host #48
600.30: VM #486 has been allocated to the host #48
600.30: VM #487 has been allocated to the host #48
600.30: VM #488 has been allocated to the host #48
600.30: VM #489 has been allocated to the host #48
600.30: VM #490 has been allocated to the host #49
600.30: VM #491 has been allocated to the host #49
600.30: VM #492 has been allocated to the host #49
600.30: VM #493 has been allocated to the host #49
600.30: VM #494 has been allocated to the host #49
600.30: VM #495 has been allocated to the host #49
600.30: VM #496 has been allocated to the host #49
600.30: VM #497 has been allocated to the host #49
600.30: VM #498 has been allocated to the host #49
600.30: VM #499 has been allocated to the host #49
600.30: VM #500 has been allocated to the host #50
600.30: VM #501 has been allocated to the host #50
600.30: VM #502 has been allocated to the host #50
600.30: VM #503 has been allocated to the host #50
600.30: VM #504 has been allocated to the host #50
600.30: VM #505 has been allocated to the host #50
600.30: VM #506 has been allocated to the host #50
600.30: VM #507 has been allocated to the host #50
600.30: VM #508 has been allocated to the host #50
600.30: VM #509 has been allocated to the host #50
600.30: VM #510 has been allocated to the host #51
600.30: VM #511 has been allocated to the host #51
600.30: VM #512 has been allocated to the host #51
600.30: VM #513 has been allocated to the host #51
600.30: VM #514 has been allocated to the host #51
600.30: VM #515 has been allocated to the host #51
600.30: VM #516 has been allocated to the host #51
600.30: VM #517 has been allocated to the host #51
600.30: VM #518 has been allocated to the host #51
600.30: VM #519 has been allocated to the host #51
600.30: VM #520 has been allocated to the host #52
600.30: VM #521 has been allocated to the host #52
600.30: VM #522 has been allocated to the host #52
600.30: VM #523 has been allocated to the host #52
600.30: VM #524 has been allocated to the host #52
600.30: VM #525 has been allocated to the host #52
600.30: VM #526 has been allocated to the host #52
600.30: VM #527 has been allocated to the host #52
600.30: VM #528 has been allocated to the host #52
600.30: VM #529 has been allocated to the host #52
600.30: VM #530 has been allocated to the host #53
600.30: VM #531 has been allocated to the host #53
600.30: VM #532 has been allocated to the host #53
600.30: VM #533 has been allocated to the host #53
600.30: VM #534 has been allocated to the host #53
600.30: VM #535 has been allocated to the host #53
600.30: VM #536 has been allocated to the host #53
600.30: VM #537 has been allocated to the host #53
600.30: VM #538 has been allocated to the host #53
600.30: VM #539 has been allocated to the host #53
600.30: VM #540 has been allocated to the host #54
600.30: VM #541 has been allocated to the host #54
600.30: VM #542 has been allocated to the host #54
600.30: VM #543 has been allocated to the host #54
600.30: VM #544 has been allocated to the host #54
600.30: VM #545 has been allocated to the host #54
600.30: VM #546 has been allocated to the host #54
600.30: VM #547 has been allocated to the host #54
600.30: VM #548 has been allocated to the host #54
600.30: VM #549 has been allocated to the host #54
600.30: VM #550 has been allocated to the host #55
600.30: VM #551 has been allocated to the host #55
600.30: VM #552 has been allocated to the host #55
600.30: VM #553 has been allocated to the host #55
600.30: VM #554 has been allocated to the host #55
600.30: VM #555 has been allocated to the host #55
600.30: VM #556 has been allocated to the host #55
600.30: VM #557 has been allocated to the host #55
600.30: VM #558 has been allocated to the host #55
600.30: VM #559 has been allocated to the host #55
600.30: VM #560 has been allocated to the host #56
600.30: VM #561 has been allocated to the host #56
600.30: VM #562 has been allocated to the host #56
600.30: VM #563 has been allocated to the host #56
600.30: VM #564 has been allocated to the host #56
600.30: VM #565 has been allocated to the host #56
600.30: VM #566 has been allocated to the host #56
600.30: VM #567 has been allocated to the host #56
600.30: VM #568 has been allocated to the host #56
600.30: VM #569 has been allocated to the host #56
600.30: VM #570 has been allocated to the host #57
600.30: VM #571 has been allocated to the host #57
600.30: VM #572 has been allocated to the host #57
600.30: VM #573 has been allocated to the host #57
600.30: VM #574 has been allocated to the host #57
600.30: VM #575 has been allocated to the host #57
600.30: VM #576 has been allocated to the host #57
600.30: VM #577 has been allocated to the host #57
600.30: VM #578 has been allocated to the host #57
600.30: VM #579 has been allocated to the host #57
600.30: VM #580 has been allocated to the host #58
600.30: VM #581 has been allocated to the host #58
600.30: VM #582 has been allocated to the host #58
600.30: VM #583 has been allocated to the host #58
600.30: VM #584 has been allocated to the host #58
600.30: VM #585 has been allocated to the host #58
600.30: VM #586 has been allocated to the host #58
600.30: VM #587 has been allocated to the host #58
600.30: VM #588 has been allocated to the host #58
600.30: VM #589 has been allocated to the host #58
600.30: VM #590 has been allocated to the host #59
600.30: VM #591 has been allocated to the host #59
600.30: VM #592 has been allocated to the host #59
600.30: VM #593 has been allocated to the host #59
600.30: VM #594 has been allocated to the host #59
600.30: VM #595 has been allocated to the host #59
600.30: VM #596 has been allocated to the host #59
600.30: VM #597 has been allocated to the host #59
600.30: VM #598 has been allocated to the host #59
600.30: VM #599 has been allocated to the host #59
600.30: VM #600 has been allocated to the host #60
600.30: VM #601 has been allocated to the host #60
600.30: VM #602 has been allocated to the host #60
600.30: VM #603 has been allocated to the host #60
600.30: VM #604 has been allocated to the host #60
600.30: VM #605 has been allocated to the host #60
600.30: VM #606 has been allocated to the host #60
600.30: VM #607 has been allocated to the host #60
600.30: VM #608 has been allocated to the host #60
600.30: VM #609 has been allocated to the host #60
600.30: VM #610 has been allocated to the host #61
600.30: VM #611 has been allocated to the host #61
600.30: VM #612 has been allocated to the host #61
600.30: VM #613 has been allocated to the host #61
600.30: VM #614 has been allocated to the host #61
600.30: VM #615 has been allocated to the host #61
600.30: VM #616 has been allocated to the host #61
600.30: VM #617 has been allocated to the host #61
600.30: VM #618 has been allocated to the host #61
600.30: VM #619 has been allocated to the host #61
600.30: VM #620 has been allocated to the host #62
600.30: VM #621 has been allocated to the host #62
600.30: VM #622 has been allocated to the host #62
600.30: VM #623 has been allocated to the host #62
600.30: VM #624 has been allocated to the host #62
600.30: VM #625 has been allocated to the host #62
600.30: VM #626 has been allocated to the host #62
600.30: VM #627 has been allocated to the host #62
600.30: VM #628 has been allocated to the host #62
600.30: VM #629 has been allocated to the host #62
600.30: VM #630 has been allocated to the host #63
600.30: VM #631 has been allocated to the host #63
600.30: VM #632 has been allocated to the host #63
600.30: VM #633 has been allocated to the host #63
600.30: VM #634 has been allocated to the host #63
600.30: VM #635 has been allocated to the host #63
600.30: VM #636 has been allocated to the host #63
600.30: VM #637 has been allocated to the host #63
600.30: VM #638 has been allocated to the host #63
600.30: VM #639 has been allocated to the host #63
600.30: VM #640 has been allocated to the host #64
600.30: VM #641 has been allocated to the host #64
600.30: VM #642 has been allocated to the host #64
600.30: VM #643 has been allocated to the host #64
600.30: VM #644 has been allocated to the host #64
600.30: VM #645 has been allocated to the host #64
600.30: VM #646 has been allocated to the host #64
600.30: VM #647 has been allocated to the host #64
600.30: VM #648 has been allocated to the host #64
600.30: VM #649 has been allocated to the host #64
600.30: VM #650 has been allocated to the host #65
600.30: VM #651 has been allocated to the host #65
600.30: VM #652 has been allocated to the host #65
600.30: VM #653 has been allocated to the host #65
600.30: VM #654 has been allocated to the host #65
600.30: VM #655 has been allocated to the host #65
600.30: VM #656 has been allocated to the host #65
600.30: VM #657 has been allocated to the host #65
600.30: VM #658 has been allocated to the host #65
600.30: VM #659 has been allocated to the host #65
600.30: VM #660 has been allocated to the host #66
600.30: VM #661 has been allocated to the host #66
600.30: VM #662 has been allocated to the host #66
600.30: VM #663 has been allocated to the host #66
600.30: VM #664 has been allocated to the host #66
600.30: VM #665 has been allocated to the host #66
600.30: VM #666 has been allocated to the host #66
600.30: VM #667 has been allocated to the host #66
600.30: VM #668 has been allocated to the host #66
600.30: VM #669 has been allocated to the host #66
600.30: VM #670 has been allocated to the host #67
600.30: VM #671 has been allocated to the host #67
600.30: VM #672 has been allocated to the host #67
600.30: VM #673 has been allocated to the host #67
600.30: VM #674 has been allocated to the host #67
600.30: VM #675 has been allocated to the host #67
600.30: VM #676 has been allocated to the host #67
600.30: VM #677 has been allocated to the host #67
600.30: VM #678 has been allocated to the host #67
600.30: VM #679 has been allocated to the host #67
600.30: VM #680 has been allocated to the host #68
600.30: VM #681 has been allocated to the host #68
600.30: VM #682 has been allocated to the host #68
600.30: VM #683 has been allocated to the host #68
600.30: VM #684 has been allocated to the host #68
600.30: VM #685 has been allocated to the host #68
600.30: VM #686 has been allocated to the host #68
600.30: VM #687 has been allocated to the host #68
600.30: VM #688 has been allocated to the host #68
600.30: VM #689 has been allocated to the host #68
600.30: VM #690 has been allocated to the host #69
600.30: VM #691 has been allocated to the host #69
600.30: VM #692 has been allocated to the host #69
600.30: VM #693 has been allocated to the host #69
600.30: VM #694 has been allocated to the host #69
600.30: VM #695 has been allocated to the host #69
600.30: VM #696 has been allocated to the host #69
600.30: VM #697 has been allocated to the host #69
600.30: VM #698 has been allocated to the host #69
600.30: VM #699 has been allocated to the host #69
600.30: VM #700 has been allocated to the host #70
600.30: VM #701 has been allocated to the host #70
600.30: VM #702 has been allocated to the host #70
600.30: VM #703 has been allocated to the host #70
600.30: VM #704 has been allocated to the host #70
600.30: VM #705 has been allocated to the host #70
600.30: VM #706 has been allocated to the host #70
600.30: VM #707 has been allocated to the host #70
600.30: VM #708 has been allocated to the host #70
600.30: VM #709 has been allocated to the host #70
600.30: VM #710 has been allocated to the host #71
600.30: VM #711 has been allocated to the host #71
600.30: VM #712 has been allocated to the host #71
600.30: VM #713 has been allocated to the host #71
600.30: VM #714 has been allocated to the host #71
600.30: VM #715 has been allocated to the host #71
600.30: VM #716 has been allocated to the host #71
600.30: VM #717 has been allocated to the host #71
600.30: VM #718 has been allocated to the host #71
600.30: VM #719 has been allocated to the host #71
600.30: VM #720 has been allocated to the host #72
600.30: VM #721 has been allocated to the host #72
600.30: VM #722 has been allocated to the host #72
600.30: VM #723 has been allocated to the host #72
600.30: VM #724 has been allocated to the host #72
600.30: VM #725 has been allocated to the host #72
600.30: VM #726 has been allocated to the host #72
600.30: VM #727 has been allocated to the host #72
600.30: VM #728 has been allocated to the host #72
600.30: VM #729 has been allocated to the host #72
600.30: VM #730 has been allocated to the host #73
600.30: VM #731 has been allocated to the host #73
600.30: VM #732 has been allocated to the host #73
600.30: VM #733 has been allocated to the host #73
600.30: VM #734 has been allocated to the host #73
600.30: VM #735 has been allocated to the host #73
600.30: VM #736 has been allocated to the host #73
600.30: VM #737 has been allocated to the host #73
600.30: VM #738 has been allocated to the host #73
600.30: VM #739 has been allocated to the host #73
600.30: VM #740 has been allocated to the host #74
600.30: VM #741 has been allocated to the host #74
600.30: VM #742 has been allocated to the host #74
600.30: VM #743 has been allocated to the host #74
600.30: VM #744 has been allocated to the host #74
600.30: VM #745 has been allocated to the host #74
600.30: VM #746 has been allocated to the host #74
600.30: VM #747 has been allocated to the host #74
600.30: VM #748 has been allocated to the host #74
600.30: VM #749 has been allocated to the host #74
600.30: VM #750 has been allocated to the host #75
600.30: VM #751 has been allocated to the host #75
600.30: VM #752 has been allocated to the host #75
600.30: VM #753 has been allocated to the host #75
600.30: VM #754 has been allocated to the host #75
600.30: VM #755 has been allocated to the host #75
600.30: VM #756 has been allocated to the host #75
600.30: VM #757 has been allocated to the host #75
600.30: VM #758 has been allocated to the host #75
600.30: VM #759 has been allocated to the host #75
600.30: VM #760 has been allocated to the host #76
600.30: VM #761 has been allocated to the host #76
600.30: VM #762 has been allocated to the host #76
600.30: VM #763 has been allocated to the host #76
600.30: VM #764 has been allocated to the host #76
600.30: VM #765 has been allocated to the host #76
600.30: VM #766 has been allocated to the host #76
600.30: VM #767 has been allocated to the host #76
600.30: VM #768 has been allocated to the host #76
600.30: VM #769 has been allocated to the host #76
600.30: VM #770 has been allocated to the host #77
600.30: VM #771 has been allocated to the host #77
600.30: VM #772 has been allocated to the host #77
600.30: VM #773 has been allocated to the host #77
600.30: VM #774 has been allocated to the host #77
600.30: VM #775 has been allocated to the host #77
600.30: VM #776 has been allocated to the host #77
600.30: VM #777 has been allocated to the host #77
600.30: VM #778 has been allocated to the host #77
600.30: VM #779 has been allocated to the host #77
600.30: VM #780 has been allocated to the host #78
600.30: VM #781 has been allocated to the host #78
600.30: VM #782 has been allocated to the host #78
600.30: VM #783 has been allocated to the host #78
600.30: VM #784 has been allocated to the host #78
600.30: VM #785 has been allocated to the host #78
600.30: VM #786 has been allocated to the host #78
600.30: VM #787 has been allocated to the host #78
600.30: VM #788 has been allocated to the host #78
600.30: VM #789 has been allocated to the host #78
600.30: VM #790 has been allocated to the host #79
600.30: VM #791 has been allocated to the host #79
600.30: VM #792 has been allocated to the host #79
600.30: VM #793 has been allocated to the host #79
600.30: VM #794 has been allocated to the host #79
600.30: VM #795 has been allocated to the host #79
600.30: VM #796 has been allocated to the host #79
600.30: VM #797 has been allocated to the host #79
600.30: VM #798 has been allocated to the host #79
600.30: VM #799 has been allocated to the host #79
600.30: VM #800 has been allocated to the host #80
600.30: VM #801 has been allocated to the host #80
600.30: VM #802 has been allocated to the host #80
600.30: VM #803 has been allocated to the host #80
600.30: VM #804 has been allocated to the host #80
600.30: VM #805 has been allocated to the host #80
600.30: VM #806 has been allocated to the host #80
600.30: VM #807 has been allocated to the host #80
600.30: VM #808 has been allocated to the host #80
600.30: VM #809 has been allocated to the host #80
600.30: VM #810 has been allocated to the host #81
600.30: VM #811 has been allocated to the host #81
600.30: VM #812 has been allocated to the host #81
600.30: VM #813 has been allocated to the host #81
600.30: VM #814 has been allocated to the host #81
600.30: VM #815 has been allocated to the host #81
600.30: VM #816 has been allocated to the host #81
600.30: VM #817 has been allocated to the host #81
600.30: VM #818 has been allocated to the host #81
600.30: VM #819 has been allocated to the host #81
600.30: VM #820 has been allocated to the host #82
600.30: VM #821 has been allocated to the host #82
600.30: VM #822 has been allocated to the host #82
600.30: VM #823 has been allocated to the host #82
600.30: VM #824 has been allocated to the host #82
600.30: VM #825 has been allocated to the host #82
600.30: VM #826 has been allocated to the host #82
600.30: VM #827 has been allocated to the host #82
600.30: VM #828 has been allocated to the host #82
600.30: VM #829 has been allocated to the host #82
600.30: VM #830 has been allocated to the host #83
600.30: VM #831 has been allocated to the host #83
600.30: VM #832 has been allocated to the host #83
600.30: VM #833 has been allocated to the host #83
600.30: VM #834 has been allocated to the host #83
600.30: VM #835 has been allocated to the host #83
600.30: VM #836 has been allocated to the host #83
600.30: VM #837 has been allocated to the host #83
600.30: VM #838 has been allocated to the host #83
600.30: VM #839 has been allocated to the host #83
600.30: VM #840 has been allocated to the host #84
600.30: VM #841 has been allocated to the host #84
600.30: VM #842 has been allocated to the host #84
600.30: VM #843 has been allocated to the host #84
600.30: VM #844 has been allocated to the host #84
600.30: VM #845 has been allocated to the host #84
600.30: VM #846 has been allocated to the host #84
600.30: VM #847 has been allocated to the host #84
600.30: VM #848 has been allocated to the host #84
600.30: VM #849 has been allocated to the host #84
600.30: VM #850 has been allocated to the host #85
600.30: VM #851 has been allocated to the host #85
600.30: VM #852 has been allocated to the host #85
600.30: VM #853 has been allocated to the host #85
600.30: VM #854 has been allocated to the host #85
600.30: VM #855 has been allocated to the host #85
600.30: VM #856 has been allocated to the host #85
600.30: VM #857 has been allocated to the host #85
600.30: VM #858 has been allocated to the host #85
600.30: VM #859 has been allocated to the host #85
600.30: VM #860 has been allocated to the host #86
600.30: VM #861 has been allocated to the host #86
600.30: VM #862 has been allocated to the host #86
600.30: VM #863 has been allocated to the host #86
