Initialising...
Starting CloudSim version 3.0
GlobalBroker is starting...
Datacenter is starting...
Entities started.
Adding: broker_0
broker_0 is starting...
600.3: broker_0: Cloud Resource List received with 1 resource(s)
600.3: broker_0: Trying to Create VM #0 in Datacenter
600.3: broker_0: Trying to Create VM #1 in Datacenter
600.3: broker_0: Trying to Create VM #2 in Datacenter
600.3: broker_0: Trying to Create VM #3 in Datacenter
600.3: broker_0: Trying to Create VM #4 in Datacenter
600.3: broker_0: Trying to Create VM #5 in Datacenter
600.3: broker_0: Trying to Create VM #6 in Datacenter
600.30: VM #0 has been allocated to the host #0
600.30: VM #1 has been allocated to the host #7
600.30: VM #2 has been allocated to the host #45
600.30: VM #3 has been allocated to the host #56
600.30: VM #4 has been allocated to the host #18
600.30: VM #5 has been allocated to the host #4
600.30: VM #6 has been allocated to the host #22
600.4: broker_0: VM #0 has been created in Datacenter #3, Host #0
600.4: broker_0: VM #1 has been created in Datacenter #3, Host #7
600.4: broker_0: VM #2 has been created in Datacenter #3, Host #45
600.4: broker_0: VM #3 has been created in Datacenter #3, Host #56
600.4: broker_0: VM #4 has been created in Datacenter #3, Host #18
600.4: broker_0: VM #5 has been created in Datacenter #3, Host #4
600.4: broker_0: VM #6 has been created in Datacenter #3, Host #22
600.4: broker_0: Sending cloudlet 0 to VM #0
600.4: broker_0: Sending cloudlet 1 to VM #1
600.4: broker_0: Sending cloudlet 2 to VM #2
600.4: broker_0: Sending cloudlet 3 to VM #3
600.4: broker_0: Sending cloudlet 4 to VM #4
600.4: broker_0: Sending cloudlet 5 to VM #5
600.4: broker_0: Sending cloudlet 6 to VM #6


--------------------------------------------------------------


New resource usage for the time frame starting at 900.40:


--------------------------------------------------------------


New resource usage for the time frame starting at 1200.40:
Adding: broker_1
broker_1 is starting...
1200.6: broker_1: Cloud Resource List received with 1 resource(s)
1200.6: broker_1: Trying to Create VM #7 in Datacenter
1200.6: broker_1: Trying to Create VM #8 in Datacenter
1200.6: broker_1: Trying to Create VM #9 in Datacenter
1200.6: broker_1: Trying to Create VM #10 in Datacenter
1200.6: broker_1: Trying to Create VM #11 in Datacenter
1200.6: broker_1: Trying to Create VM #12 in Datacenter
1200.6: broker_1: Trying to Create VM #13 in Datacenter
1200.6: broker_1: Trying to Create VM #14 in Datacenter
1200.6: broker_1: Trying to Create VM #15 in Datacenter
1200.6: broker_1: Trying to Create VM #16 in Datacenter
1200.6: broker_1: Trying to Create VM #17 in Datacenter
1200.60: VM #7 has been allocated to the host #18
1200.60: VM #8 has been allocated to the host #18
1200.60: VM #9 has been allocated to the host #13
1200.60: VM #10 has been allocated to the host #2
1200.60: VM #11 has been allocated to the host #42
1200.60: VM #12 has been allocated to the host #2
1200.60: VM #13 has been allocated to the host #2
1200.60: VM #14 has been allocated to the host #2
1200.60: VM #15 has been allocated to the host #2
1200.60: VM #16 has been allocated to the host #2
1200.60: VM #17 has been allocated to the host #18
1200.6999999999998: broker_1: VM #7 has been created in Datacenter #3, Host #18
1200.6999999999998: broker_1: VM #8 has been created in Datacenter #3, Host #18
1200.6999999999998: broker_1: VM #9 has been created in Datacenter #3, Host #13
1200.6999999999998: broker_1: VM #10 has been created in Datacenter #3, Host #2
1200.6999999999998: broker_1: VM #11 has been created in Datacenter #3, Host #42
1200.6999999999998: broker_1: VM #12 has been created in Datacenter #3, Host #2
1200.6999999999998: broker_1: VM #13 has been created in Datacenter #3, Host #2
1200.6999999999998: broker_1: VM #14 has been created in Datacenter #3, Host #2
1200.6999999999998: broker_1: VM #15 has been created in Datacenter #3, Host #2
1200.6999999999998: broker_1: VM #16 has been created in Datacenter #3, Host #2
1200.6999999999998: broker_1: VM #17 has been created in Datacenter #3, Host #18
1200.6999999999998: broker_1: Sending cloudlet 7 to VM #7
1200.6999999999998: broker_1: Sending cloudlet 8 to VM #8
1200.6999999999998: broker_1: Sending cloudlet 9 to VM #9
1200.6999999999998: broker_1: Sending cloudlet 10 to VM #10
1200.6999999999998: broker_1: Sending cloudlet 11 to VM #11
1200.6999999999998: broker_1: Sending cloudlet 12 to VM #12
1200.6999999999998: broker_1: Sending cloudlet 13 to VM #13
1200.6999999999998: broker_1: Sending cloudlet 14 to VM #14
1200.6999999999998: broker_1: Sending cloudlet 15 to VM #15
1200.6999999999998: broker_1: Sending cloudlet 16 to VM #16
1200.6999999999998: broker_1: Sending cloudlet 17 to VM #17


--------------------------------------------------------------


New resource usage for the time frame starting at 1500.70:


--------------------------------------------------------------


New resource usage for the time frame starting at 1800.70:
Adding: broker_2
broker_2 is starting...
1800.8999999999999: broker_2: Cloud Resource List received with 1 resource(s)
1800.8999999999999: broker_2: Trying to Create VM #18 in Datacenter
1800.8999999999999: broker_2: Trying to Create VM #19 in Datacenter
1800.8999999999999: broker_2: Trying to Create VM #20 in Datacenter
1800.8999999999999: broker_2: Trying to Create VM #21 in Datacenter
1800.8999999999999: broker_2: Trying to Create VM #22 in Datacenter
1800.8999999999999: broker_2: Trying to Create VM #23 in Datacenter
1800.8999999999999: broker_2: Trying to Create VM #24 in Datacenter
1800.8999999999999: broker_2: Trying to Create VM #25 in Datacenter
1800.8999999999999: broker_2: Trying to Create VM #26 in Datacenter
1800.90: VM #18 has been allocated to the host #18
1800.90: VM #19 has been allocated to the host #18
1800.90: VM #20 has been allocated to the host #18
1800.90: VM #21 has been allocated to the host #18
1800.90: VM #22 has been allocated to the host #18
1800.90: VM #23 has been allocated to the host #18
1800.90: VM #24 has been allocated to the host #32
1800.90: VM #25 has been allocated to the host #0
1800.90: VM #26 has been allocated to the host #4
1800.9999999999998: broker_2: VM #18 has been created in Datacenter #3, Host #18
1800.9999999999998: broker_2: VM #19 has been created in Datacenter #3, Host #18
1800.9999999999998: broker_2: VM #20 has been created in Datacenter #3, Host #18
1800.9999999999998: broker_2: VM #21 has been created in Datacenter #3, Host #18
1800.9999999999998: broker_2: VM #22 has been created in Datacenter #3, Host #18
1800.9999999999998: broker_2: VM #23 has been created in Datacenter #3, Host #18
1800.9999999999998: broker_2: VM #24 has been created in Datacenter #3, Host #32
1800.9999999999998: broker_2: VM #25 has been created in Datacenter #3, Host #0
1800.9999999999998: broker_2: VM #26 has been created in Datacenter #3, Host #4
1800.9999999999998: broker_2: Sending cloudlet 18 to VM #18
1800.9999999999998: broker_2: Sending cloudlet 19 to VM #19
1800.9999999999998: broker_2: Sending cloudlet 20 to VM #20
1800.9999999999998: broker_2: Sending cloudlet 21 to VM #21
1800.9999999999998: broker_2: Sending cloudlet 22 to VM #22
1800.9999999999998: broker_2: Sending cloudlet 23 to VM #23
1800.9999999999998: broker_2: Sending cloudlet 24 to VM #24
1800.9999999999998: broker_2: Sending cloudlet 25 to VM #25
1800.9999999999998: broker_2: Sending cloudlet 26 to VM #26


--------------------------------------------------------------


New resource usage for the time frame starting at 2101.00:


--------------------------------------------------------------


New resource usage for the time frame starting at 2401.00:
Adding: broker_3
broker_3 is starting...
2401.2: broker_3: Cloud Resource List received with 1 resource(s)


--------------------------------------------------------------


New resource usage for the time frame starting at 2701.00:


--------------------------------------------------------------


New resource usage for the time frame starting at 3001.00:
Adding: broker_4
broker_4 is starting...
3001.5: broker_4: Cloud Resource List received with 1 resource(s)
3001.5: broker_4: Trying to Create VM #27 in Datacenter
3001.5: broker_4: Trying to Create VM #28 in Datacenter
3001.5: broker_4: Trying to Create VM #29 in Datacenter
3001.5: broker_4: Trying to Create VM #30 in Datacenter
3001.5: broker_4: Trying to Create VM #31 in Datacenter
3001.5: broker_4: Trying to Create VM #32 in Datacenter
3001.5: broker_4: Trying to Create VM #33 in Datacenter
3001.5: broker_4: Trying to Create VM #34 in Datacenter
3001.5: broker_4: Trying to Create VM #35 in Datacenter
3001.5: broker_4: Trying to Create VM #36 in Datacenter
3001.5: broker_4: Trying to Create VM #37 in Datacenter
3001.50: VM #27 has been allocated to the host #0
3001.50: VM #28 has been allocated to the host #94
3001.50: VM #29 has been allocated to the host #83
3001.50: VM #30 has been allocated to the host #83
3001.50: VM #31 has been allocated to the host #83
3001.50: VM #32 has been allocated to the host #83
3001.50: VM #33 has been allocated to the host #83
3001.50: VM #34 has been allocated to the host #83
3001.50: VM #35 has been allocated to the host #83
3001.50: VM #36 has been allocated to the host #83
3001.50: VM #37 has been allocated to the host #83
3001.6: broker_4: VM #27 has been created in Datacenter #3, Host #0
3001.6: broker_4: VM #28 has been created in Datacenter #3, Host #94
3001.6: broker_4: VM #29 has been created in Datacenter #3, Host #83
3001.6: broker_4: VM #30 has been created in Datacenter #3, Host #83
3001.6: broker_4: VM #31 has been created in Datacenter #3, Host #83
3001.6: broker_4: VM #32 has been created in Datacenter #3, Host #83
3001.6: broker_4: VM #33 has been created in Datacenter #3, Host #83
3001.6: broker_4: VM #34 has been created in Datacenter #3, Host #83
3001.6: broker_4: VM #35 has been created in Datacenter #3, Host #83
3001.6: broker_4: VM #36 has been created in Datacenter #3, Host #83
3001.6: broker_4: VM #37 has been created in Datacenter #3, Host #83
3001.6: broker_4: Sending cloudlet 27 to VM #27
3001.6: broker_4: Sending cloudlet 28 to VM #28
3001.6: broker_4: Sending cloudlet 29 to VM #29
3001.6: broker_4: Sending cloudlet 30 to VM #30
3001.6: broker_4: Sending cloudlet 31 to VM #31
3001.6: broker_4: Sending cloudlet 32 to VM #32
3001.6: broker_4: Sending cloudlet 33 to VM #33
3001.6: broker_4: Sending cloudlet 34 to VM #34
3001.6: broker_4: Sending cloudlet 35 to VM #35
3001.6: broker_4: Sending cloudlet 36 to VM #36
3001.6: broker_4: Sending cloudlet 37 to VM #37


--------------------------------------------------------------


New resource usage for the time frame starting at 3301.60:


--------------------------------------------------------------


New resource usage for the time frame starting at 3601.60:
Adding: broker_5
broker_5 is starting...
3601.8: broker_5: Cloud Resource List received with 1 resource(s)
3601.8: broker_5: Trying to Create VM #38 in Datacenter
3601.8: broker_5: Trying to Create VM #39 in Datacenter
3601.8: broker_5: Trying to Create VM #40 in Datacenter
3601.8: broker_5: Trying to Create VM #41 in Datacenter
3601.8: broker_5: Trying to Create VM #42 in Datacenter
3601.8: broker_5: Trying to Create VM #43 in Datacenter
3601.8: broker_5: Trying to Create VM #44 in Datacenter
3601.8: broker_5: Trying to Create VM #45 in Datacenter
3601.8: broker_5: Trying to Create VM #46 in Datacenter
3601.8: broker_5: Trying to Create VM #47 in Datacenter
3601.8: broker_5: Trying to Create VM #48 in Datacenter
3601.8: broker_5: Trying to Create VM #49 in Datacenter
3601.8: broker_5: Trying to Create VM #50 in Datacenter
3601.8: broker_5: Trying to Create VM #51 in Datacenter
3601.8: broker_5: Trying to Create VM #52 in Datacenter
3601.8: broker_5: Trying to Create VM #53 in Datacenter
3601.8: broker_5: Trying to Create VM #54 in Datacenter
3601.80: VM #38 has been allocated to the host #83
3601.80: VM #39 has been allocated to the host #4
3601.80: VM #40 has been allocated to the host #0
3601.80: VM #41 has been allocated to the host #7
3601.80: VM #42 has been allocated to the host #13
3601.80: VM #43 has been allocated to the host #37
3601.80: VM #44 has been allocated to the host #22
3601.80: VM #45 has been allocated to the host #32
3601.80: VM #46 has been allocated to the host #42
3601.80: VM #47 has been allocated to the host #45
3601.80: VM #48 has been allocated to the host #44
3601.80: VM #49 has been allocated to the host #17
3601.80: VM #50 has been allocated to the host #26
3601.80: VM #51 has been allocated to the host #56
3601.80: VM #52 has been allocated to the host #94
3601.80: VM #53 has been allocated to the host #86
3601.80: VM #54 has been allocated to the host #84
3601.9: broker_5: VM #38 has been created in Datacenter #3, Host #83
3601.9: broker_5: VM #39 has been created in Datacenter #3, Host #4
3601.9: broker_5: VM #40 has been created in Datacenter #3, Host #0
3601.9: broker_5: VM #41 has been created in Datacenter #3, Host #7
3601.9: broker_5: VM #42 has been created in Datacenter #3, Host #13
3601.9: broker_5: VM #43 has been created in Datacenter #3, Host #37
3601.9: broker_5: VM #44 has been created in Datacenter #3, Host #22
3601.9: broker_5: VM #45 has been created in Datacenter #3, Host #32
3601.9: broker_5: VM #46 has been created in Datacenter #3, Host #42
3601.9: broker_5: VM #47 has been created in Datacenter #3, Host #45
3601.9: broker_5: VM #48 has been created in Datacenter #3, Host #44
3601.9: broker_5: VM #49 has been created in Datacenter #3, Host #17
3601.9: broker_5: VM #50 has been created in Datacenter #3, Host #26
3601.9: broker_5: VM #51 has been created in Datacenter #3, Host #56
3601.9: broker_5: VM #52 has been created in Datacenter #3, Host #94
3601.9: broker_5: VM #53 has been created in Datacenter #3, Host #86
3601.9: broker_5: VM #54 has been created in Datacenter #3, Host #84
3601.9: broker_5: Sending cloudlet 38 to VM #38
3601.9: broker_5: Sending cloudlet 39 to VM #39
3601.9: broker_5: Sending cloudlet 40 to VM #40
3601.9: broker_5: Sending cloudlet 41 to VM #41
3601.9: broker_5: Sending cloudlet 42 to VM #42
3601.9: broker_5: Sending cloudlet 43 to VM #43
3601.9: broker_5: Sending cloudlet 44 to VM #44
3601.9: broker_5: Sending cloudlet 45 to VM #45
3601.9: broker_5: Sending cloudlet 46 to VM #46
3601.9: broker_5: Sending cloudlet 47 to VM #47
3601.9: broker_5: Sending cloudlet 48 to VM #48
3601.9: broker_5: Sending cloudlet 49 to VM #49
3601.9: broker_5: Sending cloudlet 50 to VM #50
3601.9: broker_5: Sending cloudlet 51 to VM #51
3601.9: broker_5: Sending cloudlet 52 to VM #52
3601.9: broker_5: Sending cloudlet 53 to VM #53
3601.9: broker_5: Sending cloudlet 54 to VM #54


--------------------------------------------------------------


New resource usage for the time frame starting at 3901.90:


--------------------------------------------------------------


New resource usage for the time frame starting at 4201.90:
Adding: broker_6
broker_6 is starting...
4202.1: broker_6: Cloud Resource List received with 1 resource(s)
4202.1: broker_6: Trying to Create VM #55 in Datacenter
4202.1: broker_6: Trying to Create VM #56 in Datacenter
4202.1: broker_6: Trying to Create VM #57 in Datacenter
4202.1: broker_6: Trying to Create VM #58 in Datacenter
4202.1: broker_6: Trying to Create VM #59 in Datacenter
4202.1: broker_6: Trying to Create VM #60 in Datacenter
4202.1: broker_6: Trying to Create VM #61 in Datacenter
4202.1: broker_6: Trying to Create VM #62 in Datacenter
4202.1: broker_6: Trying to Create VM #63 in Datacenter
4202.1: broker_6: Trying to Create VM #64 in Datacenter
4202.1: broker_6: Trying to Create VM #65 in Datacenter
4202.1: broker_6: Trying to Create VM #66 in Datacenter
4202.1: broker_6: Trying to Create VM #67 in Datacenter
4202.1: broker_6: Trying to Create VM #68 in Datacenter
4202.1: broker_6: Trying to Create VM #69 in Datacenter
4202.1: broker_6: Trying to Create VM #70 in Datacenter
4202.1: broker_6: Trying to Create VM #71 in Datacenter
4202.10: VM #55 has been allocated to the host #84
4202.10: VM #56 has been allocated to the host #84
4202.10: VM #57 has been allocated to the host #84
4202.10: VM #58 has been allocated to the host #84
4202.10: VM #59 has been allocated to the host #84
4202.10: VM #60 has been allocated to the host #84
4202.10: VM #61 has been allocated to the host #84
4202.10: VM #62 has been allocated to the host #11
4202.10: VM #63 has been allocated to the host #11
4202.10: VM #64 has been allocated to the host #11
4202.10: VM #65 has been allocated to the host #11
4202.10: VM #66 has been allocated to the host #0
4202.10: VM #67 has been allocated to the host #11
4202.10: VM #68 has been allocated to the host #46
4202.10: VM #69 has been allocated to the host #11
4202.10: VM #70 has been allocated to the host #0
4202.10: VM #71 has been allocated to the host #7
4202.200000000001: broker_6: VM #55 has been created in Datacenter #3, Host #84
4202.200000000001: broker_6: VM #56 has been created in Datacenter #3, Host #84
4202.200000000001: broker_6: VM #57 has been created in Datacenter #3, Host #84
4202.200000000001: broker_6: VM #58 has been created in Datacenter #3, Host #84
4202.200000000001: broker_6: VM #59 has been created in Datacenter #3, Host #84
4202.200000000001: broker_6: VM #60 has been created in Datacenter #3, Host #84
4202.200000000001: broker_6: VM #61 has been created in Datacenter #3, Host #84
4202.200000000001: broker_6: VM #62 has been created in Datacenter #3, Host #11
4202.200000000001: broker_6: VM #63 has been created in Datacenter #3, Host #11
4202.200000000001: broker_6: VM #64 has been created in Datacenter #3, Host #11
4202.200000000001: broker_6: VM #65 has been created in Datacenter #3, Host #11
4202.200000000001: broker_6: VM #66 has been created in Datacenter #3, Host #0
4202.200000000001: broker_6: VM #67 has been created in Datacenter #3, Host #11
4202.200000000001: broker_6: VM #68 has been created in Datacenter #3, Host #46
4202.200000000001: broker_6: VM #69 has been created in Datacenter #3, Host #11
4202.200000000001: broker_6: VM #70 has been created in Datacenter #3, Host #0
4202.200000000001: broker_6: VM #71 has been created in Datacenter #3, Host #7
4202.200000000001: broker_6: Sending cloudlet 55 to VM #55
4202.200000000001: broker_6: Sending cloudlet 56 to VM #56
4202.200000000001: broker_6: Sending cloudlet 57 to VM #57
4202.200000000001: broker_6: Sending cloudlet 58 to VM #58
4202.200000000001: broker_6: Sending cloudlet 59 to VM #59
4202.200000000001: broker_6: Sending cloudlet 60 to VM #60
4202.200000000001: broker_6: Sending cloudlet 61 to VM #61
4202.200000000001: broker_6: Sending cloudlet 62 to VM #62
4202.200000000001: broker_6: Sending cloudlet 63 to VM #63
4202.200000000001: broker_6: Sending cloudlet 64 to VM #64
4202.200000000001: broker_6: Sending cloudlet 65 to VM #65
4202.200000000001: broker_6: Sending cloudlet 66 to VM #66
4202.200000000001: broker_6: Sending cloudlet 67 to VM #67
4202.200000000001: broker_6: Sending cloudlet 68 to VM #68
4202.200000000001: broker_6: Sending cloudlet 69 to VM #69
4202.200000000001: broker_6: Sending cloudlet 70 to VM #70
4202.200000000001: broker_6: Sending cloudlet 71 to VM #71


--------------------------------------------------------------


New resource usage for the time frame starting at 4502.20:


--------------------------------------------------------------


New resource usage for the time frame starting at 4802.20:
Adding: broker_7
broker_7 is starting...
4802.400000000001: broker_7: Cloud Resource List received with 1 resource(s)
4802.400000000001: broker_7: Trying to Create VM #72 in Datacenter
4802.400000000001: broker_7: Trying to Create VM #73 in Datacenter
4802.400000000001: broker_7: Trying to Create VM #74 in Datacenter
4802.400000000001: broker_7: Trying to Create VM #75 in Datacenter
4802.400000000001: broker_7: Trying to Create VM #76 in Datacenter
4802.400000000001: broker_7: Trying to Create VM #77 in Datacenter
4802.400000000001: broker_7: Trying to Create VM #78 in Datacenter
4802.40: VM #72 has been allocated to the host #84
4802.40: VM #73 has been allocated to the host #13
4802.40: VM #74 has been allocated to the host #22
4802.40: VM #75 has been allocated to the host #6
4802.40: VM #76 has been allocated to the host #6
4802.40: VM #77 has been allocated to the host #88
4802.40: VM #78 has been allocated to the host #49
4802.500000000001: broker_7: VM #72 has been created in Datacenter #3, Host #84
4802.500000000001: broker_7: VM #73 has been created in Datacenter #3, Host #13
4802.500000000001: broker_7: VM #74 has been created in Datacenter #3, Host #22
4802.500000000001: broker_7: VM #75 has been created in Datacenter #3, Host #6
4802.500000000001: broker_7: VM #76 has been created in Datacenter #3, Host #6
4802.500000000001: broker_7: VM #77 has been created in Datacenter #3, Host #88
4802.500000000001: broker_7: VM #78 has been created in Datacenter #3, Host #49
4802.500000000001: broker_7: Sending cloudlet 72 to VM #72
4802.500000000001: broker_7: Sending cloudlet 73 to VM #73
4802.500000000001: broker_7: Sending cloudlet 74 to VM #74
4802.500000000001: broker_7: Sending cloudlet 75 to VM #75
4802.500000000001: broker_7: Sending cloudlet 76 to VM #76
4802.500000000001: broker_7: Sending cloudlet 77 to VM #77
4802.500000000001: broker_7: Sending cloudlet 78 to VM #78


--------------------------------------------------------------


New resource usage for the time frame starting at 5102.50:


--------------------------------------------------------------


New resource usage for the time frame starting at 5402.50:
Adding: broker_8
broker_8 is starting...
5402.700000000001: broker_8: Cloud Resource List received with 1 resource(s)
5402.700000000001: broker_8: Trying to Create VM #79 in Datacenter
5402.700000000001: broker_8: Trying to Create VM #80 in Datacenter
5402.700000000001: broker_8: Trying to Create VM #81 in Datacenter
5402.700000000001: broker_8: Trying to Create VM #82 in Datacenter
5402.700000000001: broker_8: Trying to Create VM #83 in Datacenter
5402.700000000001: broker_8: Trying to Create VM #84 in Datacenter
5402.700000000001: broker_8: Trying to Create VM #85 in Datacenter
5402.700000000001: broker_8: Trying to Create VM #86 in Datacenter
5402.700000000001: broker_8: Trying to Create VM #87 in Datacenter
5402.700000000001: broker_8: Trying to Create VM #88 in Datacenter
5402.700000000001: broker_8: Trying to Create VM #89 in Datacenter
5402.70: VM #79 has been allocated to the host #49
5402.70: VM #80 has been allocated to the host #49
5402.70: VM #81 has been allocated to the host #60
5402.70: VM #82 has been allocated to the host #60
5402.70: VM #83 has been allocated to the host #55
5402.70: VM #84 has been allocated to the host #0
5402.70: VM #85 has been allocated to the host #24
5402.70: VM #86 has been allocated to the host #60
5402.70: VM #87 has been allocated to the host #67
5402.70: VM #88 has been allocated to the host #58
5402.70: VM #89 has been allocated to the host #60
5402.800000000001: broker_8: VM #79 has been created in Datacenter #3, Host #49
5402.800000000001: broker_8: VM #80 has been created in Datacenter #3, Host #49
5402.800000000001: broker_8: VM #81 has been created in Datacenter #3, Host #60
5402.800000000001: broker_8: VM #82 has been created in Datacenter #3, Host #60
5402.800000000001: broker_8: VM #83 has been created in Datacenter #3, Host #55
5402.800000000001: broker_8: VM #84 has been created in Datacenter #3, Host #0
5402.800000000001: broker_8: VM #85 has been created in Datacenter #3, Host #24
5402.800000000001: broker_8: VM #86 has been created in Datacenter #3, Host #60
5402.800000000001: broker_8: VM #87 has been created in Datacenter #3, Host #67
5402.800000000001: broker_8: VM #88 has been created in Datacenter #3, Host #58
5402.800000000001: broker_8: VM #89 has been created in Datacenter #3, Host #60
5402.800000000001: broker_8: Sending cloudlet 79 to VM #79
5402.800000000001: broker_8: Sending cloudlet 80 to VM #80
5402.800000000001: broker_8: Sending cloudlet 81 to VM #81
5402.800000000001: broker_8: Sending cloudlet 82 to VM #82
5402.800000000001: broker_8: Sending cloudlet 83 to VM #83
5402.800000000001: broker_8: Sending cloudlet 84 to VM #84
5402.800000000001: broker_8: Sending cloudlet 85 to VM #85
5402.800000000001: broker_8: Sending cloudlet 86 to VM #86
5402.800000000001: broker_8: Sending cloudlet 87 to VM #87
5402.800000000001: broker_8: Sending cloudlet 88 to VM #88
5402.800000000001: broker_8: Sending cloudlet 89 to VM #89


--------------------------------------------------------------


New resource usage for the time frame starting at 5702.80:


--------------------------------------------------------------


New resource usage for the time frame starting at 6002.80:
Adding: broker_9
broker_9 is starting...
6003.000000000001: broker_9: Cloud Resource List received with 1 resource(s)
6003.000000000001: broker_9: Trying to Create VM #90 in Datacenter
6003.000000000001: broker_9: Trying to Create VM #91 in Datacenter
6003.000000000001: broker_9: Trying to Create VM #92 in Datacenter
6003.00: VM #90 has been allocated to the host #60
6003.00: VM #91 has been allocated to the host #60
6003.00: VM #92 has been allocated to the host #60
6003.100000000001: broker_9: VM #90 has been created in Datacenter #3, Host #60
6003.100000000001: broker_9: VM #91 has been created in Datacenter #3, Host #60
6003.100000000001: broker_9: VM #92 has been created in Datacenter #3, Host #60
6003.100000000001: broker_9: Sending cloudlet 90 to VM #90
6003.100000000001: broker_9: Sending cloudlet 91 to VM #91
6003.100000000001: broker_9: Sending cloudlet 92 to VM #92


--------------------------------------------------------------


New resource usage for the time frame starting at 6303.10:


--------------------------------------------------------------


New resource usage for the time frame starting at 6603.10:
Adding: broker_10
broker_10 is starting...
6603.300000000001: broker_10: Cloud Resource List received with 1 resource(s)
6603.300000000001: broker_10: Trying to Create VM #93 in Datacenter
6603.300000000001: broker_10: Trying to Create VM #94 in Datacenter
6603.300000000001: broker_10: Trying to Create VM #95 in Datacenter
6603.300000000001: broker_10: Trying to Create VM #96 in Datacenter
6603.300000000001: broker_10: Trying to Create VM #97 in Datacenter
6603.300000000001: broker_10: Trying to Create VM #98 in Datacenter
6603.300000000001: broker_10: Trying to Create VM #99 in Datacenter
6603.300000000001: broker_10: Trying to Create VM #100 in Datacenter
6603.300000000001: broker_10: Trying to Create VM #101 in Datacenter
6603.300000000001: broker_10: Trying to Create VM #102 in Datacenter
6603.300000000001: broker_10: Trying to Create VM #103 in Datacenter
6603.300000000001: broker_10: Trying to Create VM #104 in Datacenter
6603.300000000001: broker_10: Trying to Create VM #105 in Datacenter
6603.300000000001: broker_10: Trying to Create VM #106 in Datacenter
6603.300000000001: broker_10: Trying to Create VM #107 in Datacenter
6603.300000000001: broker_10: Trying to Create VM #108 in Datacenter
6603.300000000001: broker_10: Trying to Create VM #109 in Datacenter
6603.30: VM #93 has been allocated to the host #76
6603.30: VM #94 has been allocated to the host #60
6603.30: VM #95 has been allocated to the host #60
6603.30: VM #96 has been allocated to the host #60
6603.30: VM #97 has been allocated to the host #84
6603.30: VM #98 has been allocated to the host #13
6603.30: VM #99 has been allocated to the host #13
6603.30: VM #100 has been allocated to the host #13
6603.30: VM #101 has been allocated to the host #13
6603.30: VM #102 has been allocated to the host #13
6603.30: VM #103 has been allocated to the host #13
6603.30: VM #104 has been allocated to the host #13
6603.30: VM #105 has been allocated to the host #14
6603.30: VM #106 has been allocated to the host #0
6603.30: VM #107 has been allocated to the host #6
6603.30: VM #108 has been allocated to the host #32
6603.30: VM #109 has been allocated to the host #42
6603.4000000000015: broker_10: VM #93 has been created in Datacenter #3, Host #76
6603.4000000000015: broker_10: VM #94 has been created in Datacenter #3, Host #60
6603.4000000000015: broker_10: VM #95 has been created in Datacenter #3, Host #60
6603.4000000000015: broker_10: VM #96 has been created in Datacenter #3, Host #60
6603.4000000000015: broker_10: VM #97 has been created in Datacenter #3, Host #84
6603.4000000000015: broker_10: VM #98 has been created in Datacenter #3, Host #13
6603.4000000000015: broker_10: VM #99 has been created in Datacenter #3, Host #13
6603.4000000000015: broker_10: VM #100 has been created in Datacenter #3, Host #13
6603.4000000000015: broker_10: VM #101 has been created in Datacenter #3, Host #13
6603.4000000000015: broker_10: VM #102 has been created in Datacenter #3, Host #13
6603.4000000000015: broker_10: VM #103 has been created in Datacenter #3, Host #13
6603.4000000000015: broker_10: VM #104 has been created in Datacenter #3, Host #13
6603.4000000000015: broker_10: VM #105 has been created in Datacenter #3, Host #14
6603.4000000000015: broker_10: VM #106 has been created in Datacenter #3, Host #0
6603.4000000000015: broker_10: VM #107 has been created in Datacenter #3, Host #6
6603.4000000000015: broker_10: VM #108 has been created in Datacenter #3, Host #32
6603.4000000000015: broker_10: VM #109 has been created in Datacenter #3, Host #42
6603.4000000000015: broker_10: Sending cloudlet 93 to VM #93
6603.4000000000015: broker_10: Sending cloudlet 94 to VM #94
6603.4000000000015: broker_10: Sending cloudlet 95 to VM #95
6603.4000000000015: broker_10: Sending cloudlet 96 to VM #96
6603.4000000000015: broker_10: Sending cloudlet 97 to VM #97
6603.4000000000015: broker_10: Sending cloudlet 98 to VM #98
6603.4000000000015: broker_10: Sending cloudlet 99 to VM #99
6603.4000000000015: broker_10: Sending cloudlet 100 to VM #100
6603.4000000000015: broker_10: Sending cloudlet 101 to VM #101
6603.4000000000015: broker_10: Sending cloudlet 102 to VM #102
6603.4000000000015: broker_10: Sending cloudlet 103 to VM #103
6603.4000000000015: broker_10: Sending cloudlet 104 to VM #104
6603.4000000000015: broker_10: Sending cloudlet 105 to VM #105
6603.4000000000015: broker_10: Sending cloudlet 106 to VM #106
6603.4000000000015: broker_10: Sending cloudlet 107 to VM #107
6603.4000000000015: broker_10: Sending cloudlet 108 to VM #108
6603.4000000000015: broker_10: Sending cloudlet 109 to VM #109


--------------------------------------------------------------


New resource usage for the time frame starting at 6903.40:


--------------------------------------------------------------


New resource usage for the time frame starting at 7203.40:
Adding: broker_11
broker_11 is starting...
7203.600000000001: broker_11: Cloud Resource List received with 1 resource(s)
7203.600000000001: broker_11: Trying to Create VM #110 in Datacenter
7203.600000000001: broker_11: Trying to Create VM #111 in Datacenter
7203.600000000001: broker_11: Trying to Create VM #112 in Datacenter
7203.600000000001: broker_11: Trying to Create VM #113 in Datacenter
7203.60: VM #110 has been allocated to the host #51
7203.60: VM #111 has been allocated to the host #7
7203.60: VM #112 has been allocated to the host #51
7203.60: VM #113 has been allocated to the host #51
7203.700000000002: broker_11: VM #110 has been created in Datacenter #3, Host #51
7203.700000000002: broker_11: VM #111 has been created in Datacenter #3, Host #7
7203.700000000002: broker_11: VM #112 has been created in Datacenter #3, Host #51
7203.700000000002: broker_11: VM #113 has been created in Datacenter #3, Host #51
7203.700000000002: broker_11: Sending cloudlet 110 to VM #110
7203.700000000002: broker_11: Sending cloudlet 111 to VM #111
7203.700000000002: broker_11: Sending cloudlet 112 to VM #112
7203.700000000002: broker_11: Sending cloudlet 113 to VM #113


--------------------------------------------------------------


New resource usage for the time frame starting at 7503.70:


--------------------------------------------------------------


New resource usage for the time frame starting at 7803.70:
Adding: broker_12
broker_12 is starting...
7803.9000000000015: broker_12: Cloud Resource List received with 1 resource(s)
7803.9000000000015: broker_12: Trying to Create VM #114 in Datacenter
7803.9000000000015: broker_12: Trying to Create VM #115 in Datacenter
7803.9000000000015: broker_12: Trying to Create VM #116 in Datacenter
7803.9000000000015: broker_12: Trying to Create VM #117 in Datacenter
7803.9000000000015: broker_12: Trying to Create VM #118 in Datacenter
7803.9000000000015: broker_12: Trying to Create VM #119 in Datacenter
7803.9000000000015: broker_12: Trying to Create VM #120 in Datacenter
7803.9000000000015: broker_12: Trying to Create VM #121 in Datacenter
7803.9000000000015: broker_12: Trying to Create VM #122 in Datacenter
7803.9000000000015: broker_12: Trying to Create VM #123 in Datacenter
7803.9000000000015: broker_12: Trying to Create VM #124 in Datacenter
7803.9000000000015: broker_12: Trying to Create VM #125 in Datacenter
7803.9000000000015: broker_12: Trying to Create VM #126 in Datacenter
7803.9000000000015: broker_12: Trying to Create VM #127 in Datacenter
7803.9000000000015: broker_12: Trying to Create VM #128 in Datacenter
7803.90: VM #114 has been allocated to the host #51
7803.90: VM #115 has been allocated to the host #51
7803.90: VM #116 has been allocated to the host #51
7803.90: VM #117 has been allocated to the host #28
7803.90: VM #118 has been allocated to the host #51
7803.90: VM #119 has been allocated to the host #51
7803.90: VM #120 has been allocated to the host #51
7803.90: VM #121 has been allocated to the host #51
7803.90: VM #122 has been allocated to the host #66
7803.90: VM #123 has been allocated to the host #0
7803.90: VM #124 has been allocated to the host #42
7803.90: VM #125 has been allocated to the host #42
7803.90: VM #126 has been allocated to the host #42
7803.90: VM #127 has been allocated to the host #42
7803.90: VM #128 has been allocated to the host #42
7804.000000000002: broker_12: VM #114 has been created in Datacenter #3, Host #51
7804.000000000002: broker_12: VM #115 has been created in Datacenter #3, Host #51
7804.000000000002: broker_12: VM #116 has been created in Datacenter #3, Host #51
7804.000000000002: broker_12: VM #117 has been created in Datacenter #3, Host #28
7804.000000000002: broker_12: VM #118 has been created in Datacenter #3, Host #51
7804.000000000002: broker_12: VM #119 has been created in Datacenter #3, Host #51
7804.000000000002: broker_12: VM #120 has been created in Datacenter #3, Host #51
7804.000000000002: broker_12: VM #121 has been created in Datacenter #3, Host #51
7804.000000000002: broker_12: VM #122 has been created in Datacenter #3, Host #66
7804.000000000002: broker_12: VM #123 has been created in Datacenter #3, Host #0
7804.000000000002: broker_12: VM #124 has been created in Datacenter #3, Host #42
7804.000000000002: broker_12: VM #125 has been created in Datacenter #3, Host #42
7804.000000000002: broker_12: VM #126 has been created in Datacenter #3, Host #42
7804.000000000002: broker_12: VM #127 has been created in Datacenter #3, Host #42
7804.000000000002: broker_12: VM #128 has been created in Datacenter #3, Host #42
7804.000000000002: broker_12: Sending cloudlet 114 to VM #114
7804.000000000002: broker_12: Sending cloudlet 115 to VM #115
7804.000000000002: broker_12: Sending cloudlet 116 to VM #116
7804.000000000002: broker_12: Sending cloudlet 117 to VM #117
7804.000000000002: broker_12: Sending cloudlet 118 to VM #118
7804.000000000002: broker_12: Sending cloudlet 119 to VM #119
7804.000000000002: broker_12: Sending cloudlet 120 to VM #120
7804.000000000002: broker_12: Sending cloudlet 121 to VM #121
7804.000000000002: broker_12: Sending cloudlet 122 to VM #122
7804.000000000002: broker_12: Sending cloudlet 123 to VM #123
7804.000000000002: broker_12: Sending cloudlet 124 to VM #124
7804.000000000002: broker_12: Sending cloudlet 125 to VM #125
7804.000000000002: broker_12: Sending cloudlet 126 to VM #126
7804.000000000002: broker_12: Sending cloudlet 127 to VM #127
7804.000000000002: broker_12: Sending cloudlet 128 to VM #128


--------------------------------------------------------------


New resource usage for the time frame starting at 8104.00:


--------------------------------------------------------------


New resource usage for the time frame starting at 8404.00:
Adding: broker_13
broker_13 is starting...
8404.2: broker_13: Cloud Resource List received with 1 resource(s)
8404.2: broker_13: Trying to Create VM #129 in Datacenter
8404.2: broker_13: Trying to Create VM #130 in Datacenter
8404.2: broker_13: Trying to Create VM #131 in Datacenter
8404.2: broker_13: Trying to Create VM #132 in Datacenter
8404.2: broker_13: Trying to Create VM #133 in Datacenter
8404.2: broker_13: Trying to Create VM #134 in Datacenter
8404.2: broker_13: Trying to Create VM #135 in Datacenter
8404.2: broker_13: Trying to Create VM #136 in Datacenter
8404.2: broker_13: Trying to Create VM #137 in Datacenter
8404.2: broker_13: Trying to Create VM #138 in Datacenter
8404.2: broker_13: Trying to Create VM #139 in Datacenter
8404.2: broker_13: Trying to Create VM #140 in Datacenter
8404.2: broker_13: Trying to Create VM #141 in Datacenter
8404.2: broker_13: Trying to Create VM #142 in Datacenter
8404.2: broker_13: Trying to Create VM #143 in Datacenter
8404.2: broker_13: Trying to Create VM #144 in Datacenter
8404.2: broker_13: Trying to Create VM #145 in Datacenter
8404.2: broker_13: Trying to Create VM #146 in Datacenter
8404.2: broker_13: Trying to Create VM #147 in Datacenter
8404.2: broker_13: Trying to Create VM #148 in Datacenter
8404.20: VM #129 has been allocated to the host #68
8404.20: VM #130 has been allocated to the host #68
8404.20: VM #131 has been allocated to the host #56
8404.20: VM #132 has been allocated to the host #68
8404.20: VM #133 has been allocated to the host #68
8404.20: VM #134 has been allocated to the host #68
8404.20: VM #135 has been allocated to the host #68
8404.20: VM #136 has been allocated to the host #68
8404.20: VM #137 has been allocated to the host #68
8404.20: VM #138 has been allocated to the host #68
8404.20: VM #139 has been allocated to the host #68
8404.20: VM #140 has been allocated to the host #42
8404.20: VM #141 has been allocated to the host #17
8404.20: VM #142 has been allocated to the host #0
8404.20: VM #143 has been allocated to the host #45
8404.20: VM #144 has been allocated to the host #94
8404.20: VM #145 has been allocated to the host #4
8404.20: VM #146 has been allocated to the host #6
8404.20: VM #147 has been allocated to the host #22
8404.20: VM #148 has been allocated to the host #32
8404.300000000001: broker_13: VM #129 has been created in Datacenter #3, Host #68
8404.300000000001: broker_13: VM #130 has been created in Datacenter #3, Host #68
8404.300000000001: broker_13: VM #131 has been created in Datacenter #3, Host #56
8404.300000000001: broker_13: VM #132 has been created in Datacenter #3, Host #68
8404.300000000001: broker_13: VM #133 has been created in Datacenter #3, Host #68
8404.300000000001: broker_13: VM #134 has been created in Datacenter #3, Host #68
8404.300000000001: broker_13: VM #135 has been created in Datacenter #3, Host #68
8404.300000000001: broker_13: VM #136 has been created in Datacenter #3, Host #68
8404.300000000001: broker_13: VM #137 has been created in Datacenter #3, Host #68
8404.300000000001: broker_13: VM #138 has been created in Datacenter #3, Host #68
8404.300000000001: broker_13: VM #139 has been created in Datacenter #3, Host #68
8404.300000000001: broker_13: VM #140 has been created in Datacenter #3, Host #42
8404.300000000001: broker_13: VM #141 has been created in Datacenter #3, Host #17
8404.300000000001: broker_13: VM #142 has been created in Datacenter #3, Host #0
8404.300000000001: broker_13: VM #143 has been created in Datacenter #3, Host #45
8404.300000000001: broker_13: VM #144 has been created in Datacenter #3, Host #94
8404.300000000001: broker_13: VM #145 has been created in Datacenter #3, Host #4
8404.300000000001: broker_13: VM #146 has been created in Datacenter #3, Host #6
8404.300000000001: broker_13: VM #147 has been created in Datacenter #3, Host #22
8404.300000000001: broker_13: VM #148 has been created in Datacenter #3, Host #32
8404.300000000001: broker_13: Sending cloudlet 129 to VM #129
8404.300000000001: broker_13: Sending cloudlet 130 to VM #130
8404.300000000001: broker_13: Sending cloudlet 131 to VM #131
8404.300000000001: broker_13: Sending cloudlet 132 to VM #132
8404.300000000001: broker_13: Sending cloudlet 133 to VM #133
8404.300000000001: broker_13: Sending cloudlet 134 to VM #134
8404.300000000001: broker_13: Sending cloudlet 135 to VM #135
8404.300000000001: broker_13: Sending cloudlet 136 to VM #136
8404.300000000001: broker_13: Sending cloudlet 137 to VM #137
8404.300000000001: broker_13: Sending cloudlet 138 to VM #138
8404.300000000001: broker_13: Sending cloudlet 139 to VM #139
8404.300000000001: broker_13: Sending cloudlet 140 to VM #140
8404.300000000001: broker_13: Sending cloudlet 141 to VM #141
8404.300000000001: broker_13: Sending cloudlet 142 to VM #142
8404.300000000001: broker_13: Sending cloudlet 143 to VM #143
8404.300000000001: broker_13: Sending cloudlet 144 to VM #144
8404.300000000001: broker_13: Sending cloudlet 145 to VM #145
8404.300000000001: broker_13: Sending cloudlet 146 to VM #146
8404.300000000001: broker_13: Sending cloudlet 147 to VM #147
8404.300000000001: broker_13: Sending cloudlet 148 to VM #148


--------------------------------------------------------------


New resource usage for the time frame starting at 8704.30:


--------------------------------------------------------------


New resource usage for the time frame starting at 9004.30:
Adding: broker_14
broker_14 is starting...
9004.5: broker_14: Cloud Resource List received with 1 resource(s)
9004.5: broker_14: Trying to Create VM #149 in Datacenter
9004.5: broker_14: Trying to Create VM #150 in Datacenter
9004.5: broker_14: Trying to Create VM #151 in Datacenter
9004.5: broker_14: Trying to Create VM #152 in Datacenter
9004.5: broker_14: Trying to Create VM #153 in Datacenter
9004.5: broker_14: Trying to Create VM #154 in Datacenter
9004.50: VM #149 has been allocated to the host #42
9004.50: VM #150 has been allocated to the host #17
9004.50: VM #151 has been allocated to the host #45
9004.50: VM #152 has been allocated to the host #49
9004.50: VM #153 has been allocated to the host #56
9004.50: VM #154 has been allocated to the host #94
9004.6: broker_14: VM #149 has been created in Datacenter #3, Host #42
9004.6: broker_14: VM #150 has been created in Datacenter #3, Host #17
9004.6: broker_14: VM #151 has been created in Datacenter #3, Host #45
9004.6: broker_14: VM #152 has been created in Datacenter #3, Host #49
9004.6: broker_14: VM #153 has been created in Datacenter #3, Host #56
9004.6: broker_14: VM #154 has been created in Datacenter #3, Host #94
9004.6: broker_14: Sending cloudlet 149 to VM #149
9004.6: broker_14: Sending cloudlet 150 to VM #150
9004.6: broker_14: Sending cloudlet 151 to VM #151
9004.6: broker_14: Sending cloudlet 152 to VM #152
9004.6: broker_14: Sending cloudlet 153 to VM #153
9004.6: broker_14: Sending cloudlet 154 to VM #154


--------------------------------------------------------------


New resource usage for the time frame starting at 9304.60:


--------------------------------------------------------------


New resource usage for the time frame starting at 9604.60:
Adding: broker_15
broker_15 is starting...
9604.8: broker_15: Cloud Resource List received with 1 resource(s)
9604.8: broker_15: Trying to Create VM #155 in Datacenter
9604.8: broker_15: Trying to Create VM #156 in Datacenter
9604.8: broker_15: Trying to Create VM #157 in Datacenter
9604.8: broker_15: Trying to Create VM #158 in Datacenter
9604.8: broker_15: Trying to Create VM #159 in Datacenter
9604.8: broker_15: Trying to Create VM #160 in Datacenter
9604.8: broker_15: Trying to Create VM #161 in Datacenter
9604.8: broker_15: Trying to Create VM #162 in Datacenter
9604.80: VM #155 has been allocated to the host #17
9604.80: VM #156 has been allocated to the host #37
9604.80: VM #157 has been allocated to the host #14
9604.80: VM #158 has been allocated to the host #5
9604.80: VM #159 has been allocated to the host #7
9604.80: VM #160 has been allocated to the host #63
9604.80: VM #161 has been allocated to the host #63
9604.80: VM #162 has been allocated to the host #63
9604.9: broker_15: VM #155 has been created in Datacenter #3, Host #17
9604.9: broker_15: VM #156 has been created in Datacenter #3, Host #37
9604.9: broker_15: VM #157 has been created in Datacenter #3, Host #14
9604.9: broker_15: VM #158 has been created in Datacenter #3, Host #5
9604.9: broker_15: VM #159 has been created in Datacenter #3, Host #7
9604.9: broker_15: VM #160 has been created in Datacenter #3, Host #63
9604.9: broker_15: VM #161 has been created in Datacenter #3, Host #63
9604.9: broker_15: VM #162 has been created in Datacenter #3, Host #63
9604.9: broker_15: Sending cloudlet 155 to VM #155
9604.9: broker_15: Sending cloudlet 156 to VM #156
9604.9: broker_15: Sending cloudlet 157 to VM #157
9604.9: broker_15: Sending cloudlet 158 to VM #158
9604.9: broker_15: Sending cloudlet 159 to VM #159
9604.9: broker_15: Sending cloudlet 160 to VM #160
9604.9: broker_15: Sending cloudlet 161 to VM #161
9604.9: broker_15: Sending cloudlet 162 to VM #162


--------------------------------------------------------------


New resource usage for the time frame starting at 9904.90:


--------------------------------------------------------------


New resource usage for the time frame starting at 10204.90:
Adding: broker_16
broker_16 is starting...
10205.099999999999: broker_16: Cloud Resource List received with 1 resource(s)
10205.099999999999: broker_16: Trying to Create VM #163 in Datacenter
10205.099999999999: broker_16: Trying to Create VM #164 in Datacenter
10205.099999999999: broker_16: Trying to Create VM #165 in Datacenter
10205.099999999999: broker_16: Trying to Create VM #166 in Datacenter
10205.10: VM #163 has been allocated to the host #63
10205.10: VM #164 has been allocated to the host #89
10205.10: VM #165 has been allocated to the host #63
10205.10: VM #166 has been allocated to the host #63
10205.199999999999: broker_16: VM #163 has been created in Datacenter #3, Host #63
10205.199999999999: broker_16: VM #164 has been created in Datacenter #3, Host #89
10205.199999999999: broker_16: VM #165 has been created in Datacenter #3, Host #63
10205.199999999999: broker_16: VM #166 has been created in Datacenter #3, Host #63
10205.199999999999: broker_16: Sending cloudlet 163 to VM #163
10205.199999999999: broker_16: Sending cloudlet 164 to VM #164
10205.199999999999: broker_16: Sending cloudlet 165 to VM #165
10205.199999999999: broker_16: Sending cloudlet 166 to VM #166


--------------------------------------------------------------


New resource usage for the time frame starting at 10505.20:


--------------------------------------------------------------


New resource usage for the time frame starting at 10805.20:
Adding: broker_17
broker_17 is starting...
10805.399999999998: broker_17: Cloud Resource List received with 1 resource(s)
10805.399999999998: broker_17: Trying to Create VM #167 in Datacenter
10805.399999999998: broker_17: Trying to Create VM #168 in Datacenter
10805.399999999998: broker_17: Trying to Create VM #169 in Datacenter
10805.399999999998: broker_17: Trying to Create VM #170 in Datacenter
10805.399999999998: broker_17: Trying to Create VM #171 in Datacenter
10805.399999999998: broker_17: Trying to Create VM #172 in Datacenter
10805.399999999998: broker_17: Trying to Create VM #173 in Datacenter
10805.399999999998: broker_17: Trying to Create VM #174 in Datacenter
10805.399999999998: broker_17: Trying to Create VM #175 in Datacenter
10805.399999999998: broker_17: Trying to Create VM #176 in Datacenter
10805.399999999998: broker_17: Trying to Create VM #177 in Datacenter
10805.399999999998: broker_17: Trying to Create VM #178 in Datacenter
10805.399999999998: broker_17: Trying to Create VM #179 in Datacenter
10805.399999999998: broker_17: Trying to Create VM #180 in Datacenter
10805.399999999998: broker_17: Trying to Create VM #181 in Datacenter
10805.40: VM #167 has been allocated to the host #63
10805.40: VM #168 has been allocated to the host #64
10805.40: VM #169 has been allocated to the host #63
10805.40: VM #170 has been allocated to the host #14
10805.40: VM #171 has been allocated to the host #47
10805.40: VM #172 has been allocated to the host #37
10805.40: VM #173 has been allocated to the host #49
10805.40: VM #174 has been allocated to the host #5
10805.40: VM #175 has been allocated to the host #24
10805.40: VM #176 has been allocated to the host #26
10805.40: VM #177 has been allocated to the host #4
10805.40: VM #178 has been allocated to the host #28
10805.40: VM #179 has been allocated to the host #44
10805.40: VM #180 has been allocated to the host #46
10805.40: VM #181 has been allocated to the host #28
10805.499999999998: broker_17: VM #167 has been created in Datacenter #3, Host #63
10805.499999999998: broker_17: VM #168 has been created in Datacenter #3, Host #64
10805.499999999998: broker_17: VM #169 has been created in Datacenter #3, Host #63
10805.499999999998: broker_17: VM #170 has been created in Datacenter #3, Host #14
10805.499999999998: broker_17: VM #171 has been created in Datacenter #3, Host #47
10805.499999999998: broker_17: VM #172 has been created in Datacenter #3, Host #37
10805.499999999998: broker_17: VM #173 has been created in Datacenter #3, Host #49
10805.499999999998: broker_17: VM #174 has been created in Datacenter #3, Host #5
10805.499999999998: broker_17: VM #175 has been created in Datacenter #3, Host #24
10805.499999999998: broker_17: VM #176 has been created in Datacenter #3, Host #26
10805.499999999998: broker_17: VM #177 has been created in Datacenter #3, Host #4
10805.499999999998: broker_17: VM #178 has been created in Datacenter #3, Host #28
10805.499999999998: broker_17: VM #179 has been created in Datacenter #3, Host #44
10805.499999999998: broker_17: VM #180 has been created in Datacenter #3, Host #46
10805.499999999998: broker_17: VM #181 has been created in Datacenter #3, Host #28
10805.499999999998: broker_17: Sending cloudlet 167 to VM #167
10805.499999999998: broker_17: Sending cloudlet 168 to VM #168
10805.499999999998: broker_17: Sending cloudlet 169 to VM #169
10805.499999999998: broker_17: Sending cloudlet 170 to VM #170
10805.499999999998: broker_17: Sending cloudlet 171 to VM #171
10805.499999999998: broker_17: Sending cloudlet 172 to VM #172
10805.499999999998: broker_17: Sending cloudlet 173 to VM #173
10805.499999999998: broker_17: Sending cloudlet 174 to VM #174
10805.499999999998: broker_17: Sending cloudlet 175 to VM #175
10805.499999999998: broker_17: Sending cloudlet 176 to VM #176
10805.499999999998: broker_17: Sending cloudlet 177 to VM #177
10805.499999999998: broker_17: Sending cloudlet 178 to VM #178
10805.499999999998: broker_17: Sending cloudlet 179 to VM #179
10805.499999999998: broker_17: Sending cloudlet 180 to VM #180
10805.499999999998: broker_17: Sending cloudlet 181 to VM #181


--------------------------------------------------------------


New resource usage for the time frame starting at 11105.50:


--------------------------------------------------------------


New resource usage for the time frame starting at 11405.50:
Adding: broker_18
broker_18 is starting...
11405.699999999997: broker_18: Cloud Resource List received with 1 resource(s)
11405.699999999997: broker_18: Trying to Create VM #182 in Datacenter
11405.699999999997: broker_18: Trying to Create VM #183 in Datacenter
11405.699999999997: broker_18: Trying to Create VM #184 in Datacenter
11405.70: VM #182 has been allocated to the host #28
11405.70: VM #183 has been allocated to the host #28
11405.70: VM #184 has been allocated to the host #28
11405.799999999997: broker_18: VM #182 has been created in Datacenter #3, Host #28
11405.799999999997: broker_18: VM #183 has been created in Datacenter #3, Host #28
11405.799999999997: broker_18: VM #184 has been created in Datacenter #3, Host #28
11405.799999999997: broker_18: Sending cloudlet 182 to VM #182
11405.799999999997: broker_18: Sending cloudlet 183 to VM #183
11405.799999999997: broker_18: Sending cloudlet 184 to VM #184


--------------------------------------------------------------


New resource usage for the time frame starting at 11705.80:


--------------------------------------------------------------


New resource usage for the time frame starting at 12005.80:
Adding: broker_19
broker_19 is starting...
12005.999999999996: broker_19: Cloud Resource List received with 1 resource(s)
12005.999999999996: broker_19: Trying to Create VM #185 in Datacenter
12005.999999999996: broker_19: Trying to Create VM #186 in Datacenter
12005.999999999996: broker_19: Trying to Create VM #187 in Datacenter
12005.999999999996: broker_19: Trying to Create VM #188 in Datacenter
12005.999999999996: broker_19: Trying to Create VM #189 in Datacenter
12005.999999999996: broker_19: Trying to Create VM #190 in Datacenter
12005.999999999996: broker_19: Trying to Create VM #191 in Datacenter
12005.999999999996: broker_19: Trying to Create VM #192 in Datacenter
12005.999999999996: broker_19: Trying to Create VM #193 in Datacenter
12005.999999999996: broker_19: Trying to Create VM #194 in Datacenter
12005.999999999996: broker_19: Trying to Create VM #195 in Datacenter
12005.999999999996: broker_19: Trying to Create VM #196 in Datacenter
12005.999999999996: broker_19: Trying to Create VM #197 in Datacenter
12005.999999999996: broker_19: Trying to Create VM #198 in Datacenter
12005.999999999996: broker_19: Trying to Create VM #199 in Datacenter
12005.999999999996: broker_19: Trying to Create VM #200 in Datacenter
12005.999999999996: broker_19: Trying to Create VM #201 in Datacenter
12006.00: VM #185 has been allocated to the host #28
12006.00: VM #186 has been allocated to the host #29
12006.00: VM #187 has been allocated to the host #63
12006.00: VM #188 has been allocated to the host #5
12006.00: VM #189 has been allocated to the host #24
12006.00: VM #190 has been allocated to the host #80
12006.00: VM #191 has been allocated to the host #26
12006.00: VM #192 has been allocated to the host #44
12006.00: VM #193 has been allocated to the host #65
12006.00: VM #194 has been allocated to the host #46
12006.00: VM #195 has been allocated to the host #14
12006.00: VM #196 has been allocated to the host #37
12006.00: VM #197 has been allocated to the host #47
12006.00: VM #198 has been allocated to the host #55
12006.00: VM #199 has been allocated to the host #58
12006.00: VM #200 has been allocated to the host #64
12006.00: VM #201 has been allocated to the host #66
12006.099999999997: broker_19: VM #185 has been created in Datacenter #3, Host #28
12006.099999999997: broker_19: VM #186 has been created in Datacenter #3, Host #29
12006.099999999997: broker_19: VM #187 has been created in Datacenter #3, Host #63
12006.099999999997: broker_19: VM #188 has been created in Datacenter #3, Host #5
12006.099999999997: broker_19: VM #189 has been created in Datacenter #3, Host #24
12006.099999999997: broker_19: VM #190 has been created in Datacenter #3, Host #80
12006.099999999997: broker_19: VM #191 has been created in Datacenter #3, Host #26
12006.099999999997: broker_19: VM #192 has been created in Datacenter #3, Host #44
12006.099999999997: broker_19: VM #193 has been created in Datacenter #3, Host #65
12006.099999999997: broker_19: VM #194 has been created in Datacenter #3, Host #46
12006.099999999997: broker_19: VM #195 has been created in Datacenter #3, Host #14
12006.099999999997: broker_19: VM #196 has been created in Datacenter #3, Host #37
12006.099999999997: broker_19: VM #197 has been created in Datacenter #3, Host #47
12006.099999999997: broker_19: VM #198 has been created in Datacenter #3, Host #55
12006.099999999997: broker_19: VM #199 has been created in Datacenter #3, Host #58
12006.099999999997: broker_19: VM #200 has been created in Datacenter #3, Host #64
12006.099999999997: broker_19: VM #201 has been created in Datacenter #3, Host #66
12006.099999999997: broker_19: Sending cloudlet 185 to VM #185
12006.099999999997: broker_19: Sending cloudlet 186 to VM #186
12006.099999999997: broker_19: Sending cloudlet 187 to VM #187
12006.099999999997: broker_19: Sending cloudlet 188 to VM #188
12006.099999999997: broker_19: Sending cloudlet 189 to VM #189
12006.099999999997: broker_19: Sending cloudlet 190 to VM #190
12006.099999999997: broker_19: Sending cloudlet 191 to VM #191
12006.099999999997: broker_19: Sending cloudlet 192 to VM #192
12006.099999999997: broker_19: Sending cloudlet 193 to VM #193
12006.099999999997: broker_19: Sending cloudlet 194 to VM #194
12006.099999999997: broker_19: Sending cloudlet 195 to VM #195
12006.099999999997: broker_19: Sending cloudlet 196 to VM #196
12006.099999999997: broker_19: Sending cloudlet 197 to VM #197
12006.099999999997: broker_19: Sending cloudlet 198 to VM #198
12006.099999999997: broker_19: Sending cloudlet 199 to VM #199
12006.099999999997: broker_19: Sending cloudlet 200 to VM #200
12006.099999999997: broker_19: Sending cloudlet 201 to VM #201


--------------------------------------------------------------


New resource usage for the time frame starting at 12306.10:


--------------------------------------------------------------


New resource usage for the time frame starting at 12606.10:
Adding: broker_20
broker_20 is starting...
12606.299999999996: broker_20: Cloud Resource List received with 1 resource(s)
12606.299999999996: broker_20: Trying to Create VM #202 in Datacenter
12606.299999999996: broker_20: Trying to Create VM #203 in Datacenter
12606.299999999996: broker_20: Trying to Create VM #204 in Datacenter
12606.30: VM #202 has been allocated to the host #63
12606.30: VM #203 has been allocated to the host #28
12606.30: VM #204 has been allocated to the host #99
12606.399999999996: broker_20: VM #202 has been created in Datacenter #3, Host #63
12606.399999999996: broker_20: VM #203 has been created in Datacenter #3, Host #28
12606.399999999996: broker_20: VM #204 has been created in Datacenter #3, Host #99
12606.399999999996: broker_20: Sending cloudlet 202 to VM #202
12606.399999999996: broker_20: Sending cloudlet 203 to VM #203
12606.399999999996: broker_20: Sending cloudlet 204 to VM #204


--------------------------------------------------------------


New resource usage for the time frame starting at 12906.40:


--------------------------------------------------------------


New resource usage for the time frame starting at 13206.40:
Adding: broker_21
broker_21 is starting...
13206.599999999995: broker_21: Cloud Resource List received with 1 resource(s)
13206.599999999995: broker_21: Trying to Create VM #205 in Datacenter
13206.599999999995: broker_21: Trying to Create VM #206 in Datacenter
13206.599999999995: broker_21: Trying to Create VM #207 in Datacenter
13206.599999999995: broker_21: Trying to Create VM #208 in Datacenter
13206.599999999995: broker_21: Trying to Create VM #209 in Datacenter
13206.599999999995: broker_21: Trying to Create VM #210 in Datacenter
13206.599999999995: broker_21: Trying to Create VM #211 in Datacenter
13206.599999999995: broker_21: Trying to Create VM #212 in Datacenter
13206.599999999995: broker_21: Trying to Create VM #213 in Datacenter
13206.599999999995: broker_21: Trying to Create VM #214 in Datacenter
13206.599999999995: broker_21: Trying to Create VM #215 in Datacenter
13206.599999999995: broker_21: Trying to Create VM #216 in Datacenter
13206.599999999995: broker_21: Trying to Create VM #217 in Datacenter
13206.60: VM #205 has been allocated to the host #99
13206.60: VM #206 has been allocated to the host #99
13206.60: VM #207 has been allocated to the host #99
13206.60: VM #208 has been allocated to the host #99
13206.60: VM #209 has been allocated to the host #99
13206.60: VM #210 has been allocated to the host #99
13206.60: VM #211 has been allocated to the host #99
13206.60: VM #212 has been allocated to the host #99
13206.60: VM #213 has been allocated to the host #99
13206.60: VM #214 has been allocated to the host #28
13206.60: VM #215 has been allocated to the host #53
13206.60: VM #216 has been allocated to the host #53
13206.60: VM #217 has been allocated to the host #53
13206.699999999995: broker_21: VM #205 has been created in Datacenter #3, Host #99
13206.699999999995: broker_21: VM #206 has been created in Datacenter #3, Host #99
13206.699999999995: broker_21: VM #207 has been created in Datacenter #3, Host #99
13206.699999999995: broker_21: VM #208 has been created in Datacenter #3, Host #99
13206.699999999995: broker_21: VM #209 has been created in Datacenter #3, Host #99
13206.699999999995: broker_21: VM #210 has been created in Datacenter #3, Host #99
13206.699999999995: broker_21: VM #211 has been created in Datacenter #3, Host #99
13206.699999999995: broker_21: VM #212 has been created in Datacenter #3, Host #99
13206.699999999995: broker_21: VM #213 has been created in Datacenter #3, Host #99
13206.699999999995: broker_21: VM #214 has been created in Datacenter #3, Host #28
13206.699999999995: broker_21: VM #215 has been created in Datacenter #3, Host #53
13206.699999999995: broker_21: VM #216 has been created in Datacenter #3, Host #53
13206.699999999995: broker_21: VM #217 has been created in Datacenter #3, Host #53
13206.699999999995: broker_21: Sending cloudlet 205 to VM #205
13206.699999999995: broker_21: Sending cloudlet 206 to VM #206
13206.699999999995: broker_21: Sending cloudlet 207 to VM #207
13206.699999999995: broker_21: Sending cloudlet 208 to VM #208
13206.699999999995: broker_21: Sending cloudlet 209 to VM #209
13206.699999999995: broker_21: Sending cloudlet 210 to VM #210
13206.699999999995: broker_21: Sending cloudlet 211 to VM #211
13206.699999999995: broker_21: Sending cloudlet 212 to VM #212
13206.699999999995: broker_21: Sending cloudlet 213 to VM #213
13206.699999999995: broker_21: Sending cloudlet 214 to VM #214
13206.699999999995: broker_21: Sending cloudlet 215 to VM #215
13206.699999999995: broker_21: Sending cloudlet 216 to VM #216
13206.699999999995: broker_21: Sending cloudlet 217 to VM #217


--------------------------------------------------------------


New resource usage for the time frame starting at 13506.70:


--------------------------------------------------------------


New resource usage for the time frame starting at 13806.70:
Adding: broker_22
broker_22 is starting...
13806.899999999994: broker_22: Cloud Resource List received with 1 resource(s)
13806.899999999994: broker_22: Trying to Create VM #218 in Datacenter
13806.899999999994: broker_22: Trying to Create VM #219 in Datacenter
13806.899999999994: broker_22: Trying to Create VM #220 in Datacenter
13806.899999999994: broker_22: Trying to Create VM #221 in Datacenter
13806.899999999994: broker_22: Trying to Create VM #222 in Datacenter
13806.899999999994: broker_22: Trying to Create VM #223 in Datacenter
13806.899999999994: broker_22: Trying to Create VM #224 in Datacenter
13806.899999999994: broker_22: Trying to Create VM #225 in Datacenter
13806.899999999994: broker_22: Trying to Create VM #226 in Datacenter
13806.899999999994: broker_22: Trying to Create VM #227 in Datacenter
13806.899999999994: broker_22: Trying to Create VM #228 in Datacenter
13806.899999999994: broker_22: Trying to Create VM #229 in Datacenter
13806.899999999994: broker_22: Trying to Create VM #230 in Datacenter
13806.899999999994: broker_22: Trying to Create VM #231 in Datacenter
13806.899999999994: broker_22: Trying to Create VM #232 in Datacenter
13806.899999999994: broker_22: Trying to Create VM #233 in Datacenter
13806.899999999994: broker_22: Trying to Create VM #234 in Datacenter
13806.899999999994: broker_22: Trying to Create VM #235 in Datacenter
13806.899999999994: broker_22: Trying to Create VM #236 in Datacenter
13806.90: VM #218 has been allocated to the host #64
13806.90: VM #219 has been allocated to the host #64
13806.90: VM #220 has been allocated to the host #64
13806.90: VM #221 has been allocated to the host #72
13806.90: VM #222 has been allocated to the host #64
13806.90: VM #223 has been allocated to the host #64
13806.90: VM #224 has been allocated to the host #28
13806.90: VM #225 has been allocated to the host #78
13806.90: VM #226 has been allocated to the host #78
13806.90: VM #227 has been allocated to the host #78
13806.90: VM #228 has been allocated to the host #78
13806.90: VM #229 has been allocated to the host #78
13806.90: VM #230 has been allocated to the host #47
13806.90: VM #231 has been allocated to the host #55
13806.90: VM #232 has been allocated to the host #21
13806.90: VM #233 has been allocated to the host #53
13806.90: VM #234 has been allocated to the host #58
13806.90: VM #235 has been allocated to the host #93
13806.90: VM #236 has been allocated to the host #78
13806.999999999995: broker_22: VM #218 has been created in Datacenter #3, Host #64
13806.999999999995: broker_22: VM #219 has been created in Datacenter #3, Host #64
13806.999999999995: broker_22: VM #220 has been created in Datacenter #3, Host #64
13806.999999999995: broker_22: VM #221 has been created in Datacenter #3, Host #72
13806.999999999995: broker_22: VM #222 has been created in Datacenter #3, Host #64
13806.999999999995: broker_22: VM #223 has been created in Datacenter #3, Host #64
13806.999999999995: broker_22: VM #224 has been created in Datacenter #3, Host #28
13806.999999999995: broker_22: VM #225 has been created in Datacenter #3, Host #78
13806.999999999995: broker_22: VM #226 has been created in Datacenter #3, Host #78
13806.999999999995: broker_22: VM #227 has been created in Datacenter #3, Host #78
13806.999999999995: broker_22: VM #228 has been created in Datacenter #3, Host #78
13806.999999999995: broker_22: VM #229 has been created in Datacenter #3, Host #78
13806.999999999995: broker_22: VM #230 has been created in Datacenter #3, Host #47
13806.999999999995: broker_22: VM #231 has been created in Datacenter #3, Host #55
13806.999999999995: broker_22: VM #232 has been created in Datacenter #3, Host #21
13806.999999999995: broker_22: VM #233 has been created in Datacenter #3, Host #53
13806.999999999995: broker_22: VM #234 has been created in Datacenter #3, Host #58
13806.999999999995: broker_22: VM #235 has been created in Datacenter #3, Host #93
13806.999999999995: broker_22: VM #236 has been created in Datacenter #3, Host #78
13806.999999999995: broker_22: Sending cloudlet 218 to VM #218
13806.999999999995: broker_22: Sending cloudlet 219 to VM #219
13806.999999999995: broker_22: Sending cloudlet 220 to VM #220
13806.999999999995: broker_22: Sending cloudlet 221 to VM #221
13806.999999999995: broker_22: Sending cloudlet 222 to VM #222
13806.999999999995: broker_22: Sending cloudlet 223 to VM #223
13806.999999999995: broker_22: Sending cloudlet 224 to VM #224
13806.999999999995: broker_22: Sending cloudlet 225 to VM #225
13806.999999999995: broker_22: Sending cloudlet 226 to VM #226
13806.999999999995: broker_22: Sending cloudlet 227 to VM #227
13806.999999999995: broker_22: Sending cloudlet 228 to VM #228
13806.999999999995: broker_22: Sending cloudlet 229 to VM #229
13806.999999999995: broker_22: Sending cloudlet 230 to VM #230
13806.999999999995: broker_22: Sending cloudlet 231 to VM #231
13806.999999999995: broker_22: Sending cloudlet 232 to VM #232
13806.999999999995: broker_22: Sending cloudlet 233 to VM #233
13806.999999999995: broker_22: Sending cloudlet 234 to VM #234
13806.999999999995: broker_22: Sending cloudlet 235 to VM #235
13806.999999999995: broker_22: Sending cloudlet 236 to VM #236


--------------------------------------------------------------


New resource usage for the time frame starting at 14107.00:


--------------------------------------------------------------


New resource usage for the time frame starting at 14407.00:
Adding: broker_23
broker_23 is starting...
14407.199999999993: broker_23: Cloud Resource List received with 1 resource(s)
14407.199999999993: broker_23: Trying to Create VM #237 in Datacenter
14407.20: VM #237 has been allocated to the host #78
14407.299999999994: broker_23: VM #237 has been created in Datacenter #3, Host #78
14407.299999999994: broker_23: Sending cloudlet 237 to VM #237


--------------------------------------------------------------


New resource usage for the time frame starting at 14707.30:


--------------------------------------------------------------


New resource usage for the time frame starting at 15007.30:
Adding: broker_24
broker_24 is starting...
15007.499999999993: broker_24: Cloud Resource List received with 1 resource(s)
15007.499999999993: broker_24: Trying to Create VM #238 in Datacenter
15007.499999999993: broker_24: Trying to Create VM #239 in Datacenter
15007.499999999993: broker_24: Trying to Create VM #240 in Datacenter
15007.499999999993: broker_24: Trying to Create VM #241 in Datacenter
15007.499999999993: broker_24: Trying to Create VM #242 in Datacenter
15007.499999999993: broker_24: Trying to Create VM #243 in Datacenter
15007.499999999993: broker_24: Trying to Create VM #244 in Datacenter
15007.499999999993: broker_24: Trying to Create VM #245 in Datacenter
15007.499999999993: broker_24: Trying to Create VM #246 in Datacenter
15007.499999999993: broker_24: Trying to Create VM #247 in Datacenter
15007.499999999993: broker_24: Trying to Create VM #248 in Datacenter
15007.50: VM #238 has been allocated to the host #40
15007.50: VM #239 has been allocated to the host #78
15007.50: VM #240 has been allocated to the host #78
15007.50: VM #241 has been allocated to the host #52
15007.50: VM #242 has been allocated to the host #78
15007.50: VM #243 has been allocated to the host #91
15007.50: VM #244 has been allocated to the host #91
15007.50: VM #245 has been allocated to the host #91
15007.50: VM #246 has been allocated to the host #91
15007.50: VM #247 has been allocated to the host #91
15007.50: VM #248 has been allocated to the host #91
15007.599999999993: broker_24: VM #238 has been created in Datacenter #3, Host #40
15007.599999999993: broker_24: VM #239 has been created in Datacenter #3, Host #78
15007.599999999993: broker_24: VM #240 has been created in Datacenter #3, Host #78
15007.599999999993: broker_24: VM #241 has been created in Datacenter #3, Host #52
15007.599999999993: broker_24: VM #242 has been created in Datacenter #3, Host #78
15007.599999999993: broker_24: VM #243 has been created in Datacenter #3, Host #91
15007.599999999993: broker_24: VM #244 has been created in Datacenter #3, Host #91
15007.599999999993: broker_24: VM #245 has been created in Datacenter #3, Host #91
15007.599999999993: broker_24: VM #246 has been created in Datacenter #3, Host #91
15007.599999999993: broker_24: VM #247 has been created in Datacenter #3, Host #91
15007.599999999993: broker_24: VM #248 has been created in Datacenter #3, Host #91
15007.599999999993: broker_24: Sending cloudlet 238 to VM #238
15007.599999999993: broker_24: Sending cloudlet 239 to VM #239
15007.599999999993: broker_24: Sending cloudlet 240 to VM #240
15007.599999999993: broker_24: Sending cloudlet 241 to VM #241
15007.599999999993: broker_24: Sending cloudlet 242 to VM #242
15007.599999999993: broker_24: Sending cloudlet 243 to VM #243
15007.599999999993: broker_24: Sending cloudlet 244 to VM #244
15007.599999999993: broker_24: Sending cloudlet 245 to VM #245
15007.599999999993: broker_24: Sending cloudlet 246 to VM #246
15007.599999999993: broker_24: Sending cloudlet 247 to VM #247
15007.599999999993: broker_24: Sending cloudlet 248 to VM #248


--------------------------------------------------------------


New resource usage for the time frame starting at 15307.60:


--------------------------------------------------------------


New resource usage for the time frame starting at 15607.60:
Adding: broker_25
broker_25 is starting...
15607.799999999992: broker_25: Cloud Resource List received with 1 resource(s)
15607.799999999992: broker_25: Trying to Create VM #249 in Datacenter
15607.799999999992: broker_25: Trying to Create VM #250 in Datacenter
15607.799999999992: broker_25: Trying to Create VM #251 in Datacenter
15607.80: VM #249 has been allocated to the host #91
15607.80: VM #250 has been allocated to the host #91
15607.80: VM #251 has been allocated to the host #91
15607.899999999992: broker_25: VM #249 has been created in Datacenter #3, Host #91
15607.899999999992: broker_25: VM #250 has been created in Datacenter #3, Host #91
15607.899999999992: broker_25: VM #251 has been created in Datacenter #3, Host #91
15607.899999999992: broker_25: Sending cloudlet 249 to VM #249
15607.899999999992: broker_25: Sending cloudlet 250 to VM #250
15607.899999999992: broker_25: Sending cloudlet 251 to VM #251


--------------------------------------------------------------


New resource usage for the time frame starting at 15907.90:


--------------------------------------------------------------


New resource usage for the time frame starting at 16207.90:
Adding: broker_26
broker_26 is starting...
16208.099999999991: broker_26: Cloud Resource List received with 1 resource(s)
16208.099999999991: broker_26: Trying to Create VM #252 in Datacenter
16208.099999999991: broker_26: Trying to Create VM #253 in Datacenter
16208.099999999991: broker_26: Trying to Create VM #254 in Datacenter
16208.099999999991: broker_26: Trying to Create VM #255 in Datacenter
16208.099999999991: broker_26: Trying to Create VM #256 in Datacenter
16208.099999999991: broker_26: Trying to Create VM #257 in Datacenter
16208.099999999991: broker_26: Trying to Create VM #258 in Datacenter
16208.099999999991: broker_26: Trying to Create VM #259 in Datacenter
16208.099999999991: broker_26: Trying to Create VM #260 in Datacenter
16208.099999999991: broker_26: Trying to Create VM #261 in Datacenter
16208.099999999991: broker_26: Trying to Create VM #262 in Datacenter
16208.099999999991: broker_26: Trying to Create VM #263 in Datacenter
16208.099999999991: broker_26: Trying to Create VM #264 in Datacenter
16208.099999999991: broker_26: Trying to Create VM #265 in Datacenter
16208.099999999991: broker_26: Trying to Create VM #266 in Datacenter
16208.099999999991: broker_26: Trying to Create VM #267 in Datacenter
16208.099999999991: broker_26: Trying to Create VM #268 in Datacenter
16208.099999999991: broker_26: Trying to Create VM #269 in Datacenter
16208.10: VM #252 has been allocated to the host #91
16208.10: VM #253 has been allocated to the host #64
16208.10: VM #254 has been allocated to the host #38
16208.10: VM #255 has been allocated to the host #22
16208.10: VM #256 has been allocated to the host #38
16208.10: VM #257 has been allocated to the host #73
16208.10: VM #258 has been allocated to the host #38
16208.10: VM #259 has been allocated to the host #66
16208.10: VM #260 has been allocated to the host #5
16208.10: VM #261 has been allocated to the host #24
16208.10: VM #262 has been allocated to the host #44
16208.10: VM #263 has been allocated to the host #38
16208.10: VM #264 has been allocated to the host #38
16208.10: VM #265 has been allocated to the host #38
16208.10: VM #266 has been allocated to the host #58
16208.10: VM #267 has been allocated to the host #38
16208.10: VM #268 has been allocated to the host #90
16208.10: VM #269 has been allocated to the host #90
16208.199999999992: broker_26: VM #252 has been created in Datacenter #3, Host #91
16208.199999999992: broker_26: VM #253 has been created in Datacenter #3, Host #64
16208.199999999992: broker_26: VM #254 has been created in Datacenter #3, Host #38
16208.199999999992: broker_26: VM #255 has been created in Datacenter #3, Host #22
16208.199999999992: broker_26: VM #256 has been created in Datacenter #3, Host #38
16208.199999999992: broker_26: VM #257 has been created in Datacenter #3, Host #73
16208.199999999992: broker_26: VM #258 has been created in Datacenter #3, Host #38
16208.199999999992: broker_26: VM #259 has been created in Datacenter #3, Host #66
16208.199999999992: broker_26: VM #260 has been created in Datacenter #3, Host #5
16208.199999999992: broker_26: VM #261 has been created in Datacenter #3, Host #24
16208.199999999992: broker_26: VM #262 has been created in Datacenter #3, Host #44
16208.199999999992: broker_26: VM #263 has been created in Datacenter #3, Host #38
16208.199999999992: broker_26: VM #264 has been created in Datacenter #3, Host #38
16208.199999999992: broker_26: VM #265 has been created in Datacenter #3, Host #38
16208.199999999992: broker_26: VM #266 has been created in Datacenter #3, Host #58
16208.199999999992: broker_26: VM #267 has been created in Datacenter #3, Host #38
16208.199999999992: broker_26: VM #268 has been created in Datacenter #3, Host #90
16208.199999999992: broker_26: VM #269 has been created in Datacenter #3, Host #90
16208.199999999992: broker_26: Sending cloudlet 252 to VM #252
16208.199999999992: broker_26: Sending cloudlet 253 to VM #253
16208.199999999992: broker_26: Sending cloudlet 254 to VM #254
16208.199999999992: broker_26: Sending cloudlet 255 to VM #255
16208.199999999992: broker_26: Sending cloudlet 256 to VM #256
16208.199999999992: broker_26: Sending cloudlet 257 to VM #257
16208.199999999992: broker_26: Sending cloudlet 258 to VM #258
16208.199999999992: broker_26: Sending cloudlet 259 to VM #259
16208.199999999992: broker_26: Sending cloudlet 260 to VM #260
16208.199999999992: broker_26: Sending cloudlet 261 to VM #261
16208.199999999992: broker_26: Sending cloudlet 262 to VM #262
16208.199999999992: broker_26: Sending cloudlet 263 to VM #263
16208.199999999992: broker_26: Sending cloudlet 264 to VM #264
16208.199999999992: broker_26: Sending cloudlet 265 to VM #265
16208.199999999992: broker_26: Sending cloudlet 266 to VM #266
16208.199999999992: broker_26: Sending cloudlet 267 to VM #267
16208.199999999992: broker_26: Sending cloudlet 268 to VM #268
16208.199999999992: broker_26: Sending cloudlet 269 to VM #269


--------------------------------------------------------------


New resource usage for the time frame starting at 16508.20:


--------------------------------------------------------------


New resource usage for the time frame starting at 16808.20:
Adding: broker_27
broker_27 is starting...
16808.39999999999: broker_27: Cloud Resource List received with 1 resource(s)


--------------------------------------------------------------


New resource usage for the time frame starting at 17108.20:


--------------------------------------------------------------


New resource usage for the time frame starting at 17408.20:
Adding: broker_28
broker_28 is starting...
17408.69999999999: broker_28: Cloud Resource List received with 1 resource(s)
17408.69999999999: broker_28: Trying to Create VM #270 in Datacenter
17408.69999999999: broker_28: Trying to Create VM #271 in Datacenter
17408.69999999999: broker_28: Trying to Create VM #272 in Datacenter
17408.69999999999: broker_28: Trying to Create VM #273 in Datacenter
17408.69999999999: broker_28: Trying to Create VM #274 in Datacenter
17408.69999999999: broker_28: Trying to Create VM #275 in Datacenter
17408.69999999999: broker_28: Trying to Create VM #276 in Datacenter
17408.69999999999: broker_28: Trying to Create VM #277 in Datacenter
17408.69999999999: broker_28: Trying to Create VM #278 in Datacenter
17408.69999999999: broker_28: Trying to Create VM #279 in Datacenter
17408.69999999999: broker_28: Trying to Create VM #280 in Datacenter
17408.69999999999: broker_28: Trying to Create VM #281 in Datacenter
17408.69999999999: broker_28: Trying to Create VM #282 in Datacenter
17408.69999999999: broker_28: Trying to Create VM #283 in Datacenter
17408.69999999999: broker_28: Trying to Create VM #284 in Datacenter
17408.69999999999: broker_28: Trying to Create VM #285 in Datacenter
17408.70: VM #270 has been allocated to the host #90
17408.70: VM #271 has been allocated to the host #90
17408.70: VM #272 has been allocated to the host #54
17408.70: VM #273 has been allocated to the host #90
17408.70: VM #274 has been allocated to the host #8
17408.70: VM #275 has been allocated to the host #76
17408.70: VM #276 has been allocated to the host #37
17408.70: VM #277 has been allocated to the host #11
17408.70: VM #278 has been allocated to the host #46
17408.70: VM #279 has been allocated to the host #46
17408.70: VM #280 has been allocated to the host #46
17408.70: VM #281 has been allocated to the host #46
17408.70: VM #282 has been allocated to the host #46
17408.70: VM #283 has been allocated to the host #10
17408.70: VM #284 has been allocated to the host #90
17408.70: VM #285 has been allocated to the host #90
17408.79999999999: broker_28: VM #270 has been created in Datacenter #3, Host #90
17408.79999999999: broker_28: VM #271 has been created in Datacenter #3, Host #90
17408.79999999999: broker_28: VM #272 has been created in Datacenter #3, Host #54
17408.79999999999: broker_28: VM #273 has been created in Datacenter #3, Host #90
17408.79999999999: broker_28: VM #274 has been created in Datacenter #3, Host #8
17408.79999999999: broker_28: VM #275 has been created in Datacenter #3, Host #76
17408.79999999999: broker_28: VM #276 has been created in Datacenter #3, Host #37
17408.79999999999: broker_28: VM #277 has been created in Datacenter #3, Host #11
17408.79999999999: broker_28: VM #278 has been created in Datacenter #3, Host #46
17408.79999999999: broker_28: VM #279 has been created in Datacenter #3, Host #46
17408.79999999999: broker_28: VM #280 has been created in Datacenter #3, Host #46
17408.79999999999: broker_28: VM #281 has been created in Datacenter #3, Host #46
17408.79999999999: broker_28: VM #282 has been created in Datacenter #3, Host #46
17408.79999999999: broker_28: VM #283 has been created in Datacenter #3, Host #10
17408.79999999999: broker_28: VM #284 has been created in Datacenter #3, Host #90
17408.79999999999: broker_28: VM #285 has been created in Datacenter #3, Host #90
17408.79999999999: broker_28: Sending cloudlet 270 to VM #270
17408.79999999999: broker_28: Sending cloudlet 271 to VM #271
17408.79999999999: broker_28: Sending cloudlet 272 to VM #272
17408.79999999999: broker_28: Sending cloudlet 273 to VM #273
17408.79999999999: broker_28: Sending cloudlet 274 to VM #274
17408.79999999999: broker_28: Sending cloudlet 275 to VM #275
17408.79999999999: broker_28: Sending cloudlet 276 to VM #276
17408.79999999999: broker_28: Sending cloudlet 277 to VM #277
17408.79999999999: broker_28: Sending cloudlet 278 to VM #278
17408.79999999999: broker_28: Sending cloudlet 279 to VM #279
17408.79999999999: broker_28: Sending cloudlet 280 to VM #280
17408.79999999999: broker_28: Sending cloudlet 281 to VM #281
17408.79999999999: broker_28: Sending cloudlet 282 to VM #282
17408.79999999999: broker_28: Sending cloudlet 283 to VM #283
17408.79999999999: broker_28: Sending cloudlet 284 to VM #284
17408.79999999999: broker_28: Sending cloudlet 285 to VM #285


--------------------------------------------------------------


New resource usage for the time frame starting at 17708.80:


--------------------------------------------------------------


New resource usage for the time frame starting at 18008.80:
Adding: broker_29
broker_29 is starting...
18008.99999999999: broker_29: Cloud Resource List received with 1 resource(s)
18008.99999999999: broker_29: Trying to Create VM #286 in Datacenter
18008.99999999999: broker_29: Trying to Create VM #287 in Datacenter
18008.99999999999: broker_29: Trying to Create VM #288 in Datacenter
18008.99999999999: broker_29: Trying to Create VM #289 in Datacenter
18008.99999999999: broker_29: Trying to Create VM #290 in Datacenter
18008.99999999999: broker_29: Trying to Create VM #291 in Datacenter
18008.99999999999: broker_29: Trying to Create VM #292 in Datacenter
18008.99999999999: broker_29: Trying to Create VM #293 in Datacenter
18008.99999999999: broker_29: Trying to Create VM #294 in Datacenter
18008.99999999999: broker_29: Trying to Create VM #295 in Datacenter
18008.99999999999: broker_29: Trying to Create VM #296 in Datacenter
18008.99999999999: broker_29: Trying to Create VM #297 in Datacenter
18009.00: VM #286 has been allocated to the host #90
18009.00: VM #287 has been allocated to the host #46
18009.00: VM #288 has been allocated to the host #40
18009.00: VM #289 has been allocated to the host #64
18009.00: VM #290 has been allocated to the host #61
18009.00: VM #291 has been allocated to the host #87
18009.00: VM #292 has been allocated to the host #54
18009.00: VM #293 has been allocated to the host #61
18009.00: VM #294 has been allocated to the host #61
18009.00: VM #295 has been allocated to the host #61
18009.00: VM #296 has been allocated to the host #49
18009.00: VM #297 has been allocated to the host #61
18009.099999999988: broker_29: VM #286 has been created in Datacenter #3, Host #90
18009.099999999988: broker_29: VM #287 has been created in Datacenter #3, Host #46
18009.099999999988: broker_29: VM #288 has been created in Datacenter #3, Host #40
18009.099999999988: broker_29: VM #289 has been created in Datacenter #3, Host #64
18009.099999999988: broker_29: VM #290 has been created in Datacenter #3, Host #61
18009.099999999988: broker_29: VM #291 has been created in Datacenter #3, Host #87
18009.099999999988: broker_29: VM #292 has been created in Datacenter #3, Host #54
18009.099999999988: broker_29: VM #293 has been created in Datacenter #3, Host #61
18009.099999999988: broker_29: VM #294 has been created in Datacenter #3, Host #61
18009.099999999988: broker_29: VM #295 has been created in Datacenter #3, Host #61
18009.099999999988: broker_29: VM #296 has been created in Datacenter #3, Host #49
18009.099999999988: broker_29: VM #297 has been created in Datacenter #3, Host #61
18009.099999999988: broker_29: Sending cloudlet 286 to VM #286
18009.099999999988: broker_29: Sending cloudlet 287 to VM #287
18009.099999999988: broker_29: Sending cloudlet 288 to VM #288
18009.099999999988: broker_29: Sending cloudlet 289 to VM #289
18009.099999999988: broker_29: Sending cloudlet 290 to VM #290
18009.099999999988: broker_29: Sending cloudlet 291 to VM #291
18009.099999999988: broker_29: Sending cloudlet 292 to VM #292
18009.099999999988: broker_29: Sending cloudlet 293 to VM #293
18009.099999999988: broker_29: Sending cloudlet 294 to VM #294
18009.099999999988: broker_29: Sending cloudlet 295 to VM #295
18009.099999999988: broker_29: Sending cloudlet 296 to VM #296
18009.099999999988: broker_29: Sending cloudlet 297 to VM #297


--------------------------------------------------------------


New resource usage for the time frame starting at 18309.10:


--------------------------------------------------------------


New resource usage for the time frame starting at 18609.10:
Adding: broker_30
broker_30 is starting...
18609.29999999999: broker_30: Cloud Resource List received with 1 resource(s)
18609.29999999999: broker_30: Trying to Create VM #298 in Datacenter
18609.29999999999: broker_30: Trying to Create VM #299 in Datacenter
18609.29999999999: broker_30: Trying to Create VM #300 in Datacenter
18609.29999999999: broker_30: Trying to Create VM #301 in Datacenter
18609.29999999999: broker_30: Trying to Create VM #302 in Datacenter
18609.29999999999: broker_30: Trying to Create VM #303 in Datacenter
18609.29999999999: broker_30: Trying to Create VM #304 in Datacenter
18609.29999999999: broker_30: Trying to Create VM #305 in Datacenter
18609.29999999999: broker_30: Trying to Create VM #306 in Datacenter
18609.29999999999: broker_30: Trying to Create VM #307 in Datacenter
18609.29999999999: broker_30: Trying to Create VM #308 in Datacenter
18609.29999999999: broker_30: Trying to Create VM #309 in Datacenter
18609.29999999999: broker_30: Trying to Create VM #310 in Datacenter
18609.29999999999: broker_30: Trying to Create VM #311 in Datacenter
18609.29999999999: broker_30: Trying to Create VM #312 in Datacenter
18609.29999999999: broker_30: Trying to Create VM #313 in Datacenter
18609.29999999999: broker_30: Trying to Create VM #314 in Datacenter
18609.30: VM #298 has been allocated to the host #61
18609.30: VM #299 has been allocated to the host #61
18609.30: VM #300 has been allocated to the host #61
18609.30: VM #301 has been allocated to the host #46
18609.30: VM #302 has been allocated to the host #64
18609.30: VM #303 has been allocated to the host #29
18609.30: VM #304 has been allocated to the host #11
18609.30: VM #305 has been allocated to the host #38
18609.30: VM #306 has been allocated to the host #17
18609.30: VM #307 has been allocated to the host #17
18609.30: VM #308 has been allocated to the host #17
18609.30: VM #309 has been allocated to the host #17
18609.30: VM #310 has been allocated to the host #17
18609.30: VM #311 has been allocated to the host #17
18609.30: VM #312 has been allocated to the host #40
18609.30: VM #313 has been allocated to the host #54
18609.30: VM #314 has been allocated to the host #93
18609.399999999987: broker_30: VM #298 has been created in Datacenter #3, Host #61
18609.399999999987: broker_30: VM #299 has been created in Datacenter #3, Host #61
18609.399999999987: broker_30: VM #300 has been created in Datacenter #3, Host #61
18609.399999999987: broker_30: VM #301 has been created in Datacenter #3, Host #46
18609.399999999987: broker_30: VM #302 has been created in Datacenter #3, Host #64
18609.399999999987: broker_30: VM #303 has been created in Datacenter #3, Host #29
18609.399999999987: broker_30: VM #304 has been created in Datacenter #3, Host #11
18609.399999999987: broker_30: VM #305 has been created in Datacenter #3, Host #38
18609.399999999987: broker_30: VM #306 has been created in Datacenter #3, Host #17
18609.399999999987: broker_30: VM #307 has been created in Datacenter #3, Host #17
18609.399999999987: broker_30: VM #308 has been created in Datacenter #3, Host #17
18609.399999999987: broker_30: VM #309 has been created in Datacenter #3, Host #17
18609.399999999987: broker_30: VM #310 has been created in Datacenter #3, Host #17
18609.399999999987: broker_30: VM #311 has been created in Datacenter #3, Host #17
18609.399999999987: broker_30: VM #312 has been created in Datacenter #3, Host #40
18609.399999999987: broker_30: VM #313 has been created in Datacenter #3, Host #54
18609.399999999987: broker_30: VM #314 has been created in Datacenter #3, Host #93
18609.399999999987: broker_30: Sending cloudlet 298 to VM #298
18609.399999999987: broker_30: Sending cloudlet 299 to VM #299
18609.399999999987: broker_30: Sending cloudlet 300 to VM #300
18609.399999999987: broker_30: Sending cloudlet 301 to VM #301
18609.399999999987: broker_30: Sending cloudlet 302 to VM #302
18609.399999999987: broker_30: Sending cloudlet 303 to VM #303
18609.399999999987: broker_30: Sending cloudlet 304 to VM #304
18609.399999999987: broker_30: Sending cloudlet 305 to VM #305
18609.399999999987: broker_30: Sending cloudlet 306 to VM #306
18609.399999999987: broker_30: Sending cloudlet 307 to VM #307
18609.399999999987: broker_30: Sending cloudlet 308 to VM #308
18609.399999999987: broker_30: Sending cloudlet 309 to VM #309
18609.399999999987: broker_30: Sending cloudlet 310 to VM #310
18609.399999999987: broker_30: Sending cloudlet 311 to VM #311
18609.399999999987: broker_30: Sending cloudlet 312 to VM #312
18609.399999999987: broker_30: Sending cloudlet 313 to VM #313
18609.399999999987: broker_30: Sending cloudlet 314 to VM #314


--------------------------------------------------------------


New resource usage for the time frame starting at 18909.40:


--------------------------------------------------------------


New resource usage for the time frame starting at 19209.40:
Adding: broker_31
broker_31 is starting...
19209.599999999988: broker_31: Cloud Resource List received with 1 resource(s)
19209.599999999988: broker_31: Trying to Create VM #315 in Datacenter
19209.599999999988: broker_31: Trying to Create VM #316 in Datacenter
19209.599999999988: broker_31: Trying to Create VM #317 in Datacenter
19209.599999999988: broker_31: Trying to Create VM #318 in Datacenter
19209.599999999988: broker_31: Trying to Create VM #319 in Datacenter
19209.599999999988: broker_31: Trying to Create VM #320 in Datacenter
19209.599999999988: broker_31: Trying to Create VM #321 in Datacenter
19209.60: VM #315 has been allocated to the host #93
19209.60: VM #316 has been allocated to the host #93
19209.60: VM #317 has been allocated to the host #93
19209.60: VM #318 has been allocated to the host #40
19209.60: VM #319 has been allocated to the host #40
19209.60: VM #320 has been allocated to the host #40
19209.60: VM #321 has been allocated to the host #49
19209.699999999986: broker_31: VM #315 has been created in Datacenter #3, Host #93
19209.699999999986: broker_31: VM #316 has been created in Datacenter #3, Host #93
19209.699999999986: broker_31: VM #317 has been created in Datacenter #3, Host #93
19209.699999999986: broker_31: VM #318 has been created in Datacenter #3, Host #40
19209.699999999986: broker_31: VM #319 has been created in Datacenter #3, Host #40
19209.699999999986: broker_31: VM #320 has been created in Datacenter #3, Host #40
19209.699999999986: broker_31: VM #321 has been created in Datacenter #3, Host #49
19209.699999999986: broker_31: Sending cloudlet 315 to VM #315
19209.699999999986: broker_31: Sending cloudlet 316 to VM #316
19209.699999999986: broker_31: Sending cloudlet 317 to VM #317
19209.699999999986: broker_31: Sending cloudlet 318 to VM #318
19209.699999999986: broker_31: Sending cloudlet 319 to VM #319
19209.699999999986: broker_31: Sending cloudlet 320 to VM #320
19209.699999999986: broker_31: Sending cloudlet 321 to VM #321


--------------------------------------------------------------


New resource usage for the time frame starting at 19509.70:


--------------------------------------------------------------


New resource usage for the time frame starting at 19809.70:
Adding: broker_32
broker_32 is starting...
19809.899999999987: broker_32: Cloud Resource List received with 1 resource(s)


--------------------------------------------------------------


New resource usage for the time frame starting at 20109.70:


--------------------------------------------------------------


New resource usage for the time frame starting at 20409.70:
Adding: broker_33
broker_33 is starting...
20410.199999999986: broker_33: Cloud Resource List received with 1 resource(s)
20410.199999999986: broker_33: Trying to Create VM #322 in Datacenter
20410.199999999986: broker_33: Trying to Create VM #323 in Datacenter
20410.199999999986: broker_33: Trying to Create VM #324 in Datacenter
20410.199999999986: broker_33: Trying to Create VM #325 in Datacenter
20410.199999999986: broker_33: Trying to Create VM #326 in Datacenter
20410.199999999986: broker_33: Trying to Create VM #327 in Datacenter
20410.20: VM #322 has been allocated to the host #40
20410.20: VM #323 has been allocated to the host #11
20410.20: VM #324 has been allocated to the host #95
20410.20: VM #325 has been allocated to the host #95
20410.20: VM #326 has been allocated to the host #95
20410.20: VM #327 has been allocated to the host #95
20410.299999999985: broker_33: VM #322 has been created in Datacenter #3, Host #40
20410.299999999985: broker_33: VM #323 has been created in Datacenter #3, Host #11
20410.299999999985: broker_33: VM #324 has been created in Datacenter #3, Host #95
20410.299999999985: broker_33: VM #325 has been created in Datacenter #3, Host #95
20410.299999999985: broker_33: VM #326 has been created in Datacenter #3, Host #95
20410.299999999985: broker_33: VM #327 has been created in Datacenter #3, Host #95
20410.299999999985: broker_33: Sending cloudlet 322 to VM #322
20410.299999999985: broker_33: Sending cloudlet 323 to VM #323
20410.299999999985: broker_33: Sending cloudlet 324 to VM #324
20410.299999999985: broker_33: Sending cloudlet 325 to VM #325
20410.299999999985: broker_33: Sending cloudlet 326 to VM #326
20410.299999999985: broker_33: Sending cloudlet 327 to VM #327


--------------------------------------------------------------


New resource usage for the time frame starting at 20710.30:


--------------------------------------------------------------


New resource usage for the time frame starting at 21010.30:
Adding: broker_34
broker_34 is starting...
21010.499999999985: broker_34: Cloud Resource List received with 1 resource(s)


--------------------------------------------------------------


New resource usage for the time frame starting at 21310.30:


--------------------------------------------------------------


New resource usage for the time frame starting at 21610.30:
Adding: broker_35
broker_35 is starting...
21610.799999999985: broker_35: Cloud Resource List received with 1 resource(s)
21610.799999999985: broker_35: Trying to Create VM #328 in Datacenter
21610.799999999985: broker_35: Trying to Create VM #329 in Datacenter
21610.799999999985: broker_35: Trying to Create VM #330 in Datacenter
21610.799999999985: broker_35: Trying to Create VM #331 in Datacenter
21610.799999999985: broker_35: Trying to Create VM #332 in Datacenter
21610.799999999985: broker_35: Trying to Create VM #333 in Datacenter
21610.799999999985: broker_35: Trying to Create VM #334 in Datacenter
21610.799999999985: broker_35: Trying to Create VM #335 in Datacenter
21610.799999999985: broker_35: Trying to Create VM #336 in Datacenter
21610.799999999985: broker_35: Trying to Create VM #337 in Datacenter
21610.799999999985: broker_35: Trying to Create VM #338 in Datacenter
21610.799999999985: broker_35: Trying to Create VM #339 in Datacenter
21610.799999999985: broker_35: Trying to Create VM #340 in Datacenter
21610.80: VM #328 has been allocated to the host #98
21610.80: VM #329 has been allocated to the host #95
21610.80: VM #330 has been allocated to the host #95
21610.80: VM #331 has been allocated to the host #58
21610.80: VM #332 has been allocated to the host #58
21610.80: VM #333 has been allocated to the host #65
21610.80: VM #334 has been allocated to the host #65
21610.80: VM #335 has been allocated to the host #65
21610.80: VM #336 has been allocated to the host #16
21610.80: VM #337 has been allocated to the host #5
21610.80: VM #338 has been allocated to the host #16
21610.80: VM #339 has been allocated to the host #98
21610.80: VM #340 has been allocated to the host #16
21610.899999999983: broker_35: VM #328 has been created in Datacenter #3, Host #98
21610.899999999983: broker_35: VM #329 has been created in Datacenter #3, Host #95
21610.899999999983: broker_35: VM #330 has been created in Datacenter #3, Host #95
21610.899999999983: broker_35: VM #331 has been created in Datacenter #3, Host #58
21610.899999999983: broker_35: VM #332 has been created in Datacenter #3, Host #58
21610.899999999983: broker_35: VM #333 has been created in Datacenter #3, Host #65
21610.899999999983: broker_35: VM #334 has been created in Datacenter #3, Host #65
